Workbook

Sheet Information
B2: Destiny 2 PvE Legendary Weapon Damage Generator
B3: Spreadsheet created and maintained by RokDC and Maeix - Contact at the bottom
B5: Update following the number crunching with EoF will probably take a bit of time as every weapon will need retesting. Still hope the new shooting range streamlines this process for faster and more reliable updates in the future!
A6: Version: | B6: 3.1
A7: Most recent version available: | B7: =IFERROR(__xludf.DUMMYFUNCTION("importrange(""https://docs.google.com/spreadsheets/d/1rY_iChu08CVnIMfHliZQwup10-GnmPtEu5FG0DNy8VM/edit"",""Information!B6"")"),"3.1") -> 3.1
B8: =IF(B6=B7,"","Update available! - In order to update the sheet, you need to create a new personal copy with the link below. Please check the changelog on the original sheet.")
A9: Link to the original sheet for updates: | B9: =HYPERLINK("https://docs.google.com/spreadsheets/d/1rY_iChu08CVnIMfHliZQwup10-GnmPtEu5FG0DNy8VM/edit?usp=sharing") -> https://docs.google.com/spreadsheets/d/1rY_iChu08CVnIMfHliZQwup10-GnmPtEu5FG0DNy8VM/edit?usp=sharing
A10: Hyperlink to share the sheet: | B10: https://destiny2.science/damage-generator
A11: Get started | B11: You can browse the public version of the spreadsheet. For full access to the sheet and all of its features you need to make a personal copy. (File > Create a copy; Google account required) Your personal copy will notify you about future updates. Please do not request access to the original spreadsheet.
A12: =IMAGE("https://cdn.icon-icons.com/icons2/272/PNG/512/Youtube_30038.png") | B12: =HYPERLINK("https://www.youtube.com/watch?v=khlzyX72jkc","You can find a tutorial on how to use this spreadsheet on YouTube (outdated)") -> You can find a tutorial on how to use this spreadsheet on YouTube (outdated)
A13: =IMAGE("https://encrypted-tbn3.gstatic.com/images?q=tbn:ANd9GcR8t3Q_kYYlM9FI7Y_IThJlk8MR9eyAzShqgzdzoXr3m7ymrwQ") | B13: =HYPERLINK("https://podcasts.google.com/feed/aHR0cHM6Ly9mZWVkcy5jYXB0aXZhdGUuZm0vcHZlLXBvZGNhc3QtdmVyc3VzLWVuZW1pZXMv/episode/YmI4NTVjYmQtMzhhMS00OTU3LWExYTMtOWJkMGU2MTFhNzQ2?sa=X&ved=0CAUQkfYCahcKEwjQh-mQlOqCAxUAAAAAHQAAAAAQAQ","RokDC and this spreadsheet on PvE: Podcast Versus Enemies") -> RokDC and this spreadsheet on PvE: Podcast Versus Enemies
A15: Spreadsheet Overview
A16: Database | B16: Central HUB - Includes all Special and and Heavy Legendary Weapons, their base data and various Damage metrics
A17: Main features | B17: - Select an encounter for discrete damage output
B18: - Apply global modifiers regarding magazine size, reserves or reload speed
B19: - Sort and Filter by many parameters
B20: - Apply Buffs and Debuffs to the calculations
B21: - Craft weapons by selecting Element and Perks
A22: Buffs/Debuffs | B22: Advanced buff/debuff stacking calculator, can be applied to the 'Database'
A23: Damage Chart | B23: Visualisation of Damage and DPS of all weapons in the database
A24: Selected Comparison | B24: Head-to-head comparison of all parameters of selected guns.
A25: Visual Comparison | B25: Visual comparison of the selected guns as a staircase diagram. Visual intervals dont always match the firerate which can cause inconsistent visual step lengths.
A27: Changelog
A28: 2024-11-09 v3.1 | B28: Addition of missing (Aggressive Glaive, Aggressive Sword) and new (Heavy Burst Shotgun) Archetypes
A29: 2024-10-27 v3.0 | B29: Rework of the spreadsheet including removal of any exotic weapons and addition of new features - See more in the v3.0 News above
A30: 2024-06-06 v2.7 | B30: Tentative Update of the Database based on the Patchnotes for Final Shape - In-game testing will take place after the Raid race; Visual comparisons have not been updated yet nor has the Scaling feature
A31: 2024-05-16 v2.6.5 | B31: Various Hotfixes (thanks to users crossboy and reichembach on Discord); Adjustements/corrections
A32: 2024-04-18 v2.6.4 | B32: Into the Light patch; GL Impact changes; Micro-Missile frame added; 1KV reserves
A33: 2024-03-15 v2.6.3 | B33: Implementing undocumented changes to special GLs; Unclear if intended from Bungie, might get rolled back/fixed at any time
A34: 2024-03-06 v2.6.2 | B34: Hotfix for Update 2.6.1; Anarchy ticks, Wendigo, Backend stuff
A35: 2024-03-06 v2.6.1 | B35: Midseason patch for Season of the Wish; Rocket and HGL Reserves, Spike Grenades; Misc;
A36: 2023-11-29 v2.6 | B36: Season of the Wish launch update; Swords; Glaives; New Exotic; Misc
A37: 2023-09-17 v2.5.1 | B37: Sword update; Updating combos and resulting damage values after the charge time changes; Adding in recently added sword archetypes; Addition of Crota's End encounters
A38: 2023-08-24 v2.5 | B38: Season of the Witch patch; New exotic weapons and reserve changes
A39: 2023-06-25 v2.4 | B39: Catch-up update for timelines and Buffs and Debuffs, now up to date with Lightfall and Season of the Deep sandbox changes
... A101: Disclaimer / Remarks | B101: All data got collected manually and therefore can include mistakes like false values or information. If you happen to notice one, please contact us! Some of the parameters are relatively hard to determine precisely and we obviously can't guarantee them to always be correct. As most of the data on timings got determined using frame counting on 60fps recordings, the general margin of error is 16.66ms. This is even more of an issue as some of the values listed in game turned out to be misleading or straight up wrong. (Example: Truth is listed as 15 RPM while it actually is 45 RPM). Even the slightest change in values or assumptions can cause significant movement among the rankings so judge the weapons with caution and common sense and don't blindly rely on this spreadsheet.
B102: Some (exotic) weapon mechanics exceed what the formulas can handle and therefore got slightly simplified. Read more on those cases in the 'How-To-Use'-tab
B103: The numbers in this spreadsheet require (almost) perfect conditions and execution in most cases. Consider them the theoretical ceiling. Ease-of-use is not a factor in this framework but will always be in praxis.
B104: The scope of this spreadsheet was to make weapons more comparable by applying coherent and consistent measures and calculations. The modifiers allow for indidividual settings and the assumptions made regarding several parameters try to be as close to actual Raid Boss encounters as possible.
A106: Contact | B106: For any questions/remarks/corrections please contact @maeix on Discord or visit the Destiny Science Discord server (Hivemind)

Sheet How To Use
A2: Features How to use this Spreadsheet
A3: Database Features | B3: 1. General functionalities
B4: Table | C4: All columns can be sorted and filtered to search for specific weapons and frames; A lot of columns are hidden by default - Expand them at your own risk
C5: Weapons are sorted by weapon type (e.g. Fusion Rifle, Shotgun, etc.) and frame (e.g. Adaptive Frame, Precision Frame, etc.)
C6: Special Weapons (Green background)
C7: Heavy Weapons (Purple background)
B8: Select | C8: The select feature allows for quick selection of weapons (toggle the box(es) and then filter by 'TRUE')
B9: 2. Global modifiers
B10: Raid Encounters | C10: The drop-down menu includes all dungeon and raid bosses to be selected
C11: Note: Durations are not 100% precise and are very loosely measured. In most situations you won't have the full duration to play with due to encounter design and damage setups.
B12: Custom | C12: The custom damage phase duration lets you enter a custom duration as long as you toggle the box.
B13: Encounter Damage | C13: The Encounter duration determines the 'Encounter damage' in the last column of the database. This is the discrete theoretical damage output for the given duration.
B14: 3. Perk selection
B15: Functionality | C15: Allows to assign an element and 2 perks to each weapon. If you want to create multiple weapons of the same frame, just copy the base entry in a new row.
C16: Not all perks are available as not everything works with the architecture of the spreadsheet and not all available perks realistically work with each weapon.
C17: Some Perks get simplified to be applicable universally. Perks that require weapon rotations (Envious Arsenal, BnS,...) do not take the rotation into account, the Damage per second is only for the time shooting the gun in question.
C18: The assigned element determines the application of selected element-specific buffs like Surges in the Buffs/Debuffs section
B19: 4. Damage scores
B20: TDO & DPS Scores | C20: TDO and DPS Scores are intended to be a tool for quick relative comparison. The highest current value in the database equals a score of 100. Selected perks, buffs and debuffs are considered.
B21: Damage Score | C21: Damage score is the average value of the TDO and DPS Score without any weighting. I promise
A22: Buffs/ Debuff selection | B22: 5. Buff/Debuff selection
B23: Functionality | C23: The Buff/Debuff tab offers an advanced buff/debuff stacking calculator that follows all stacking rules. Multipliers are calculated per weapon type and per element and can be applied to the Database.
C24: Buffs and Debuffs are opt-in
A25: Comparisons | B25: 5. Select
B26: Select | C26: Select up to 10 weapons from the 'Database'-tab for a head-to-head comparison on the 'Selected Comparison'-tab and the 'Visual Comparison'-tab. The current selection in the public version is for demonstration purposes.
B27: 5.1. Numeric Comparison
B28: Selected Comparison | C28: This sheet allows for a numeric comparison of the selected guns with the parameters and KPIs from the 'Database' Tab. Conditioned formatting is adjusted for a head-to-head comparison
B29: 5.2. Visual Comparison
B30: Graphs | C30: This sheet allows for a visual comparison of the selected guns using a staircase diagram. Please note that this diagram has fixed 0.5s intervals/steps which dont always match the weapon's firerate. This means that vertical lines which represent impacts can only occur every 0,5s. If an impact happens in between these intervals it'll only be displayed at the next 0,5s interval. Multiple shots going down between two interval borders can appear as 1 higher vertical step. This can cause inconsistent visual steps in the staircase function. The values at the 0.5s intervals should always have the correct values nonetheless. In a future update we will try to lower the intervals to 0,1s however this might stress the sheet and its scripts too much. This also has no impact on the accuracy of the Encounter damage value in the database.
A31: Methodology and Explanations How to read this Spreadsheet
A32: Methodology / Special Cases / Additional Notes | B32: 6. Methodology
B33: Parameters | C33: Basic parameters of the weapons used for calculations of the KPIs
B34: Base Impact | C34: Bodyshot damage on Kalli, Last Wish at the activity power cap without any buffs, debuffs or perks active. Values are verified by comparing them to converted bodyshot values from the enclave.
B35: Modified Impact | C35: Applies the weapon's crit multiplier, selected perks, global modifiers and all selected buffs and debuffs.
B36: Magazine | C36: Magazine size (base and max) is sourced from Mossy - It is the average magazine size of all weapons of that frame that have been released since S14
B37: Reserves | C37: Reserves (base and max) are sourced from Mossy - It is the average number of reserves of all weapons of that frame that have been released since S14
B38: RPM | C38: Rounds-per-minute. These are based on the ingame values but got corrected by our findings during the testing.
B39: Reload Speed | C39: Reload speed is calculated using the weapon type specific reload formulas sourced from D2Foundry [If you know who to credit for exactly, please lmk!]. Reload speed includes the base stat (once again, average of recently released weapons) as well as modifiers like loader mods and lunafactions boots as well as selected perks.
B40: KPIs | C40: Performance indicators for all weapons
B41: Time to empty mag | C41: Time it takes to empty one full magazine. The first shot in this model takes place on frame 0. Single shot weapons therefore have a value of 0
...

Sheet Database
B2: Encounter Information | F2: Expand between columns J and AB ‹‹ | K2: ›› for all base values and more parameters
B3: PoH - Zulmak
B4: =IF(C5=TRUE,B5,VLOOKUP(B3,backend!$E$4:F57,2,FALSE)) -> 20 | C4: Damage phase duration in seconds
B5: 30 | C5: FALSE | D5: ✎ Custom Damage phase duration | F5: In order to use all functionalities like sorting, filtering or selecting perks, you need to make a copy. See 'Information - Get started' | H5: Selected modifiers, element and perks get applied to all subsequent damage calculations In order to craft multiple weapons of the same type add a row and copy that weapon's base entry Not all perks are available and not every perk work withs each weapon type. Learn more about the feature and its limitations under 'How To Use' | K5: You can finetune further parameters in this section. It is advised to only change columns in green unless you are very sure what you are doing. For the origins of the values in the green columns, have a look in 'How To Use' | AB5: Damage scores for a quick relative comparison between weapon types. Highest current value per category equals 100. Damage score is the average of TDO and DPS Score | AE5: Values appear in green, if the reserves last for the entire damage phase based on the selected encounter | AG5: Various Damage and DPS metrics based on all previously applied values, parameters and modifiers Optimized DPS: Ending Damage after the last full magazine has been fired Sustained DPS: Damage over a theoretical infinite supply of ammunition Encounter Damage: Discrete Damage that can be done for the duration of the selected Encounter | AN5: These are intermediate calculations, it is advised to not touch them :-)
B6: FALSE | C6: Master (-20 Power delta)
B7: Global Weapon Modifier
B8: FALSE | C8: Apply Buffs and Debuffs
B9: FALSE | C9: 3x Reserve mods (Chest)
B10: FALSE | C10: Max. Magazine size (Backup Mag + Perks)
B11: FALSE | C11: Lunafaction Boots
B12: FALSE | C12: 1x Loader mod (Arms)
B14: Ammo type | C14: ="Select: "&COUNTIF(C15:C57,TRUE)&"/10" -> Select: 0/10 | D14: Weapon type | E14: archetype_code | F14: Frame | G14: Archetype combined | H14: Element | I14: Weapon Perk 1 | J14: Weapon Perk 2 | K14: Damage (Base) | L14: Damage (Modified) | M14: Crit multiplier | N14: Magazine (Base) | O14: Magazine (Max) | P14: Magazine (Modified) | Q14: RPM | R14: RPM (Modified) | S14: Reserves (Base) | T14: Reserves (x3) | U14: Reserves (Modified) | V14: Reload Stat (Base) | W14: Reload Stat (Modified) | X14: Reload Speed (Calc) | Y14: Max Reload Measured | Z14: Reload Cap (VanHolden) | AA14: Reload Speed | AB14: TDO Score | AC14: DPS Score | AD14: Damage Score | AE14: Time to empty magazine | AF14: Time to empty reserves | AG14: Single Mag Damage | AH14: Single Mag DPS | AI14: Total Damage Output (TDO) | AJ14: Optimized Damage | AK14: TDO DPS | AL14: Optimized DPS | AM14: Sustained DPS | AN14: reloads | AO14: time to shoot | AP14: dead time | AQ14: full mags | AR14: full mag dmg | AS14: leftover time | AT14: leftover bullets | AU14: leftover dmg | AV14: Encounter Damage
B15: Special | C15: FALSE | D15: Fusion Rifle | E15: fr_adaptive | F15: Adaptive | G15: =D15&" - "& F15 -> Fusion Rifle - Adaptive | H15: Any | I15: - | J15: - | K15: =VLOOKUP(E15,backend!$BP$5:$BQ57,2,FALSE) -> 39074 | L15: =K15*M15*IF(B15="Special",VLOOKUP(I15,backend!$H$4:$M57,2,FALSE),VLOOKUP(I15,backend!$H$4:$M57,3,FALSE))*IF(B15="Special",VLOOKUP(J15,backend!$H$4:$M57,2,FALSE),VLOOKUP(J15,backend!$H$4:$M57,3,FALSE))*IF($B$8=TRUE,VLOOKUP(D15,BuffsDebuffs!$P$8:$X$27,MATCH(H15,BuffsDebuffs!$P$8:$X$8,0),FALSE),1)*IF($B$6=TRUE,backend!$BN$5,1) -> 39074 | M15: =VLOOKUP(E15,backend!$BP$5:$BS57,4,FALSE) -> 1 | N15: 6 | O15: 8 | P15: =MAX(IFNA(VLOOKUP(IF($B$10=TRUE,O15,N15),backend!$P$4:$Y57,MATCH(I15,backend!$P$3:$Y$3,0),FALSE),IF($B$10=TRUE,O15,N15)),IFNA(VLOOKUP(IF($B$10=TRUE,O15,N15),backend!$P$4:$Y57,MATCH(J15,backend!$P$3:$Y$3,0),FALSE),IF($B$10=TRUE,O15,N15))) -> 6 | Q15: 50 | R15: =Q15/VLOOKUP(I15,backend!$H$4:$N57,7,FALSE)/VLOOKUP(J15,backend!$H$4:$N57,7,FALSE) -> 50 | S15: 19 | T15: 25 | U15: =MAX(IFNA(VLOOKUP(IF($B$9=TRUE,T15,S15),backend!$AA$4:$AF57,MATCH(I15,backend!$AA$3:$AF$3,0),FALSE),IF($B$9=TRUE,T15,S15)),IFNA(VLOOKUP(IF($B$9=TRUE,T15,S15),backend!$AA$4:$AF57,MATCH(J15,backend!$AA$3:$AF$3,0),FALSE),IF($B$9=TRUE,T15,S15))) -> 19 | V15: =VLOOKUP(E15,backend!$BB$4:$BH57,7,FALSE) -> 33.6 | W15: =MIN(100,V15+VLOOKUP(I15,backend!$H$4:$N57,5,FALSE)+VLOOKUP(J15,backend!$H$4:$N57,5,FALSE)+IF($B$11=TRUE,100,0)+IF($B$12,10,0)) -> 33.6 | X15: =(VLOOKUP(D15,backend!$AV$4:$AZ57,2,FALSE)*W15^2+VLOOKUP(D15,backend!$AV$4:$AZ57,3,FALSE)*W15+VLOOKUP(D15,backend!$AV$4:$AZ57,4,FALSE))*VLOOKUP(I15,backend!$H$4:$N57,6,FALSE)*VLOOKUP(J15,backend!$H$4:$N57,6,FALSE)*IF($B$12=TRUE,0.85,1)*IF($B$11=TRUE,0.9,1)*IF(D15="Shotgun",P15,1)*IF(F15="Rapid-Fire",0.8,1)+IF(OR(D15="Fusion Rifle",D15="Linear Fusion Rifle"),0.516,0) -> 2.7485717 | Y15: 1.8 | Z15: =VLOOKUP(D15,backend!$AV$4:$AZ57,5,FALSE)*IF(D15="Shotgun",P15,1)+IF(OR(D15="Fusion Rifle",D15="Linear Fusion Rifle"),0.516,0) -> 1.583 | AA15: =MAX(X15,Z15) -> 2.7485717 | AB15: =AJ15/MAX(AJ$15:AJ57)*100 -> 34.110869 | AC15: =AL15/MAX(AL$15:AL57)*100 -> 57.93603 | AD15: =AVERAGE(AB15:AC15) -> 46.023449 | AE15: =60/R15*(P15-1) -> 6 | AF15: =ROUNDDOWN(U15/P15,0)*AE15+ROUNDDOWN((U15-1)/P15,0)*AA15+Max(0,((U15-ROUNDDOWN(U15/P15,0)*P15)-1)*(60/R15)) -> 26.245715 | AG15: =P15*L15 -> 234444 | AH15: =IF(ISERROR(AG15/AE15),"-",AG15/AE15) -> 39074 | AI15: =U15*L15 -> 742406 | AJ15: =ROUNDDOWN(U15/N15,0)*AG15 -> 703332 | AK15: =AI15/AF15 -> 28286.751 | AL15: =IF(P15=1,AK15,MAX(AK15,(ROUNDDOWN(U15/P15,0)*AG15)/(ROUNDDOWN(U15/P15,0)*AE15+(ROUNDDOWN(U15/P15,0)-1)*AA15))) -> 29932.66 | AM15: =IF(P15=U15,AH15,AG15/(AE15+AA15)) -> 26797.974 | AN15: =ROUNDDOWN(B$4/(AA15+AE15),0) -> 2 | AO15: =B$4-AN15*AA15 -> 14.502857 | AP15: =IF(AN15=AQ15,0,B$4-(AN15*AA15+AQ15*AE15)) -> 0 | AQ15: =MIN(AN15+1,IF(ISERROR(ROUNDDOWN(AO15/AE15,0)),AN15+1,ROUNDDOWN(AO15/AE15,0))) -> 2 | AR15: =AQ15*AG15 -> 468888 | AS15: =Max(0,AO15-AQ15*AE15)-AP15 -> 2.5028566 | AT15: =MIN(N15,IF(AN15<AQ15,0,ROUNDDOWN(IF(AS15=0,0,AS15*(R15/60)+1),0))) -> 3 | AU15: =AT15*L15 -> 117222 | AV15: =Min(AI15,AU15+AR15) -> 586110
B16: Special | C16: FALSE | D16: Fusion Rifle | E16: fr_aggressive | F16: Aggressive | G16: =D16&" - "& F16 -> Fusion Rifle - Aggressive | H16: Any | I16: - | J16: - | K16: =VLOOKUP(E16,backend!$BP$5:$BQ57,2,FALSE) -> 45164 | L16: =K16*M16*IF(B16="Special",VLOOKUP(I16,backend!$H$4:$M57,2,FALSE),VLOOKUP(I16,backend!$H$4:$M57,3,FALSE))*IF(B16="Special",VLOOKUP(J16,backend!$H$4:$M57,2,FALSE),VLOOKUP(J16,backend!$H$4:$M57,3,FALSE))*IF($B$8=TRUE,VLOOKUP(D16,BuffsDebuffs!$P$8:$X$27,MATCH(H16,BuffsDebuffs!$P$8:$X$8,0),FALSE),1)*IF($B$6=TRUE,backend!$BN$5,1) -> 45164 | M16: =VLOOKUP(E16,backend!$BP$5:$BS57,4,FALSE) -> 1 | N16: 7 | O16: 8 | P16: =MAX(IFNA(VLOOKUP(IF($B$10=TRUE,O16,N16),backend!$P$4:$Y57,MATCH(I16,backend!$P$3:$Y$3,0),FALSE),IF($B$10=TRUE,O16,N16)),IFNA(VLOOKUP(IF($B$10=TRUE,O16,N16),backend!$P$4:$Y57,MATCH(J16,backend!$P$3:$Y$3,0),FALSE),IF($B$10=TRUE,O16,N16))) -> 7 | Q16: 45 | R16: =Q16/VLOOKUP(I16,backend!$H$4:$N57,7,FALSE)/VLOOKUP(J16,backend!$H$4:$N57,7,FALSE) -> 45 | S16: 19 | T16: 25 | U16: =MAX(IFNA(VLOOKUP(IF($B$9=TRUE,T16,S16),backend!$AA$4:$AF57,MATCH(I16,backend!$AA$3:$AF$3,0),FALSE),IF($B$9=TRUE,T16,S16)),IFNA(VLOOKUP(IF($B$9=TRUE,T16,S16),backend!$AA$4:$AF57,MATCH(J16,backend!$AA$3:$AF$3,0),FALSE),IF($B$9=TRUE,T16,S16))) -> 19 | V16: =VLOOKUP(E16,backend!$BB$4:$BH57,7,FALSE) -> 34 | W16: =MIN(100,V16+VLOOKUP(I16,backend!$H$4:$N57,5,FALSE)+VLOOKUP(J16,backend!$H$4:$N57,5,FALSE)+IF($B$11=TRUE,100,0)+IF($B$12,10,0)) -> 34 | X16: =(VLOOKUP(D16,backend!$AV$4:$AZ57,2,FALSE)*W16^2+VLOOKUP(D16,backend!$AV$4:$AZ57,3,FALSE)*W16+VLOOKUP(D16,backend!$AV$4:$AZ57,4,FALSE))*VLOOKUP(I16,backend!$H$4:$N57,6,FALSE)*VLOOKUP(J16,backend!$H$4:$N57,6,FALSE)*IF($B$12=TRUE,0.85,1)*IF($B$11=TRUE,0.9,1)*IF(D16="Shotgun",P16,1)*IF(F16="Rapid-Fire",0.8,1)+IF(OR(D16="Fusion Rifle",D16="Linear Fusion Rifle"),0.516,0) -> 2.7423133 | Y16: 1.816 | Z16: =VLOOKUP(D16,backend!$AV$4:$AZ57,5,FALSE)*IF(D16="Shotgun",P16,1)+IF(OR(D16="Fusion Rifle",D16="Linear Fusion Rifle"),0.516,0) -> 1.583 | AA16: =MAX(X16,Z16) -> 2.7423133 | AB16: =AJ16/MAX(AJ$15:AJ58)*100 -> 30.665697 | AC16: =AL16/MAX(AL$15:AL58)*100 -> 65.298118 | AD16: =AVERAGE(AB16:AC16) -> 47.981908 | AE16: =60/R16*(P16-1) -> 8 | AF16: =ROUNDDOWN(U16/P16,0)*AE16+ROUNDDOWN((U16-1)/P16,0)*AA16+Max(0,((U16-ROUNDDOWN(U16/P16,0)*P16)-1)*(60/R16)) -> 26.81796 | AG16: =P16*L16 -> 316148 | AH16: =IF(ISERROR(AG16/AE16),"-",AG16/AE16) -> 39518.5 | AI16: =U16*L16 -> 858116 | AJ16: =ROUNDDOWN(U16/N16,0)*AG16 -> 632296 | AK16: =AI16/AF16 -> 31997.811 | AL16: =IF(P16=1,AK16,MAX(AK16,(ROUNDDOWN(U16/P16,0)*AG16)/(ROUNDDOWN(U16/P16,0)*AE16+(ROUNDDOWN(U16/P16,0)-1)*AA16))) -> 33736.284 | AM16: =IF(P16=U16,AH16,AG16/(AE16+AA16)) -> 29430.16 | AN16: =ROUNDDOWN(B$4/(AA16+AE16),0) -> 1 | AO16: =B$4-AN16*AA16 -> 17.257687 | AP16: =IF(AN16=AQ16,0,B$4-(AN16*AA16+AQ16*AE16)) -> 1.2576867 | AQ16: =MIN(AN16+1,IF(ISERROR(ROUNDDOWN(AO16/AE16,0)),AN16+1,ROUNDDOWN(AO16/AE16,0))) -> 2 | AR16: =AQ16*AG16 -> 632296 | AS16: =Max(0,AO16-AQ16*AE16)-AP16 -> 0 | AT16: =MIN(N16,IF(AN16<AQ16,0,ROUNDDOWN(IF(AS16=0,0,AS16*(R16/60)+1),0))) -> 0 | AU16: =AT16*L16 -> 0 | AV16: =Min(AI16,AU16+AR16) -> 632296
B17: Special | C17: FALSE | D17: Fusion Rifle | E17: fr_hi | F17: High-Impact | G17: =D17&" - "& F17 -> Fusion Rifle - High-Impact | H17: Any | I17: - | J17: - | K17: =VLOOKUP(E17,backend!$BP$5:$BQ57,2,FALSE) -> 49575 | L17: =K17*M17*IF(B17="Special",VLOOKUP(I17,backend!$H$4:$M57,2,FALSE),VLOOKUP(I17,backend!$H$4:$M57,3,FALSE))*IF(B17="Special",VLOOKUP(J17,backend!$H$4:$M57,2,FALSE),VLOOKUP(J17,backend!$H$4:$M57,3,FALSE))*IF($B$8=TRUE,VLOOKUP(D17,BuffsDebuffs!$P$8:$X$27,MATCH(H17,BuffsDebuffs!$P$8:$X$8,0),FALSE),1)*IF($B$6=TRUE,backend!$BN$5,1) -> 49575 | M17: =VLOOKUP(E17,backend!$BP$5:$BS57,4,FALSE) -> 1 | N17: 5 | O17: 8 | P17: =MAX(IFNA(VLOOKUP(IF($B$10=TRUE,O17,N17),backend!$P$4:$Y57,MATCH(I17,backend!$P$3:$Y$3,0),FALSE),IF($B$10=TRUE,O17,N17)),IFNA(VLOOKUP(IF($B$10=TRUE,O17,N17),backend!$P$4:$Y57,MATCH(J17,backend!$P$3:$Y$3,0),FALSE),IF($B$10=TRUE,O17,N17))) -> 5 | Q17: 39.56 | R17: =Q17/VLOOKUP(I17,backend!$H$4:$N57,7,FALSE)/VLOOKUP(J17,backend!$H$4:$N57,7,FALSE) -> 39.56 | S17: 18 | T17: 25 | U17: =MAX(IFNA(VLOOKUP(IF($B$9=TRUE,T17,S17),backend!$AA$4:$AF57,MATCH(I17,backend!$AA$3:$AF$3,0),FALSE),IF($B$9=TRUE,T17,S17)),IFNA(VLOOKUP(IF($B$9=TRUE,T17,S17),backend!$AA$4:$AF57,MATCH(J17,backend!$AA$3:$AF$3,0),FALSE),IF($B$9=TRUE,T17,S17))) -> 18 | V17: =VLOOKUP(E17,backend!$BB$4:$BH57,7,FALSE) -> 19 | W17: =MIN(100,V17+VLOOKUP(I17,backend!$H$4:$N57,5,FALSE)+VLOOKUP(J17,backend!$H$4:$N57,5,FALSE)+IF($B$11=TRUE,100,0)+IF($B$12,10,0)) -> 19 | X17: =(VLOOKUP(D17,backend!$AV$4:$AZ57,2,FALSE)*W17^2+VLOOKUP(D17,backend!$AV$4:$AZ57,3,FALSE)*W17+VLOOKUP(D17,backend!$AV$4:$AZ57,4,FALSE))*VLOOKUP(I17,backend!$H$4:$N57,6,FALSE)*VLOOKUP(J17,backend!$H$4:$N57,6,FALSE)*IF($B$12=TRUE,0.85,1)*IF($B$11=TRUE,0.9,1)*IF(D17="Shotgun",P17,1)*IF(F17="Rapid-Fire",0.8,1)+IF(OR(D17="Fusion Rifle",D17="Linear Fusion Rifle"),0.516,0) -> 2.9904794 | Y17: 2.034 | Z17: =VLOOKUP(D17,backend!$AV$4:$AZ57,5,FALSE)*IF(D17="Shotgun",P17,1)+IF(OR(D17="Fusion Rifle",D17="Linear Fusion Rifle"),0.516,0) -> 1.583 | AA17: =MAX(X17,Z17) -> 2.9904794 | AB17: =AJ17/MAX(AJ$15:AJ59)*100 -> 36.065037 | AC17: =AL17/MAX(AL$15:AL59)*100 -> 59.522376 | AD17: =AVERAGE(AB17:AC17) -> 47.793706 | AE17: =60/R17*(P17-1) -> 6.0667341 | AF17: =ROUNDDOWN(U17/P17,0)*AE17+ROUNDDOWN((U17-1)/P17,0)*AA17+Max(0,((U17-ROUNDDOWN(U17/P17,0)*P17)-1)*(60/R17)) -> 30.205008 | AG17: =P17*L17 -> 247875 | AH17: =IF(ISERROR(AG17/AE17),"-",AG17/AE17) -> 40858.062 | AI17: =U17*L17 -> 892350 | AJ17: =ROUNDDOWN(U17/N17,0)*AG17 -> 743625 | AK17: =AI17/AF17 -> 29543.115 | AL17: =IF(P17=1,AK17,MAX(AK17,(ROUNDDOWN(U17/P17,0)*AG17)/(ROUNDDOWN(U17/P17,0)*AE17+(ROUNDDOWN(U17/P17,0)-1)*AA17))) -> 30752.245 | AM17: =IF(P17=U17,AH17,AG17/(AE17+AA17)) -> 27367.689 | AN17: =ROUNDDOWN(B$4/(AA17+AE17),0) -> 2 | AO17: =B$4-AN17*AA17 -> 14.019041 | AP17: =IF(AN17=AQ17,0,B$4-(AN17*AA17+AQ17*AE17)) -> 0 | AQ17: =MIN(AN17+1,IF(ISERROR(ROUNDDOWN(AO17/AE17,0)),AN17+1,ROUNDDOWN(AO17/AE17,0))) -> 2 | AR17: =AQ17*AG17 -> 495750 | AS17: =Max(0,AO17-AQ17*AE17)-AP17 -> 1.885573 | AT17: =MIN(N17,IF(AN17<AQ17,0,ROUNDDOWN(IF(AS17=0,0,AS17*(R17/60)+1),0))) -> 2 | AU17: =AT17*L17 -> 99150 | AV17: =Min(AI17,AU17+AR17) -> 594900
B18: Special | C18: FALSE | D18: Fusion Rifle | E18: fr_precision | F18: Precision | G18: =D18&" - "& F18 -> Fusion Rifle - Precision | H18: Any | I18: - | J18: - | K18: =VLOOKUP(E18,backend!$BP$5:$BQ57,2,FALSE) -> 40523 | L18: =K18*M18*IF(B18="Special",VLOOKUP(I18,backend!$H$4:$M57,2,FALSE),VLOOKUP(I18,backend!$H$4:$M57,3,FALSE))*IF(B18="Special",VLOOKUP(J18,backend!$H$4:$M57,2,FALSE),VLOOKUP(J18,backend!$H$4:$M57,3,FALSE))*IF($B$8=TRUE,VLOOKUP(D18,BuffsDebuffs!$P$8:$X$27,MATCH(H18,BuffsDebuffs!$P$8:$X$8,0),FALSE),1)*IF($B$6=TRUE,backend!$BN$5,1) -> 40523 | M18: =VLOOKUP(E18,backend!$BP$5:$BS57,4,FALSE) -> 1 | N18: 6 | O18: 8 | P18: =MAX(IFNA(VLOOKUP(IF($B$10=TRUE,O18,N18),backend!$P$4:$Y57,MATCH(I18,backend!$P$3:$Y$3,0),FALSE),IF($B$10=TRUE,O18,N18)),IFNA(VLOOKUP(IF($B$10=TRUE,O18,N18),backend!$P$4:$Y57,MATCH(J18,backend!$P$3:$Y$3,0),FALSE),IF($B$10=TRUE,O18,N18))) -> 6 | Q18: 45.57 | R18: =Q18/VLOOKUP(I18,backend!$H$4:$N57,7,FALSE)/VLOOKUP(J18,backend!$H$4:$N57,7,FALSE) -> 45.57 | S18: 20 | T18: 28 | U18: =MAX(IFNA(VLOOKUP(IF($B$9=TRUE,T18,S18),backend!$AA$4:$AF57,MATCH(I18,backend!$AA$3:$AF$3,0),FALSE),IF($B$9=TRUE,T18,S18)),IFNA(VLOOKUP(IF($B$9=TRUE,T18,S18),backend!$AA$4:$AF57,MATCH(J18,backend!$AA$3:$AF$3,0),FALSE),IF($B$9=TRUE,T18,S18))) -> 20 | V18: =VLOOKUP(E18,backend!$BB$4:$BH57,7,FALSE) -> 30.8 | W18: =MIN(100,V18+VLOOKUP(I18,backend!$H$4:$N57,5,FALSE)+VLOOKUP(J18,backend!$H$4:$N57,5,FALSE)+IF($B$11=TRUE,100,0)+IF($B$12,10,0)) -> 30.8 | X18: =(VLOOKUP(D18,backend!$AV$4:$AZ57,2,FALSE)*W18^2+VLOOKUP(D18,backend!$AV$4:$AZ57,3,FALSE)*W18+VLOOKUP(D18,backend!$AV$4:$AZ57,4,FALSE))*VLOOKUP(I18,backend!$H$4:$N57,6,FALSE)*VLOOKUP(J18,backend!$H$4:$N57,6,FALSE)*IF($B$12=TRUE,0.85,1)*IF($B$11=TRUE,0.9,1)*IF(D18="Shotgun",P18,1)*IF(F18="Rapid-Fire",0.8,1)+IF(OR(D18="Fusion Rifle",D18="Linear Fusion Rifle"),0.516,0) -> 2.7929321 | Y18: 1.9 | Z18: =VLOOKUP(D18,backend!$AV$4:$AZ57,5,FALSE)*IF(D18="Shotgun",P18,1)+IF(OR(D18="Fusion Rifle",D18="Linear Fusion Rifle"),0.516,0) -> 1.583 | AA18: =MAX(X18,Z18) -> 2.7929321 | AB18: =AJ18/MAX(AJ$15:AJ60)*100 -> 35.375818 | AC18: =AL18/MAX(AL$15:AL60)*100 -> 55.7243 | AD18: =AVERAGE(AB18:AC18) -> 45.550059 | AE18: =60/R18*(P18-1) -> 6.5832785 | AF18: =ROUNDDOWN(U18/P18,0)*AE18+ROUNDDOWN((U18-1)/P18,0)*AA18+Max(0,((U18-ROUNDDOWN(U18/P18,0)*P18)-1)*(60/R18)) -> 29.445287 | AG18: =P18*L18 -> 243138 | AH18: =IF(ISERROR(AG18/AE18),"-",AG18/AE18) -> 36932.662 | AI18: =U18*L18 -> 810460 | AJ18: =ROUNDDOWN(U18/N18,0)*AG18 -> 729414 | AK18: =AI18/AF18 -> 27524.269 | AL18: =IF(P18=1,AK18,MAX(AK18,(ROUNDDOWN(U18/P18,0)*AG18)/(ROUNDDOWN(U18/P18,0)*AE18+(ROUNDDOWN(U18/P18,0)-1)*AA18))) -> 28789.969 | AM18: =IF(P18=U18,AH18,AG18/(AE18+AA18)) -> 25931.372 | AN18: =ROUNDDOWN(B$4/(AA18+AE18),0) -> 2 | AO18: =B$4-AN18*AA18 -> 14.414136 | AP18: =IF(AN18=AQ18,0,B$4-(AN18*AA18+AQ18*AE18)) -> 0 | AQ18: =MIN(AN18+1,IF(ISERROR(ROUNDDOWN(AO18/AE18,0)),AN18+1,ROUNDDOWN(AO18/AE18,0))) -> 2 | AR18: =AQ18*AG18 -> 486276 | AS18: =Max(0,AO18-AQ18*AE18)-AP18 -> 1.2475789 | AT18: =MIN(N18,IF(AN18<AQ18,0,ROUNDDOWN(IF(AS18=0,0,AS18*(R18/60)+1),0))) -> 1 | AU18: =AT18*L18 -> 40523 | AV18: =Min(AI18,AU18+AR18) -> 526799
B19: Special | C19: FALSE | D19: Fusion Rifle | E19: fr_rf | F19: Rapid-Fire | G19: =D19&" - "& F19 -> Fusion Rifle - Rapid-Fire | H19: Any | I19: - | J19: - | K19: =VLOOKUP(E19,backend!$BP$5:$BQ57,2,FALSE) -> 36900 | L19: =K19*M19*IF(B19="Special",VLOOKUP(I19,backend!$H$4:$M57,2,FALSE),VLOOKUP(I19,backend!$H$4:$M57,3,FALSE))*IF(B19="Special",VLOOKUP(J19,backend!$H$4:$M57,2,FALSE),VLOOKUP(J19,backend!$H$4:$M57,3,FALSE))*IF($B$8=TRUE,VLOOKUP(D19,BuffsDebuffs!$P$8:$X$27,MATCH(H19,BuffsDebuffs!$P$8:$X$8,0),FALSE),1)*IF($B$6=TRUE,backend!$BN$5,1) -> 36900 | M19: =VLOOKUP(E19,backend!$BP$5:$BS57,4,FALSE) -> 1 | N19: 7 | O19: 8 | P19: =MAX(IFNA(VLOOKUP(IF($B$10=TRUE,O19,N19),backend!$P$4:$Y57,MATCH(I19,backend!$P$3:$Y$3,0),FALSE),IF($B$10=TRUE,O19,N19)),IFNA(VLOOKUP(IF($B$10=TRUE,O19,N19),backend!$P$4:$Y57,MATCH(J19,backend!$P$3:$Y$3,0),FALSE),IF($B$10=TRUE,O19,N19))) -> 7 | Q19: 58.06 | R19: =Q19/VLOOKUP(I19,backend!$H$4:$N57,7,FALSE)/VLOOKUP(J19,backend!$H$4:$N57,7,FALSE) -> 58.06 | S19: 20 | T19: 26 | U19: =MAX(IFNA(VLOOKUP(IF($B$9=TRUE,T19,S19),backend!$AA$4:$AF57,MATCH(I19,backend!$AA$3:$AF$3,0),FALSE),IF($B$9=TRUE,T19,S19)),IFNA(VLOOKUP(IF($B$9=TRUE,T19,S19),backend!$AA$4:$AF57,MATCH(J19,backend!$AA$3:$AF$3,0),FALSE),IF($B$9=TRUE,T19,S19))) -> 20 | V19: =VLOOKUP(E19,backend!$BB$4:$BH57,7,FALSE) -> 45.8 | W19: =MIN(100,V19+VLOOKUP(I19,backend!$H$4:$N57,5,FALSE)+VLOOKUP(J19,backend!$H$4:$N57,5,FALSE)+IF($B$11=TRUE,100,0)+IF($B$12,10,0)) -> 45.8 | X19: =(VLOOKUP(D19,backend!$AV$4:$AZ57,2,FALSE)*W19^2+VLOOKUP(D19,backend!$AV$4:$AZ57,3,FALSE)*W19+VLOOKUP(D19,backend!$AV$4:$AZ57,4,FALSE))*VLOOKUP(I19,backend!$H$4:$N57,6,FALSE)*VLOOKUP(J19,backend!$H$4:$N57,6,FALSE)*IF($B$12=TRUE,0.85,1)*IF($B$11=TRUE,0.9,1)*IF(D19="Shotgun",P19,1)*IF(F19="Rapid-Fire",0.8,1)+IF(OR(D19="Fusion Rifle",D19="Linear Fusion Rifle"),0.516,0) -> 2.1564375 | Y19: 1.684 | Z19: =VLOOKUP(D19,backend!$AV$4:$AZ57,5,FALSE)*IF(D19="Shotgun",P19,1)+IF(OR(D19="Fusion Rifle",D19="Linear Fusion Rifle"),0.516,0) -> 1.583 | AA19: =MAX(X19,Z19) -> 2.1564375 | AB19: =AJ19/MAX(AJ$15:AJ61)*100 -> 25.054561 | AC19: =AL19/MAX(AL$15:AL61)*100 -> 68.686906 | AD19: =AVERAGE(AB19:AC19) -> 46.870733 | AE19: =60/R19*(P19-1) -> 6.2004823 | AF19: =ROUNDDOWN(U19/P19,0)*AE19+ROUNDDOWN((U19-1)/P19,0)*AA19+Max(0,((U19-ROUNDDOWN(U19/P19,0)*P19)-1)*(60/R19)) -> 21.880908 | AG19: =P19*L19 -> 258300 | AH19: =IF(ISERROR(AG19/AE19),"-",AG19/AE19) -> 41658.05 | AI19: =U19*L19 -> 738000 | AJ19: =ROUNDDOWN(U19/N19,0)*AG19 -> 516600 | AK19: =AI19/AF19 -> 33728.033 | AL19: =IF(P19=1,AK19,MAX(AK19,(ROUNDDOWN(U19/P19,0)*AG19)/(ROUNDDOWN(U19/P19,0)*AE19+(ROUNDDOWN(U19/P19,0)-1)*AA19))) -> 35487.101 | AM19: =IF(P19=U19,AH19,AG19/(AE19+AA19)) -> 30908.517 | AN19: =ROUNDDOWN(B$4/(AA19+AE19),0) -> 2 | AO19: =B$4-AN19*AA19 -> 15.687125 | AP19: =IF(AN19=AQ19,0,B$4-(AN19*AA19+AQ19*AE19)) -> 0 | AQ19: =MIN(AN19+1,IF(ISERROR(ROUNDDOWN(AO19/AE19,0)),AN19+1,ROUNDDOWN(AO19/AE19,0))) -> 2 | AR19: =AQ19*AG19 -> 516600 | AS19: =Max(0,AO19-AQ19*AE19)-AP19 -> 3.2861605 | AT19: =MIN(N19,IF(AN19<AQ19,0,ROUNDDOWN(IF(AS19=0,0,AS19*(R19/60)+1),0))) -> 4 | AU19: =AT19*L19 -> 147600 | AV19: =Min(AI19,AU19+AR19) -> 664200
B20: Special | C20: FALSE | D20: Glaive | E20: glaive_adaptive | F20: Adaptive | G20: =D20&" - "& F20 -> Glaive - Adaptive | H20: Any | I20: - | J20: - | K20: =VLOOKUP(E20,backend!$BP$5:$BQ57,2,FALSE) -> 23455 | L20: =K20*M20*IF(B20="Special",VLOOKUP(I20,backend!$H$4:$M57,2,FALSE),VLOOKUP(I20,backend!$H$4:$M57,3,FALSE))*IF(B20="Special",VLOOKUP(J20,backend!$H$4:$M57,2,FALSE),VLOOKUP(J20,backend!$H$4:$M57,3,FALSE))*IF($B$8=TRUE,VLOOKUP(D20,BuffsDebuffs!$P$8:$X$27,MATCH(H20,BuffsDebuffs!$P$8:$X$8,0),FALSE),1)*IF($B$6=TRUE,backend!$BN$5,1) -> 23455 | M20: =VLOOKUP(E20,backend!$BP$5:$BS57,4,FALSE) -> 1 | N20: 5 | O20: 7 | P20: =MAX(IFNA(VLOOKUP(IF($B$10=TRUE,O20,N20),backend!$P$4:$Y57,MATCH(I20,backend!$P$3:$Y$3,0),FALSE),IF($B$10=TRUE,O20,N20)),IFNA(VLOOKUP(IF($B$10=TRUE,O20,N20),backend!$P$4:$Y57,MATCH(J20,backend!$P$3:$Y$3,0),FALSE),IF($B$10=TRUE,O20,N20))) -> 5 | Q20: 66 | R20: =Q20/VLOOKUP(I20,backend!$H$4:$N57,7,FALSE)/VLOOKUP(J20,backend!$H$4:$N57,7,FALSE) -> 66 | S20: 27 | T20: 35 | U20: =MAX(IFNA(VLOOKUP(IF($B$9=TRUE,T20,S20),backend!$AA$4:$AF57,MATCH(I20,backend!$AA$3:$AF$3,0),FALSE),IF($B$9=TRUE,T20,S20)),IFNA(VLOOKUP(IF($B$9=TRUE,T20,S20),backend!$AA$4:$AF57,MATCH(J20,backend!$AA$3:$AF$3,0),FALSE),IF($B$9=TRUE,T20,S20))) -> 27 | V20: =VLOOKUP(E20,backend!$BB$4:$BH57,7,FALSE) -> 44.8 | W20: =MIN(100,V20+VLOOKUP(I20,backend!$H$4:$N57,5,FALSE)+VLOOKUP(J20,backend!$H$4:$N57,5,FALSE)+IF($B$11=TRUE,100,0)+IF($B$12,10,0)) -> 44.8 | X20: =(VLOOKUP(D20,backend!$AV$4:$AZ57,2,FALSE)*W20^2+VLOOKUP(D20,backend!$AV$4:$AZ57,3,FALSE)*W20+VLOOKUP(D20,backend!$AV$4:$AZ57,4,FALSE))*VLOOKUP(I20,backend!$H$4:$N57,6,FALSE)*VLOOKUP(J20,backend!$H$4:$N57,6,FALSE)*IF($B$12=TRUE,0.85,1)*IF($B$11=TRUE,0.9,1)*IF(D20="Shotgun",P20,1)*IF(F20="Rapid-Fire",0.8,1)+IF(OR(D20="Fusion Rifle",D20="Linear Fusion Rifle"),0.516,0) -> 2.716 | Y20: 1.35 | Z20: =VLOOKUP(D20,backend!$AV$4:$AZ57,5,FALSE)*IF(D20="Shotgun",P20,1)+IF(OR(D20="Fusion Rifle",D20="Linear Fusion Rifle"),0.516,0) -> 1.35 | AA20: =MAX(X20,Z20) -> 2.716 | AB20: =AJ20/MAX(AJ$15:AJ62)*100 -> 28.438576 | AC20: =AL20/MAX(AL$15:AL62)*100 -> 39.074664 | AD20: =AVERAGE(AB20:AC20) -> 33.75662 | AE20: =60/R20*(P20-1) -> 3.6363636 | AF20: =ROUNDDOWN(U20/P20,0)*AE20+ROUNDDOWN((U20-1)/P20,0)*AA20+Max(0,((U20-ROUNDDOWN(U20/P20,0)*P20)-1)*(60/R20)) -> 32.670909 | AG20: =P20*L20 -> 117275 | AH20: =IF(ISERROR(AG20/AE20),"-",AG20/AE20) -> 32250.625 | AI20: =U20*L20 -> 633285 | AJ20: =ROUNDDOWN(U20/N20,0)*AG20 -> 586375 | AK20: =AI20/AF20 -> 19383.758 | AL20: =IF(P20=1,AK20,MAX(AK20,(ROUNDDOWN(U20/P20,0)*AG20)/(ROUNDDOWN(U20/P20,0)*AE20+(ROUNDDOWN(U20/P20,0)-1)*AA20))) -> 20187.932 | AM20: =IF(P20=U20,AH20,AG20/(AE20+AA20)) -> 18461.632 | AN20: =ROUNDDOWN(B$4/(AA20+AE20),0) -> 3 | AO20: =B$4-AN20*AA20 -> 11.852 | AP20: =IF(AN20=AQ20,0,B$4-(AN20*AA20+AQ20*AE20)) -> 0 | AQ20: =MIN(AN20+1,IF(ISERROR(ROUNDDOWN(AO20/AE20,0)),AN20+1,ROUNDDOWN(AO20/AE20,0))) -> 3 | AR20: =AQ20*AG20 -> 351825 | AS20: =Max(0,AO20-AQ20*AE20)-AP20 -> 0.94290909 | AT20: =MIN(N20,IF(AN20<AQ20,0,ROUNDDOWN(IF(AS20=0,0,AS20*(R20/60)+1),0))) -> 2 | AU20: =AT20*L20 -> 46910 | AV20: =Min(AI20,AU20+AR20) -> 398735
B21: Special | C21: FALSE | D21: Glaive | E21: glaive_aggressive | F21: Aggressive | G21: Glaive - Aggressive | H21: Any | I21: - | J21: - | K21: =VLOOKUP(E21,backend!$BP$5:$BQ57,2,FALSE) -> 26918 | L21: =K21*M21*IF(B21="Special",VLOOKUP(I21,backend!$H$4:$M57,2,FALSE),VLOOKUP(I21,backend!$H$4:$M57,3,FALSE))*IF(B21="Special",VLOOKUP(J21,backend!$H$4:$M57,2,FALSE),VLOOKUP(J21,backend!$H$4:$M57,3,FALSE))*IF($B$8=TRUE,VLOOKUP(D21,BuffsDebuffs!$P$8:$X$27,MATCH(H21,BuffsDebuffs!$P$8:$X$8,0),FALSE),1)*IF($B$6=TRUE,backend!$BN$5,1) -> 26918 | M21: =VLOOKUP(E21,backend!$BP$5:$BS57,4,FALSE) -> 1 | N21: 5 | O21: 7 | P21: =MAX(IFNA(VLOOKUP(IF($B$10=TRUE,O21,N21),backend!$P$4:$Y57,MATCH(I21,backend!$P$3:$Y$3,0),FALSE),IF($B$10=TRUE,O21,N21)),IFNA(VLOOKUP(IF($B$10=TRUE,O21,N21),backend!$P$4:$Y57,MATCH(J21,backend!$P$3:$Y$3,0),FALSE),IF($B$10=TRUE,O21,N21))) -> 5 | Q21: 45 | R21: =Q21/VLOOKUP(I21,backend!$H$4:$N57,7,FALSE)/VLOOKUP(J21,backend!$H$4:$N57,7,FALSE) -> 45 | S21: 27 | T21: 34 | U21: =MAX(IFNA(VLOOKUP(IF($B$9=TRUE,T21,S21),backend!$AA$4:$AF57,MATCH(I21,backend!$AA$3:$AF$3,0),FALSE),IF($B$9=TRUE,T21,S21)),IFNA(VLOOKUP(IF($B$9=TRUE,T21,S21),backend!$AA$4:$AF57,MATCH(J21,backend!$AA$3:$AF$3,0),FALSE),IF($B$9=TRUE,T21,S21))) -> 27 | V21: =VLOOKUP(E21,backend!$BB$4:$BH57,7,FALSE) -> 36 | W21: =MIN(100,V21+VLOOKUP(I21,backend!$H$4:$N57,5,FALSE)+VLOOKUP(J21,backend!$H$4:$N57,5,FALSE)+IF($B$11=TRUE,100,0)+IF($B$12,10,0)) -> 36 | X21: =(VLOOKUP(D21,backend!$AV$4:$AZ57,2,FALSE)*W21^2+VLOOKUP(D21,backend!$AV$4:$AZ57,3,FALSE)*W21+VLOOKUP(D21,backend!$AV$4:$AZ57,4,FALSE))*VLOOKUP(I21,backend!$H$4:$N57,6,FALSE)*VLOOKUP(J21,backend!$H$4:$N57,6,FALSE)*IF($B$12=TRUE,0.85,1)*IF($B$11=TRUE,0.9,1)*IF(D21="Shotgun",P21,1)*IF(F21="Rapid-Fire",0.8,1)+IF(OR(D21="Fusion Rifle",D21="Linear Fusion Rifle"),0.516,0) -> 2.87 | Y21: 1.35 | Z21: =VLOOKUP(D21,backend!$AV$4:$AZ57,5,FALSE)*IF(D21="Shotgun",P21,1)+IF(OR(D21="Fusion Rifle",D21="Linear Fusion Rifle"),0.516,0) -> 1.35 | AA21: =MAX(X21,Z21) -> 2.87 | AB21: =AJ21/MAX(AJ$15:AJ63)*100 -> 32.637373 | AC21: =AL21/MAX(AL$15:AL63)*100 -> 34.145197 | AD21: =AVERAGE(AB21:AC21) -> 33.391285 | AE21: =60/R21*(P21-1) -> 5.3333333 | AF21: =ROUNDDOWN(U21/P21,0)*AE21+ROUNDDOWN((U21-1)/P21,0)*AA21+Max(0,((U21-ROUNDDOWN(U21/P21,0)*P21)-1)*(60/R21)) -> 42.35 | AG21: =P21*L21 -> 134590 | AH21: =IF(ISERROR(AG21/AE21),"-",AG21/AE21) -> 25235.625 | AI21: =U21*L21 -> 726786 | AJ21: =ROUNDDOWN(U21/N21,0)*AG21 -> 672950 | AK21: =AI21/AF21 -> 17161.417 | AL21: =IF(P21=1,AK21,MAX(AK21,(ROUNDDOWN(U21/P21,0)*AG21)/(ROUNDDOWN(U21/P21,0)*AE21+(ROUNDDOWN(U21/P21,0)-1)*AA21))) -> 17641.122 | AM21: =IF(P21=U21,AH21,AG21/(AE21+AA21)) -> 16406.745 | AN21: =ROUNDDOWN(B$4/(AA21+AE21),0) -> 2 | AO21: =B$4-AN21*AA21 -> 14.26 | AP21: =IF(AN21=AQ21,0,B$4-(AN21*AA21+AQ21*AE21)) -> 0 | AQ21: =MIN(AN21+1,IF(ISERROR(ROUNDDOWN(AO21/AE21,0)),AN21+1,ROUNDDOWN(AO21/AE21,0))) -> 2 | AR21: =AQ21*AG21 -> 269180 | AS21: =Max(0,AO21-AQ21*AE21)-AP21 -> 3.5933333 | AT21: =MIN(N21,IF(AN21<AQ21,0,ROUNDDOWN(IF(AS21=0,0,AS21*(R21/60)+1),0))) -> 3 | AU21: =AT21*L21 -> 80754 | AV21: =Min(AI21,AU21+AR21) -> 349934
B22: Special | C22: FALSE | D22: Glaive | E22: glaive_rf | F22: Rapid-Fire | G22: =D22&" - "& F22 -> Glaive - Rapid-Fire | H22: Any | I22: - | J22: - | K22: =VLOOKUP(E22,backend!$BP$5:$BQ57,2,FALSE) -> 18469 | L22: =K22*M22*IF(B22="Special",VLOOKUP(I22,backend!$H$4:$M57,2,FALSE),VLOOKUP(I22,backend!$H$4:$M57,3,FALSE))*IF(B22="Special",VLOOKUP(J22,backend!$H$4:$M57,2,FALSE),VLOOKUP(J22,backend!$H$4:$M57,3,FALSE))*IF($B$8=TRUE,VLOOKUP(D22,BuffsDebuffs!$P$8:$X$27,MATCH(H22,BuffsDebuffs!$P$8:$X$8,0),FALSE),1)*IF($B$6=TRUE,backend!$BN$5,1) -> 18469 | M22: =VLOOKUP(E22,backend!$BP$5:$BS57,4,FALSE) -> 1 | N22: 5 | O22: 7 | P22: =MAX(IFNA(VLOOKUP(IF($B$10=TRUE,O22,N22),backend!$P$4:$Y57,MATCH(I22,backend!$P$3:$Y$3,0),FALSE),IF($B$10=TRUE,O22,N22)),IFNA(VLOOKUP(IF($B$10=TRUE,O22,N22),backend!$P$4:$Y57,MATCH(J22,backend!$P$3:$Y$3,0),FALSE),IF($B$10=TRUE,O22,N22))) -> 5 | Q22: 80 | R22: =Q22/VLOOKUP(I22,backend!$H$4:$N57,7,FALSE)/VLOOKUP(J22,backend!$H$4:$N57,7,FALSE) -> 80 | S22: 30 | T22: 36 | U22: =MAX(IFNA(VLOOKUP(IF($B$9=TRUE,T22,S22),backend!$AA$4:$AF57,MATCH(I22,backend!$AA$3:$AF$3,0),FALSE),IF($B$9=TRUE,T22,S22)),IFNA(VLOOKUP(IF($B$9=TRUE,T22,S22),backend!$AA$4:$AF57,MATCH(J22,backend!$AA$3:$AF$3,0),FALSE),IF($B$9=TRUE,T22,S22))) -> 30 | V22: =VLOOKUP(E22,backend!$BB$4:$BH57,7,FALSE) -> 66 | W22: =MIN(100,V22+VLOOKUP(I22,backend!$H$4:$N57,5,FALSE)+VLOOKUP(J22,backend!$H$4:$N57,5,FALSE)+IF($B$11=TRUE,100,0)+IF($B$12,10,0)) -> 66 | X22: =(VLOOKUP(D22,backend!$AV$4:$AZ57,2,FALSE)*W22^2+VLOOKUP(D22,backend!$AV$4:$AZ57,3,FALSE)*W22+VLOOKUP(D22,backend!$AV$4:$AZ57,4,FALSE))*VLOOKUP(I22,backend!$H$4:$N57,6,FALSE)*VLOOKUP(J22,backend!$H$4:$N57,6,FALSE)*IF($B$12=TRUE,0.85,1)*IF($B$11=TRUE,0.9,1)*IF(D22="Shotgun",P22,1)*IF(F22="Rapid-Fire",0.8,1)+IF(OR(D22="Fusion Rifle",D22="Linear Fusion Rifle"),0.516,0) -> 1.876 | Y22: 1.35 | Z22: =VLOOKUP(D22,backend!$AV$4:$AZ57,5,FALSE)*IF(D22="Shotgun",P22,1)+IF(OR(D22="Fusion Rifle",D22="Linear Fusion Rifle"),0.516,0) -> 1.35 | AA22: =MAX(X22,Z22) -> 1.876 | AB22: =AJ22/MAX(AJ$15:AJ64)*100 -> 26.871817 | AC22: =AL22/MAX(AL$15:AL64)*100 -> 39.168291 | AD22: =AVERAGE(AB22:AC22) -> 33.020054 | AE22: =60/R22*(P22-1) -> 3 | AF22: =ROUNDDOWN(U22/P22,0)*AE22+ROUNDDOWN((U22-1)/P22,0)*AA22+Max(0,((U22-ROUNDDOWN(U22/P22,0)*P22)-1)*(60/R22)) -> 27.38 | AG22: =P22*L22 -> 92345 | AH22: =IF(ISERROR(AG22/AE22),"-",AG22/AE22) -> 30781.667 | AI22: =U22*L22 -> 554070 | AJ22: =ROUNDDOWN(U22/N22,0)*AG22 -> 554070 | AK22: =AI22/AF22 -> 20236.304 | AL22: =IF(P22=1,AK22,MAX(AK22,(ROUNDDOWN(U22/P22,0)*AG22)/(ROUNDDOWN(U22/P22,0)*AE22+(ROUNDDOWN(U22/P22,0)-1)*AA22))) -> 20236.304 | AM22: =IF(P22=U22,AH22,AG22/(AE22+AA22)) -> 18938.679 | AN22: =ROUNDDOWN(B$4/(AA22+AE22),0) -> 4 | AO22: =B$4-AN22*AA22 -> 12.496 | AP22: =IF(AN22=AQ22,0,B$4-(AN22*AA22+AQ22*AE22)) -> 0 | AQ22: =MIN(AN22+1,IF(ISERROR(ROUNDDOWN(AO22/AE22,0)),AN22+1,ROUNDDOWN(AO22/AE22,0))) -> 4 | AR22: =AQ22*AG22 -> 369380 | AS22: =Max(0,AO22-AQ22*AE22)-AP22 -> 0.496 | AT22: =MIN(N22,IF(AN22<AQ22,0,ROUNDDOWN(IF(AS22=0,0,AS22*(R22/60)+1),0))) -> 1 | AU22: =AT22*L22 -> 18469 | AV22: =Min(AI22,AU22+AR22) -> 387849
B23: Special | C23: FALSE | D23: Grenade Launcher | E23: gl_ad | F23: Aera Denial | G23: =D23&" - "& F23 -> Grenade Launcher - Aera Denial | H23: Any | I23: - | J23: - | K23: =VLOOKUP(E23,backend!$BP$5:$BQ57,2,FALSE) -> 51012 | L23: =K23*M23*IF(B23="Special",VLOOKUP(I23,backend!$H$4:$M57,2,FALSE),VLOOKUP(I23,backend!$H$4:$M57,3,FALSE))*IF(B23="Special",VLOOKUP(J23,backend!$H$4:$M57,2,FALSE),VLOOKUP(J23,backend!$H$4:$M57,3,FALSE))*IF($B$8=TRUE,VLOOKUP(D23,BuffsDebuffs!$P$8:$X$27,MATCH(H23,BuffsDebuffs!$P$8:$X$8,0),FALSE),1)*IF($B$6=TRUE,backend!$BN$5,1) -> 51012 | M23: =VLOOKUP(E23,backend!$BP$5:$BS57,4,FALSE) -> 1 | N23: 1 | O23: 1 | P23: =MAX(IFNA(VLOOKUP(IF($B$10=TRUE,O23,N23),backend!$P$4:$Y57,MATCH(I23,backend!$P$3:$Y$3,0),FALSE),IF($B$10=TRUE,O23,N23)),IFNA(VLOOKUP(IF($B$10=TRUE,O23,N23),backend!$P$4:$Y57,MATCH(J23,backend!$P$3:$Y$3,0),FALSE),IF($B$10=TRUE,O23,N23))) -> 1 | Q23: 10 | R23: =Q23/VLOOKUP(I23,backend!$H$4:$N57,7,FALSE)/VLOOKUP(J23,backend!$H$4:$N57,7,FALSE) -> 10 | S23: 24 | T23: 25 | U23: =MAX(IFNA(VLOOKUP(IF($B$9=TRUE,T23,S23),backend!$AA$4:$AF57,MATCH(I23,backend!$AA$3:$AF$3,0),FALSE),IF($B$9=TRUE,T23,S23)),IFNA(VLOOKUP(IF($B$9=TRUE,T23,S23),backend!$AA$4:$AF57,MATCH(J23,backend!$AA$3:$AF$3,0),FALSE),IF($B$9=TRUE,T23,S23))) -> 24 | V23: =VLOOKUP(E23,backend!$BB$4:$BH57,7,FALSE) -> 67.5 | W23: =MIN(100,V23+VLOOKUP(I23,backend!$H$4:$N57,5,FALSE)+VLOOKUP(J23,backend!$H$4:$N57,5,FALSE)+IF($B$11=TRUE,100,0)+IF($B$12,10,0)) -> 67.5 | X23: =(VLOOKUP(D23,backend!$AV$4:$AZ57,2,FALSE)*W23^2+VLOOKUP(D23,backend!$AV$4:$AZ57,3,FALSE)*W23+VLOOKUP(D23,backend!$AV$4:$AZ57,4,FALSE))*VLOOKUP(I23,backend!$H$4:$N57,6,FALSE)*VLOOKUP(J23,backend!$H$4:$N57,6,FALSE)*IF($B$12=TRUE,0.85,1)*IF($B$11=TRUE,0.9,1)*IF(D23="Shotgun",P23,1)*IF(F23="Rapid-Fire",0.8,1)+IF(OR(D23="Fusion Rifle",D23="Linear Fusion Rifle"),0.516,0) -> 2.1100932 | Y23: 1.5 | Z23: =VLOOKUP(D23,backend!$AV$4:$AZ57,5,FALSE)*IF(D23="Shotgun",P23,1)+IF(OR(D23="Fusion Rifle",D23="Linear Fusion Rifle"),0.516,0) -> 1.5 | AA23: =MAX(X23,Z23) -> 2.1100932 | AB23: =AJ23/MAX(AJ$15:AJ65)*100 -> 59.376691 | AC23: =AL23/MAX(AL$15:AL65)*100 -> 48.826718 | AD23: =AVERAGE(AB23:AC23) -> 54.101705 | AE23: =60/R23*(P23-1) -> 0 | AF23: =ROUNDDOWN(U23/P23,0)*AE23+ROUNDDOWN((U23-1)/P23,0)*AA23+Max(0,((U23-ROUNDDOWN(U23/P23,0)*P23)-1)*(60/R23)) -> 48.532144 | AG23: =P23*L23 -> 51012 | AH23: =IF(ISERROR(AG23/AE23),"-",AG23/AE23) -> - | AI23: =U23*L23 -> 1224288 | AJ23: =ROUNDDOWN(U23/N23,0)*AG23 -> 1224288 | AK23: =AI23/AF23 -> 25226.332 | AL23: =IF(P23=1,AK23,MAX(AK23,(ROUNDDOWN(U23/P23,0)*AG23)/(ROUNDDOWN(U23/P23,0)*AE23+(ROUNDDOWN(U23/P23,0)-1)*AA23))) -> 25226.332 | AM23: =IF(P23=U23,AH23,AG23/(AE23+AA23)) -> 24175.235 | AN23: =ROUNDDOWN(B$4/(AA23+AE23),0) -> 9 | AO23: =B$4-AN23*AA23 -> 1.0091609 | AP23: =IF(AN23=AQ23,0,B$4-(AN23*AA23+AQ23*AE23)) -> 1.0091609 | AQ23: =MIN(AN23+1,IF(ISERROR(ROUNDDOWN(AO23/AE23,0)),AN23+1,ROUNDDOWN(AO23/AE23,0))) -> 10 | AR23: =AQ23*AG23 -> 510120 | AS23: =Max(0,AO23-AQ23*AE23)-AP23 -> 0 | AT23: =MIN(N23,IF(AN23<AQ23,0,ROUNDDOWN(IF(AS23=0,0,AS23*(R23/60)+1),0))) -> 0 | AU23: =AT23*L23 -> 0 | AV23: =Min(AI23,AU23+AR23) -> 510120
B24: Special | C24: FALSE | D24: Grenade Launcher | E24: gl_df | F24: Double-Fire | G24: =D24&" - "& F24 -> Grenade Launcher - Double-Fire | H24: Any | I24: - | J24: - | K24: =VLOOKUP(E24,backend!$BP$5:$BQ57,2,FALSE) -> 38380 | L24: =K24*M24*IF(B24="Special",VLOOKUP(I24,backend!$H$4:$M57,2,FALSE),VLOOKUP(I24,backend!$H$4:$M57,3,FALSE))*IF(B24="Special",VLOOKUP(J24,backend!$H$4:$M57,2,FALSE),VLOOKUP(J24,backend!$H$4:$M57,3,FALSE))*IF($B$8=TRUE,VLOOKUP(D24,BuffsDebuffs!$P$8:$X$27,MATCH(H24,BuffsDebuffs!$P$8:$X$8,0),FALSE),1)*IF($B$6=TRUE,backend!$BN$5,1) -> 38380 | M24: =VLOOKUP(E24,backend!$BP$5:$BS57,4,FALSE) -> 1 | N24: 1 | O24: 1 | P24: =MAX(IFNA(VLOOKUP(IF($B$10=TRUE,O24,N24),backend!$P$4:$Y57,MATCH(I24,backend!$P$3:$Y$3,0),FALSE),IF($B$10=TRUE,O24,N24)),IFNA(VLOOKUP(IF($B$10=TRUE,O24,N24),backend!$P$4:$Y57,MATCH(J24,backend!$P$3:$Y$3,0),FALSE),IF($B$10=TRUE,O24,N24))) -> 1 | Q24: 100 | R24: =Q24/VLOOKUP(I24,backend!$H$4:$N57,7,FALSE)/VLOOKUP(J24,backend!$H$4:$N57,7,FALSE) -> 100 | S24: 22 | T24: 24 | U24: =MAX(IFNA(VLOOKUP(IF($B$9=TRUE,T24,S24),backend!$AA$4:$AF57,MATCH(I24,backend!$AA$3:$AF$3,0),FALSE),IF($B$9=TRUE,T24,S24)),IFNA(VLOOKUP(IF($B$9=TRUE,T24,S24),backend!$AA$4:$AF57,MATCH(J24,backend!$AA$3:$AF$3,0),FALSE),IF($B$9=TRUE,T24,S24))) -> 22 | V24: =VLOOKUP(E24,backend!$BB$4:$BH57,7,FALSE) -> 34.333333 | W24: =MIN(100,V24+VLOOKUP(I24,backend!$H$4:$N57,5,FALSE)+VLOOKUP(J24,backend!$H$4:$N57,5,FALSE)+IF($B$11=TRUE,100,0)+IF($B$12,10,0)) -> 34.333333 | X24: =(VLOOKUP(D24,backend!$AV$4:$AZ57,2,FALSE)*W24^2+VLOOKUP(D24,backend!$AV$4:$AZ57,3,FALSE)*W24+VLOOKUP(D24,backend!$AV$4:$AZ57,4,FALSE))*VLOOKUP(I24,backend!$H$4:$N57,6,FALSE)*VLOOKUP(J24,backend!$H$4:$N57,6,FALSE)*IF($B$12=TRUE,0.85,1)*IF($B$11=TRUE,0.9,1)*IF(D24="Shotgun",P24,1)*IF(F24="Rapid-Fire",0.8,1)+IF(OR(D24="Fusion Rifle",D24="Linear Fusion Rifle"),0.516,0) -> 2.5833298 | Y24: 1.5 | Z24: =VLOOKUP(D24,backend!$AV$4:$AZ57,5,FALSE)*IF(D24="Shotgun",P24,1)+IF(OR(D24="Fusion Rifle",D24="Linear Fusion Rifle"),0.516,0) -> 1.5 | AA24: =MAX(X24,Z24) -> 2.5833298 | AB24: =AJ24/MAX(AJ$15:AJ66)*100 -> 40.95058 | AC24: =AL24/MAX(AL$15:AL66)*100 -> 30.125338 | AD24: =AVERAGE(AB24:AC24) -> 35.537959 | AE24: =60/R24*(P24-1) -> 0 | AF24: =ROUNDDOWN(U24/P24,0)*AE24+ROUNDDOWN((U24-1)/P24,0)*AA24+Max(0,((U24-ROUNDDOWN(U24/P24,0)*P24)-1)*(60/R24)) -> 54.249927 | AG24: =P24*L24 -> 38380 | AH24: =IF(ISERROR(AG24/AE24),"-",AG24/AE24) -> - | AI24: =U24*L24 -> 844360 | AJ24: =ROUNDDOWN(U24/N24,0)*AG24 -> 844360 | AK24: =AI24/AF24 -> 15564.261 | AL24: =IF(P24=1,AK24,MAX(AK24,(ROUNDDOWN(U24/P24,0)*AG24)/(ROUNDDOWN(U24/P24,0)*AE24+(ROUNDDOWN(U24/P24,0)-1)*AA24))) -> 15564.261 | AM24: =IF(P24=U24,AH24,AG24/(AE24+AA24)) -> 14856.794 | AN24: =ROUNDDOWN(B$4/(AA24+AE24),0) -> 7 | AO24: =B$4-AN24*AA24 -> 1.9166912 | AP24: =IF(AN24=AQ24,0,B$4-(AN24*AA24+AQ24*AE24)) -> 1.9166912 | AQ24: =MIN(AN24+1,IF(ISERROR(ROUNDDOWN(AO24/AE24,0)),AN24+1,ROUNDDOWN(AO24/AE24,0))) -> 8 | AR24: =AQ24*AG24 -> 307040 | AS24: =Max(0,AO24-AQ24*AE24)-AP24 -> 0 | AT24: =MIN(N24,IF(AN24<AQ24,0,ROUNDDOWN(IF(AS24=0,0,AS24*(R24/60)+1),0))) -> 0 | AU24: =AT24*L24 -> 0 | AV24: =Min(AI24,AU24+AR24) -> 307040
B25: Special | C25: FALSE | D25: Grenade Launcher | E25: gl_lw | F25: Lightweight | G25: =D25&" - "& F25 -> Grenade Launcher - Lightweight | H25: Any | I25: - | J25: - | K25: =VLOOKUP(E25,backend!$BP$5:$BQ57,2,FALSE) -> 30838 | L25: =K25*M25*IF(B25="Special",VLOOKUP(I25,backend!$H$4:$M57,2,FALSE),VLOOKUP(I25,backend!$H$4:$M57,3,FALSE))*IF(B25="Special",VLOOKUP(J25,backend!$H$4:$M57,2,FALSE),VLOOKUP(J25,backend!$H$4:$M57,3,FALSE))*IF($B$8=TRUE,VLOOKUP(D25,BuffsDebuffs!$P$8:$X$27,MATCH(H25,BuffsDebuffs!$P$8:$X$8,0),FALSE),1)*IF($B$6=TRUE,backend!$BN$5,1) -> 30838 | M25: =VLOOKUP(E25,backend!$BP$5:$BS57,4,FALSE) -> 1 | N25: 1 | O25: 1 | P25: =MAX(IFNA(VLOOKUP(IF($B$10=TRUE,O25,N25),backend!$P$4:$Y57,MATCH(I25,backend!$P$3:$Y$3,0),FALSE),IF($B$10=TRUE,O25,N25)),IFNA(VLOOKUP(IF($B$10=TRUE,O25,N25),backend!$P$4:$Y57,MATCH(J25,backend!$P$3:$Y$3,0),FALSE),IF($B$10=TRUE,O25,N25))) -> 1 | Q25: 90 | R25: =Q25/VLOOKUP(I25,backend!$H$4:$N57,7,FALSE)/VLOOKUP(J25,backend!$H$4:$N57,7,FALSE) -> 90 | S25: 24 | T25: 25 | U25: =MAX(IFNA(VLOOKUP(IF($B$9=TRUE,T25,S25),backend!$AA$4:$AF57,MATCH(I25,backend!$AA$3:$AF$3,0),FALSE),IF($B$9=TRUE,T25,S25)),IFNA(VLOOKUP(IF($B$9=TRUE,T25,S25),backend!$AA$4:$AF57,MATCH(J25,backend!$AA$3:$AF$3,0),FALSE),IF($B$9=TRUE,T25,S25))) -> 24 | V25: =VLOOKUP(E25,backend!$BB$4:$BH57,7,FALSE) -> 66 | W25: =MIN(100,V25+VLOOKUP(I25,backend!$H$4:$N57,5,FALSE)+VLOOKUP(J25,backend!$H$4:$N57,5,FALSE)+IF($B$11=TRUE,100,0)+IF($B$12,10,0)) -> 66 | X25: =(VLOOKUP(D25,backend!$AV$4:$AZ57,2,FALSE)*W25^2+VLOOKUP(D25,backend!$AV$4:$AZ57,3,FALSE)*W25+VLOOKUP(D25,backend!$AV$4:$AZ57,4,FALSE))*VLOOKUP(I25,backend!$H$4:$N57,6,FALSE)*VLOOKUP(J25,backend!$H$4:$N57,6,FALSE)*IF($B$12=TRUE,0.85,1)*IF($B$11=TRUE,0.9,1)*IF(D25="Shotgun",P25,1)*IF(F25="Rapid-Fire",0.8,1)+IF(OR(D25="Fusion Rifle",D25="Linear Fusion Rifle"),0.516,0) -> 2.128056 | Y25: 1.5 | Z25: =VLOOKUP(D25,backend!$AV$4:$AZ57,5,FALSE)*IF(D25="Shotgun",P25,1)+IF(OR(D25="Fusion Rifle",D25="Linear Fusion Rifle"),0.516,0) -> 1.5 | AA25: =MAX(X25,Z25) -> 2.128056 | AB25: =AJ25/MAX(AJ$15:AJ67)*100 -> 35.89466 | AC25: =AL25/MAX(AL$15:AL67)*100 -> 29.267794 | AD25: =AVERAGE(AB25:AC25) -> 32.581227 | AE25: =60/R25*(P25-1) -> 0 | AF25: =ROUNDDOWN(U25/P25,0)*AE25+ROUNDDOWN((U25-1)/P25,0)*AA25+Max(0,((U25-ROUNDDOWN(U25/P25,0)*P25)-1)*(60/R25)) -> 48.945287 | AG25: =P25*L25 -> 30838 | AH25: =IF(ISERROR(AG25/AE25),"-",AG25/AE25) -> - | AI25: =U25*L25 -> 740112 | AJ25: =ROUNDDOWN(U25/N25,0)*AG25 -> 740112 | AK25: =AI25/AF25 -> 15121.211 | AL25: =IF(P25=1,AK25,MAX(AK25,(ROUNDDOWN(U25/P25,0)*AG25)/(ROUNDDOWN(U25/P25,0)*AE25+(ROUNDDOWN(U25/P25,0)-1)*AA25))) -> 15121.211 | AM25: =IF(P25=U25,AH25,AG25/(AE25+AA25)) -> 14491.16 | AN25: =ROUNDDOWN(B$4/(AA25+AE25),0) -> 9 | AO25: =B$4-AN25*AA25 -> 0.84749644 | AP25: =IF(AN25=AQ25,0,B$4-(AN25*AA25+AQ25*AE25)) -> 0.84749644 | AQ25: =MIN(AN25+1,IF(ISERROR(ROUNDDOWN(AO25/AE25,0)),AN25+1,ROUNDDOWN(AO25/AE25,0))) -> 10 | AR25: =AQ25*AG25 -> 308380 | AS25: =Max(0,AO25-AQ25*AE25)-AP25 -> 0 | AT25: =MIN(N25,IF(AN25<AQ25,0,ROUNDDOWN(IF(AS25=0,0,AS25*(R25/60)+1),0))) -> 0 | AU25: =AT25*L25 -> 0 | AV25: =Min(AI25,AU25+AR25) -> 308380
B26: Special | C26: FALSE | D26: Grenade Launcher | E26: gl_mm | F26: Micro-Missile | G26: =D26&" - "& F26 -> Grenade Launcher - Micro-Missile | H26: Any | I26: - | J26: - | K26: =VLOOKUP(E26,backend!$BP$5:$BQ57,2,FALSE) -> 39711 | L26: =K26*M26*IF(B26="Special",VLOOKUP(I26,backend!$H$4:$M57,2,FALSE),VLOOKUP(I26,backend!$H$4:$M57,3,FALSE))*IF(B26="Special",VLOOKUP(J26,backend!$H$4:$M57,2,FALSE),VLOOKUP(J26,backend!$H$4:$M57,3,FALSE))*IF($B$8=TRUE,VLOOKUP(D26,BuffsDebuffs!$P$8:$X$27,MATCH(H26,BuffsDebuffs!$P$8:$X$8,0),FALSE),1)*IF($B$6=TRUE,backend!$BN$5,1) -> 39711 | M26: =VLOOKUP(E26,backend!$BP$5:$BS57,4,FALSE) -> 1 | N26: 1 | O26: 1 | P26: =MAX(IFNA(VLOOKUP(IF($B$10=TRUE,O26,N26),backend!$P$4:$Y57,MATCH(I26,backend!$P$3:$Y$3,0),FALSE),IF($B$10=TRUE,O26,N26)),IFNA(VLOOKUP(IF($B$10=TRUE,O26,N26),backend!$P$4:$Y57,MATCH(J26,backend!$P$3:$Y$3,0),FALSE),IF($B$10=TRUE,O26,N26))) -> 1 | Q26: 90 | R26: =Q26/VLOOKUP(I26,backend!$H$4:$N57,7,FALSE)/VLOOKUP(J26,backend!$H$4:$N57,7,FALSE) -> 90 | S26: 24 | T26: 25 | U26: =MAX(IFNA(VLOOKUP(IF($B$9=TRUE,T26,S26),backend!$AA$4:$AF57,MATCH(I26,backend!$AA$3:$AF$3,0),FALSE),IF($B$9=TRUE,T26,S26)),IFNA(VLOOKUP(IF($B$9=TRUE,T26,S26),backend!$AA$4:$AF57,MATCH(J26,backend!$AA$3:$AF$3,0),FALSE),IF($B$9=TRUE,T26,S26))) -> 24 | V26: =VLOOKUP(E26,backend!$BB$4:$BH57,7,FALSE) -> 63 | W26: =MIN(100,V26+VLOOKUP(I26,backend!$H$4:$N57,5,FALSE)+VLOOKUP(J26,backend!$H$4:$N57,5,FALSE)+IF($B$11=TRUE,100,0)+IF($B$12,10,0)) -> 63 | X26: =(VLOOKUP(D26,backend!$AV$4:$AZ57,2,FALSE)*W26^2+VLOOKUP(D26,backend!$AV$4:$AZ57,3,FALSE)*W26+VLOOKUP(D26,backend!$AV$4:$AZ57,4,FALSE))*VLOOKUP(I26,backend!$H$4:$N57,6,FALSE)*VLOOKUP(J26,backend!$H$4:$N57,6,FALSE)*IF($B$12=TRUE,0.85,1)*IF($B$11=TRUE,0.9,1)*IF(D26="Shotgun",P26,1)*IF(F26="Rapid-Fire",0.8,1)+IF(OR(D26="Fusion Rifle",D26="Linear Fusion Rifle"),0.516,0) -> 2.1649591 | Y26: 1.5 | Z26: =VLOOKUP(D26,backend!$AV$4:$AZ57,5,FALSE)*IF(D26="Shotgun",P26,1)+IF(OR(D26="Fusion Rifle",D26="Linear Fusion Rifle"),0.516,0) -> 1.5 | AA26: =MAX(X26,Z26) -> 2.1649591 | AB26: =AJ26/MAX(AJ$15:AJ68)*100 -> 46.22261 | AC26: =AL26/MAX(AL$15:AL68)*100 -> 37.046567 | AD26: =AVERAGE(AB26:AC26) -> 41.634589 | AE26: =60/R26*(P26-1) -> 0 | AF26: =ROUNDDOWN(U26/P26,0)*AE26+ROUNDDOWN((U26-1)/P26,0)*AA26+Max(0,((U26-ROUNDDOWN(U26/P26,0)*P26)-1)*(60/R26)) -> 49.794058 | AG26: =P26*L26 -> 39711 | AH26: =IF(ISERROR(AG26/AE26),"-",AG26/AE26) -> - | AI26: =U26*L26 -> 953064 | AJ26: =ROUNDDOWN(U26/N26,0)*AG26 -> 953064 | AK26: =AI26/AF26 -> 19140.115 | AL26: =IF(P26=1,AK26,MAX(AK26,(ROUNDDOWN(U26/P26,0)*AG26)/(ROUNDDOWN(U26/P26,0)*AE26+(ROUNDDOWN(U26/P26,0)-1)*AA26))) -> 19140.115 | AM26: =IF(P26=U26,AH26,AG26/(AE26+AA26)) -> 18342.61 | AN26: =ROUNDDOWN(B$4/(AA26+AE26),0) -> 9 | AO26: =B$4-AN26*AA26 -> 0.51536855 | AP26: =IF(AN26=AQ26,0,B$4-(AN26*AA26+AQ26*AE26)) -> 0.51536855 | AQ26: =MIN(AN26+1,IF(ISERROR(ROUNDDOWN(AO26/AE26,0)),AN26+1,ROUNDDOWN(AO26/AE26,0))) -> 10 | AR26: =AQ26*AG26 -> 397110 | AS26: =Max(0,AO26-AQ26*AE26)-AP26 -> 0 | AT26: =MIN(N26,IF(AN26<AQ26,0,ROUNDDOWN(IF(AS26=0,0,AS26*(R26/60)+1),0))) -> 0 | AU26: =AT26*L26 -> 0 | AV26: =Min(AI26,AU26+AR26) -> 397110
B27: Special | C27: FALSE | D27: Grenade Launcher | E27: gl_wave | F27: Wave | G27: =D27&" - "& F27 -> Grenade Launcher - Wave | H27: Any | I27: - | J27: - | K27: =VLOOKUP(E27,backend!$BP$5:$BQ57,2,FALSE) -> 22413 | L27: =K27*M27*IF(B27="Special",VLOOKUP(I27,backend!$H$4:$M57,2,FALSE),VLOOKUP(I27,backend!$H$4:$M57,3,FALSE))*IF(B27="Special",VLOOKUP(J27,backend!$H$4:$M57,2,FALSE),VLOOKUP(J27,backend!$H$4:$M57,3,FALSE))*IF($B$8=TRUE,VLOOKUP(D27,BuffsDebuffs!$P$8:$X$27,MATCH(H27,BuffsDebuffs!$P$8:$X$8,0),FALSE),1)*IF($B$6=TRUE,backend!$BN$5,1) -> 22413 | M27: =VLOOKUP(E27,backend!$BP$5:$BS57,4,FALSE) -> 1 | N27: 1 | O27: 1 | P27: =MAX(IFNA(VLOOKUP(IF($B$10=TRUE,O27,N27),backend!$P$4:$Y57,MATCH(I27,backend!$P$3:$Y$3,0),FALSE),IF($B$10=TRUE,O27,N27)),IFNA(VLOOKUP(IF($B$10=TRUE,O27,N27),backend!$P$4:$Y57,MATCH(J27,backend!$P$3:$Y$3,0),FALSE),IF($B$10=TRUE,O27,N27))) -> 1 | Q27: 90 | R27: =Q27/VLOOKUP(I27,backend!$H$4:$N57,7,FALSE)/VLOOKUP(J27,backend!$H$4:$N57,7,FALSE) -> 90 | S27: 24 | T27: 25 | U27: =MAX(IFNA(VLOOKUP(IF($B$9=TRUE,T27,S27),backend!$AA$4:$AF57,MATCH(I27,backend!$AA$3:$AF$3,0),FALSE),IF($B$9=TRUE,T27,S27)),IFNA(VLOOKUP(IF($B$9=TRUE,T27,S27),backend!$AA$4:$AF57,MATCH(J27,backend!$AA$3:$AF$3,0),FALSE),IF($B$9=TRUE,T27,S27))) -> 24 | V27: =VLOOKUP(E27,backend!$BB$4:$BH57,7,FALSE) -> 68.4 | W27: =MIN(100,V27+VLOOKUP(I27,backend!$H$4:$N57,5,FALSE)+VLOOKUP(J27,backend!$H$4:$N57,5,FALSE)+IF($B$11=TRUE,100,0)+IF($B$12,10,0)) -> 68.4 | X27: =(VLOOKUP(D27,backend!$AV$4:$AZ57,2,FALSE)*W27^2+VLOOKUP(D27,backend!$AV$4:$AZ57,3,FALSE)*W27+VLOOKUP(D27,backend!$AV$4:$AZ57,4,FALSE))*VLOOKUP(I27,backend!$H$4:$N57,6,FALSE)*VLOOKUP(J27,backend!$H$4:$N57,6,FALSE)*IF($B$12=TRUE,0.85,1)*IF($B$11=TRUE,0.9,1)*IF(D27="Shotgun",P27,1)*IF(F27="Rapid-Fire",0.8,1)+IF(OR(D27="Fusion Rifle",D27="Linear Fusion Rifle"),0.516,0) -> 2.099472 | Y27: 1.5 | Z27: =VLOOKUP(D27,backend!$AV$4:$AZ57,5,FALSE)*IF(D27="Shotgun",P27,1)+IF(OR(D27="Fusion Rifle",D27="Linear Fusion Rifle"),0.516,0) -> 1.5 | AA27: =MAX(X27,Z27) -> 2.099472 | AB27: =AJ27/MAX(AJ$15:AJ69)*100 -> 26.088171 | AC27: =AL27/MAX(AL$15:AL69)*100 -> 21.561389 | AD27: =AVERAGE(AB27:AC27) -> 23.82478 | AE27: =60/R27*(P27-1) -> 0 | AF27: =ROUNDDOWN(U27/P27,0)*AE27+ROUNDDOWN((U27-1)/P27,0)*AA27+Max(0,((U27-ROUNDDOWN(U27/P27,0)*P27)-1)*(60/R27)) -> 48.287857 | AG27: =P27*L27 -> 22413 | AH27: =IF(ISERROR(AG27/AE27),"-",AG27/AE27) -> - | AI27: =U27*L27 -> 537912 | AJ27: =ROUNDDOWN(U27/N27,0)*AG27 -> 537912 | AK27: =AI27/AF27 -> 11139.695 | AL27: =IF(P27=1,AK27,MAX(AK27,(ROUNDDOWN(U27/P27,0)*AG27)/(ROUNDDOWN(U27/P27,0)*AE27+(ROUNDDOWN(U27/P27,0)-1)*AA27))) -> 11139.695 | AM27: =IF(P27=U27,AH27,AG27/(AE27+AA27)) -> 10675.541 | AN27: =ROUNDDOWN(B$4/(AA27+AE27),0) -> 9 | AO27: =B$4-AN27*AA27 -> 1.1047517 | AP27: =IF(AN27=AQ27,0,B$4-(AN27*AA27+AQ27*AE27)) -> 1.1047517 | AQ27: =MIN(AN27+1,IF(ISERROR(ROUNDDOWN(AO27/AE27,0)),AN27+1,ROUNDDOWN(AO27/AE27,0))) -> 10 | AR27: =AQ27*AG27 -> 224130 | AS27: =Max(0,AO27-AQ27*AE27)-AP27 -> 0 | AT27: =MIN(N27,IF(AN27<AQ27,0,ROUNDDOWN(IF(AS27=0,0,AS27*(R27/60)+1),0))) -> 0 | AU27: =AT27*L27 -> 0 | AV27: =Min(AI27,AU27+AR27) -> 224130
B28: Heavy | C28: FALSE | D28: Heavy Grenade Launcher | E28: hgl_adaptive | F28: Adaptive | G28: =D28&" - "& F28 -> Heavy Grenade Launcher - Adaptive | H28: Any | I28: - | J28: - | K28: =VLOOKUP(E28,backend!$BP$5:$BQ57,2,FALSE) -> 42180 | L28: =K28*M28*IF(B28="Special",VLOOKUP(I28,backend!$H$4:$M57,2,FALSE),VLOOKUP(I28,backend!$H$4:$M57,3,FALSE))*IF(B28="Special",VLOOKUP(J28,backend!$H$4:$M57,2,FALSE),VLOOKUP(J28,backend!$H$4:$M57,3,FALSE))*IF($B$8=TRUE,VLOOKUP(D28,BuffsDebuffs!$P$8:$X$27,MATCH(H28,BuffsDebuffs!$P$8:$X$8,0),FALSE),1)*IF($B$6=TRUE,backend!$BN$5,1) -> 42180 | M28: =VLOOKUP(E28,backend!$BP$5:$BS57,4,FALSE) -> 1 | N28: 6 | O28: 8 | P28: =MAX(IFNA(VLOOKUP(IF($B$10=TRUE,O28,N28),backend!$P$4:$Y57,MATCH(I28,backend!$P$3:$Y$3,0),FALSE),IF($B$10=TRUE,O28,N28)),IFNA(VLOOKUP(IF($B$10=TRUE,O28,N28),backend!$P$4:$Y57,MATCH(J28,backend!$P$3:$Y$3,0),FALSE),IF($B$10=TRUE,O28,N28))) -> 6 | Q28: 120 | R28: =Q28/VLOOKUP(I28,backend!$H$4:$N57,7,FALSE)/VLOOKUP(J28,backend!$H$4:$N57,7,FALSE) -> 120 | S28: 26 | T28: 30 | U28: =MAX(IFNA(VLOOKUP(IF($B$9=TRUE,T28,S28),backend!$AA$4:$AF57,MATCH(I28,backend!$AA$3:$AF$3,0),FALSE),IF($B$9=TRUE,T28,S28)),IFNA(VLOOKUP(IF($B$9=TRUE,T28,S28),backend!$AA$4:$AF57,MATCH(J28,backend!$AA$3:$AF$3,0),FALSE),IF($B$9=TRUE,T28,S28))) -> 26 | V28: =VLOOKUP(E28,backend!$BB$4:$BH57,7,FALSE) -> 43 | W28: =MIN(100,V28+VLOOKUP(I28,backend!$H$4:$N57,5,FALSE)+VLOOKUP(J28,backend!$H$4:$N57,5,FALSE)+IF($B$11=TRUE,100,0)+IF($B$12,10,0)) -> 43 | X28: =(VLOOKUP(D28,backend!$AV$4:$AZ57,2,FALSE)*W28^2+VLOOKUP(D28,backend!$AV$4:$AZ57,3,FALSE)*W28+VLOOKUP(D28,backend!$AV$4:$AZ57,4,FALSE))*VLOOKUP(I28,backend!$H$4:$N57,6,FALSE)*VLOOKUP(J28,backend!$H$4:$N57,6,FALSE)*IF($B$12=TRUE,0.85,1)*IF($B$11=TRUE,0.9,1)*IF(D28="Shotgun",P28,1)*IF(F28="Rapid-Fire",0.8,1)+IF(OR(D28="Fusion Rifle",D28="Linear Fusion Rifle"),0.516,0) -> 3.197972 | Y28: 1.967 | Z28: =VLOOKUP(D28,backend!$AV$4:$AZ57,5,FALSE)*IF(D28="Shotgun",P28,1)+IF(OR(D28="Fusion Rifle",D28="Linear Fusion Rifle"),0.516,0) -> 1.967 | AA28: =MAX(X28,Z28) -> 3.197972 | AB28: =AJ28/MAX(AJ$15:AJ70)*100 -> 49.096464 | AC28: =AL28/MAX(AL$15:AL70)*100 -> 100 | AD28: =AVERAGE(AB28:AC28) -> 74.548232 | AE28: =60/R28*(P28-1) -> 2.5 | AF28: =ROUNDDOWN(U28/P28,0)*AE28+ROUNDDOWN((U28-1)/P28,0)*AA28+Max(0,((U28-ROUNDDOWN(U28/P28,0)*P28)-1)*(60/R28)) -> 23.291888 | AG28: =P28*L28 -> 253080 | AH28: =IF(ISERROR(AG28/AE28),"-",AG28/AE28) -> 101232 | AI28: =U28*L28 -> 1096680 | AJ28: =ROUNDDOWN(U28/N28,0)*AG28 -> 1012320 | AK28: =AI28/AF28 -> 47084.204 | AL28: =IF(P28=1,AK28,MAX(AK28,(ROUNDDOWN(U28/P28,0)*AG28)/(ROUNDDOWN(U28/P28,0)*AE28+(ROUNDDOWN(U28/P28,0)-1)*AA28))) -> 51665.017 | AM28: =IF(P28=U28,AH28,AG28/(AE28+AA28)) -> 44415.803 | AN28: =ROUNDDOWN(B$4/(AA28+AE28),0) -> 3 | AO28: =B$4-AN28*AA28 -> 10.406084 | AP28: =IF(AN28=AQ28,0,B$4-(AN28*AA28+AQ28*AE28)) -> 0.40608395 | AQ28: =MIN(AN28+1,IF(ISERROR(ROUNDDOWN(AO28/AE28,0)),AN28+1,ROUNDDOWN(AO28/AE28,0))) -> 4 | AR28: =AQ28*AG28 -> 1012320 | AS28: =Max(0,AO28-AQ28*AE28)-AP28 -> 0 | AT28: =MIN(N28,IF(AN28<AQ28,0,ROUNDDOWN(IF(AS28=0,0,AS28*(R28/60)+1),0))) -> 0 | AU28: =AT28*L28 -> 0 | AV28: =Min(AI28,AU28+AR28) -> 1012320
