Workbook

Sheet Home
A1: Welcome to my boss DPS spreadsheet! Here you'll find the most accurate boss damage testing that currently exists in Destiny 2. Feel free to make a copy (File > Make a copy) if you want to play around with the data yourself. Here's a brief overview of the tabs: | C1: WATCH: How does this spreadsheet work? | D1: Current News
A2: Changelog | B2: History of changes made to the spreadsheet. | C2: If you have any suggestions or questions, feel free to reach out to me at @theaegisrelic on Discord. | D2: Working on MoT damage testing and stuff.
A3: FAQ | B3: Commonly asked questions/myths about boss DPS.
A4: Equipment | B4: The stuff you need for DPS, whether it be weapons or armor.
A5: Weapons | B5: True weapon damage values against Templar.
A6: Abilities | B6: True ability damage values against Templar.
A7: Scaling | B7: How well certain damage sources stack with multiple users.
A8: Ranking | B8: DPS strategies involving more than one weapon, ranked by DPS/total.
A9: Graphing | B9: Full data dump of relevant DPS strategies over time.
A10: Sustained | B10: Precise DPS of individual damage sources.
A11: Swap | B11: Measures of DPS in the context of swapping.
A12: Bosses | B12: Health values and considerations.
A13: Pack Hunter | B13: Pack Hunter scaling and stacking tests.
A14: Ergo Sum | B14: Testing every archetype combination of Destiny's first special sword.
... A18: Testing | B18: Clipboard dump for temporary experiments.

Sheet Changelog
A1: Date | B1: Description
A2: upcoming | B2: Renegades testing.
A3: 46093 | B3: Added Something Something to Sustained tab.
A4: 46084 | B4: Added Hellion to Swap tab.
A5: 46054 | B5: Added New Land Beyond holster swap to Swap tab.
A6: 46052 | B6: Added Shattershafts chunking to Historical tab.
A7: 46051 | B7: Updated chunking values for every relevant Weapons tab entry.
A8: 46044 | B8: Added Contraverse chunking to Sustained tab and Historical tab, added pre-additive Verity grapples to Historical tab.
A9: 46030 | B9: Updated New Land Beyond reserves in Sustained tab.
A10: 46027 | B10: Updated bolt values in Weapons tab.
A11: 46012 | B11: Updated New Malpais value in Weapons and Sustained tab.
A12: 46008 | B12: Added Heirloom and Praxic Blade to Weapons and Sustained tab.
A13: 46007 | B13: Updated Golden Gun Nighthawk and Needlestorm Mataiodoxia values in Abilities and Swap tabs.
A14: 46005 | B14: Added Equilibrium legendary archetypes to Weapons tab and Sustained tab. Added Equilibrium bosses to Bosses tab.
... A191: 45119 | B191: Video released, Conditional pellet Apex rotation modified to account for Heat Rises (2 dash), added FAQ, Bosses, and Historical tabs.

Sheet FAQ
A1: Frequently Asked Questions
A2: Adept Impact | B2: How much does Adept Impact matter on swords? | C2: 2.93% on light attack, 1.9% on heavy attack (wave).
A3: BnS first shot | B3: Does Bait and Switch affect the shot that activates it? | C3: It depends. If a Bait and Switch weapon is the one to activate Bait and Switch, people typically think that, because the timer has not started and the damage number appears to be an unbuffed one, it is not active. However, in solo instances, the game actually does do the BnS damage to the enemy, meaning that BnS is effectively a flat 30% perk for all shots if used correctly. In the attached video, see that both rocket shots do approximately the same amount to the health bar despite the first shot being the activation condition (the difference between both shots' damage can be attributed to the ~7500 DDT damage error against Templar, 1 pixel's worth). In team settings, however, BnS does not seem to affect the first shot due to instance activity, which likely resulted in the 27% buff value you see in the Wolfpacks tab rather than a full 30.
A4: BnS timing | B4: How long do you have to activate Bait and Switch? | C4: About 7 seconds between each weapon (14s total). No, this does not mean you can shoot weapon 1, wait 1 second, shoot weapon 2, wait 13 seconds, then shoot your Bait weapon. Additionally, you can infinitely store Bait and Switch prep by repeatedly tapping your second weapon without ever going back to your first weapon, provided you initially shot your second weapon within 7 seconds of firing the first. Finally, you can't start shooting weapons to reproc Bait and Switch until its timer is out.
A5: Danger Zone blinding | B5: Does Danger Zone increase the blast radius of the blinding effect of Disorienting Grenades? | C5: No, not even with blast radius that is theoretically >0.
A6: Cluster Bomb | B6: How much damage does Cluster Bomb add to a rocket? | C6: On Templar, each cluster does 334+1669 damage (old scalar). Assuming all 8 clusters hit, that's 16024 extra damage on top of a base value of 72339, which comes out to an increase of ~22.15%. However, none of this damage is affected by Pack Hunter, which yields a final result of ~17.5% overall against a regular Pack Hunter rocket.
A7: Debuff extension | B7: How does debuff extension work? | C7: Timer-based full debuffs (30%) like Tractor and Felwinter's can have their timers refreshed by the application of a timer-based weaken, including Echo of Undermining grenades and Snare Bomb. This interaction does not work with either Tether variant, since the debuff applied by those supers does not seem to apply as a timed status effect, but rather by a consistent connection to the Tether object itself.
A8: Double vs. triple swaps | B8: How much damage loss is not using a third weapon in an Izi rocket rotation? | C8: With how little your third weapon (GL/slug/sniper) makes up these days, in an Izi/slug/Apex Broodweaver rotation, you lose something like 4% of your damage by not using a third weapon, but having a third fill is still important if you're waiting for your rocket to load.
A9: Duality | B9: Is Duality worth using in the context of slug swapping? | C9: Given that the standard double slug rocket rotation doesn't use any exotics, using Duality in place of Sojourner's Tale actually boosts damage by about 18.5% per shot against Frenzy Sojourner's. On top of this, in certain boss phases, you can proc On Black Wings and refresh it during damage through precision hits on the boss.
A10: Frame-based damage | B10: How much are certain damage sources affected by FPS? | C10: Health bar-wise, not at all. This includes Leviathan's Breath, Touch of Thunder storm grenades, Anarchy, and Wolfpack rockets, tested at 30 (capped) to 150 (uncapped). When others have found that the game reports lower wipe screen numbers, this is likely because the game counts damage ticks on a per-frame basis, whereas the instance itself actually calculates damage values at its own rate.
A11: Frontloaded health bars | B11: Are bosses "frontloaded" in health? | C11: No. Based on extensive testing across every raid and dungeon boss in the game, not a single boss has a health bar that is not uniformly distributed.
A12: Golden Gun buffing | B12: Does Well override Radiant for Golden Gun purposes? What about kinetic surges? | C12: Yes. Stay outside a Well if you want to do full Golden Gun damage! As for kinetic surges, they are patched and no longer stack with Golden Gun! Finally, other empowering buffs like Lumina and Banner Shield also override the Radiant buff for Golden Gun :(
A13: Kinetic Tremors | B13: How much damage does Kinetic Tremors add to different weapons? Does it scale with different multipliers? | C13: Here's how Kinetic Tremors scales on different weapon types, converted to a perk equivalent: rapid sniper: ~57.8% buff, 0.433s proc rapid scout: ~160.2% buff, 0.932s proc rapid pulse: ~49.6% buff, 0.981s proc precision HC: ~82.3% buff, 1.392s proc adaptive sidearm: ~109.4% buff, 1.2s proc rapid auto: ~175.6% buff, ~0.83s proc lightweight SMG: ~163.7% buff, ~0.804s proc precision bow: ~146.1% buff, ~1.15s proc And yes, it scales with buffs/debuffs/surges/most perks, but it does not stack with other players — only one KT user per team.
... A21: Weavewalk | B21: Is Weavewalk worth using with Rain of Fire for reloading rockets? | C21: Generally no, the animation is too slow (slower than a dash or Ascent reload, and approaching reloading at ~1.8s).

Sheet Equipment (WIP)
A1: # | B1: Pic | C1: Role | D1: Name | E1: Column 1 | F1: Column 2 | G1: Perk 1 | H1: Perk 2 | I1: Notes
A2: 1 | C2: Ability | D2: Celestial Nighthawk | E2: / | F2: / | G2: / | H2: / | I2: Solid damage super with great ranged burst
A3: 1 | C3: Ability | D3: Cuirass of the Falling Star | E3: / | F3: / | G3: / | H3: / | I3: Zero effort for best damage super in the game
A4: 1 | C4: Main | D4: Ergo Sum | E4: / | F4: / | G4: Caster Frame Lightweight Frame Wave Frame | H4: The Perfect Fifth Unplanned Reprieve Wolfpack Rounds | I4: Best sword damage when Transcendent
A5: 1 | C5: Buff | D5: Gjallarhorn | E5: Fixed | F5: Fixed | G5: Fixed | H5: Fixed | I5: Exists to augment Hezen users
A6: 1 | C6: Main | D6: Hezen Vengeance | E6: Quick Launch | F6: Impact Casing | G6: Overflow Envious Assassin Cluster Bomb | H6: Bait and Switch Elemental Honing | I6: Best general burst damage
A7: 1 | C7: Buff | D7: Sanguine Alchemy | E7: / | F7: / | G7: / | H7: / | I7: Best damage armor exotic, free 10% for doing nothing
A8: 1 | C8: Ability | D8: Solipsism | E8: / | F8: / | G8: Spirit of Inmost Light Spirit of Apotheosis | H8: Spirit of the Star-Eater Spirit of Verity | I8: Great pairing with Nova, excellent for Transcendence farming
A9: 1 | C9: Utility | D9: Tractor Cannon | E9: Fixed | F9: Fixed | G9: Fixed | H9: Fixed | I9: Easiest long-term 30% debuff source
A10: 2 | C10: Main | D10: Bequest | E10: Jagged Edge | F10: Swordmaster's Guard | G10: Relentless Strikes | H10: Surrounded | I10: Very easy Surrounded sword damage
A11: 2 | C11: Filler | D11: Choir of One | E11: Fluted Barrel | F11: Alloy Magazine Flared Magwell | G11: Short-Action Stock | H11: Onslaught | I11: Great for object-based damage, like Crypt Security or blights
A12: 2 | C12: Main | D12: Cynosure | E12: Quick Launch | F12: Impact Casing | G12: Overflow Envious Assassin Reconstruction | H12: Elemental Honing High Ground | I12: Hezen alternative with Reconstruction
A13: 2 | C13: Buff | D13: Edge of Action | E13: Lightweight Emitter | F13: Swap Mag | G13: Short-Action Stock | H13: / | I13: Free 5% buff and great refreshable protection for glaive/sword damage
... A110: 4 | C110: Filler | D110: Yesterday's Question | E110: Fluted Barrel | F110: Appended Mag | G110: Rapid Hit | H110: Vorpal Weapon | I110: Best energy slot legendary LP HC, basically irrelevant

Sheet Weapons (old)
A1: INFORMATION | G1: VISUAL | L1: HEALTHBAR | T1: VERIFICATION
A2: 🖼️ | B2: Type | C2: Subtype | D2: primary Tick | E2: secondary Ticks | F2: Modifiers | G2: Boss | H2: Wipe | I2: # | J2: Full Modifiers | K2: visual Value | L2: Boss | M2: # | N2: Type | O2: HP1 | P2: HP2 | Q2: % | R2: Full Modifiers | S2: healthbar Value | T2: Patch | U2: NG | V2: Multi | W2: Crit | X2: Ratio | Y2: Deviation
B3: Auto rifle | C3: Adaptive frame | D3: 383 | E3: 219 body | G3: S | H3: 383 | I3: 1 | J3: =IFS(G3="S",21494/2048*1.25,G3="C",1.25*2*1.22,OR(G3="R",G3="T"),1.25*1.22) -> 13.118896 | K3: =H3/I3/J3/V3/U3 -> 25.386547 | L3: S | M3: 49 | N3: B | O3: 90.023753 | P3: 85.748219 | Q3: =O3-P3 -> 4.275534 | R3: =IFS(L3="S",21494/2048*1.25) -> 13.118896 | S3: =IFS(N3="B",Q3/M3/100*249945/R3/V3/U3 *W3,N3="C",Q3/M3/100*249945/R3/V3/U3 ) -> 25.281233 | T3: 9.0.0.8 | U3: 1 | V3: 1.15 | W3: =383/219 -> 1.7488584 | X3: =S3/K3 -> 0.99585159 | Y3: =(S3-K3)*M3*U3*V3*J3/(249945/845) -> -0.2632015
B4: Auto rifle | C4: Balanced heat weapon - 450RPM primary | D4: 596 | E4: 352 body | G4: S | H4: 596 | I4: 1 | J4: =IFS(G4="S",21494/2048*1.25,G4="C",1.25*2*1.22,OR(G4="R",G4="T"),1.25*1.22) -> 13.118896 | K4: =H4/I4/J4/V4/U4 -> 37.623727 | L4: S | M4: 50 | N4: B | O4: 90.023753 | P4: 83.016627 | Q4: =O4-P4 -> 7.007126 | R4: =IFS(L4="S",21494/2048*1.25) -> 13.118896 | S4: =IFS(N4="B",Q4/M4/100*249945/R4/V4/U4 *W4,N4="C",Q4/M4/100*249945/R4/V4/U4 ) -> 37.439801 | T4: 9.5.0.2 | U4: 1.05 | V4: 1.15 | W4: =596/352 -> 1.6931818 | X4: =S4/K4 -> 0.99511143 | Y4: =(S4-K4)*M4*U4*V4*J4/(249945/845) -> -0.49250518
B5: Auto rifle | C5: Centrifuse | D5: 543 | E5: 320 body | G5: S | H5: 543 | I5: 1 | J5: =IFS(G5="S",21494/2048*1.25,G5="C",1.25*2*1.22,OR(G5="R",G5="T"),1.25*1.22) -> 13.118896 | K5: =H5/I5/J5/V5/U5 -> 32.719902 | L5: S | M5: 44 | N5: B | O5: 90.023753 | P5: 84.441805 | Q5: =O5-P5 -> 5.581948 | R5: =IFS(L5="S",21494/2048*1.25) -> 13.118896 | S5: =IFS(N5="B",Q5/M5/100*249945/R5/V5/U5 *W5,N5="C",Q5/M5/100*249945/R5/V5/U5 ) -> 32.421984 | T5: 9.0.0.8 | U5: 1.1 | V5: 1.15 | W5: =543/320 -> 1.696875 | X5: =S5/K5 -> 0.99089488 | Y5: =(S5-K5)*M5*U5*V5*J5/(249945/845) -> -0.73544529
B6: Auto rifle | C6: Cerberus+1 | D6: =1064*1.25 -> 1330 | E6: 741 body | F6: point blank | G6: S | H6: 1330 | I6: 1 | J6: =IFS(G6="S",21494/2048*1.25,G6="C",1.25*2*1.22,OR(G6="R",G6="T"),1.25*1.22) -> 13.118896 | K6: =H6/I6/J6/V6/U6 -> 88.156938 | L6: S | M6: 7 | N6: B | O6: 90.023753 | P6: 87.885986 | Q6: =O6-P6 -> 2.137767 | R6: =IFS(L6="S",21494/2048*1.25) -> 13.118896 | S6: =IFS(N6="B",Q6/M6/100*249945/R6/V6/U6 *W6,N6="C",Q6/M6/100*249945/R6/V6/U6 ) -> 90.812382 | T6: 9.0.0.8 | U6: 1 | V6: 1.15 | W6: =1330/741 -> 1.7948718 | X6: =S6/K6 -> 1.0301218 | Y6: =(S6-K6)*M6*U6*V6*J6/(249945/845) -> 0.94807506
B7: Auto rifle | C7: Choir of One | D7: 4128 | E7: 2301 body | F7: hitscan | G7: S | H7: 4128 | I7: 1 | J7: =IFS(G7="S",21494/2048*1.25,G7="C",1.25*2*1.22,OR(G7="R",G7="T"),1.25*1.22) -> 13.118896 | K7: =H7/I7/J7/V7/U7 -> 248.74357 | L7: S | M7: 19 | N7: B | O7: 90.023753 | P7: 72.565321 | Q7: =O7-P7 -> 17.458432 | R7: =IFS(L7="S",21494/2048*1.25) -> 13.118896 | S7: =IFS(N7="B",Q7/M7/100*249945/R7/V7/U7 *W7,N7="C",Q7/M7/100*249945/R7/V7/U7 ) -> 248.27405 | T7: 9.0.0.8 | U7: 1.1 | V7: 1.15 | W7: =4128/2301 -> 1.7940026 | X7: =S7/K7 -> 0.99811244 | Y7: =(S7-K7)*M7*U7*V7*J7/(249945/845) -> -0.50050197
B8: Auto rifle | C8: Choir of One | D8: 8061 | E8: 930 secondary | F8: projectile - point blank | G8: S | H8: =8061+930 -> 8991 | I8: 1 | J8: =IFS(G8="S",21494/2048*1.25,G8="C",1.25*2*1.22,OR(G8="R",G8="T"),1.25*1.22) -> 13.118896 | K8: =H8/I8/J8/V8/U8 -> 541.7765 | L8: S | M8: 4 | N8: B | O8: 90.023753 | P8: 75.534442 | Q8: =O8-P8 -> 14.489311 | R8: =IFS(L8="S",21494/2048*1.25) -> 13.118896 | S8: =IFS(N8="B",Q8/M8/100*249945/R8/V8/U8 *W8,N8="C",Q8/M8/100*249945/R8/V8/U8 ) -> 545.56232 | T8: 9.0.0.8 | U8: 1.1 | V8: 1.15 | W8: 1 | X8: =S8/K8 -> 1.0069878 | Y8: =(S8-K8)*M8*U8*V8*J8/(249945/845) -> 0.84960923
B9: Auto rifle | C9: Choir of One | D9: 1613 | E9: 155 secondary | F9: projectile - spaced | G9: S | H9: =(1613+155)*5 -> 8840 | I9: 1 | J9: =IFS(G9="S",21494/2048*1.25,G9="C",1.25*2*1.22,OR(G9="R",G9="T"),1.25*1.22) -> 13.118896 | K9: =H9/I9/J9/V9/U9 -> 532.6776 | L9: / | M9: / | N9: / | O9: / | P9: / | Q9: / | R9: / | S9: / | T9: 9.0.0.8 | U9: 1.1 | V9: 1.15 | W9: 1 | X9: =101183/101700 -> 0.99491642 | Y9: =(101183-101700)/(1500000/845) -> -0.29124333
B10: Auto rifle | C10: Hard Light | D10: 383 | E10: 219 body | G10: S | H10: 383 | I10: 1 | J10: =IFS(G10="S",21494/2048*1.25,G10="C",1.25*2*1.22,OR(G10="R",G10="T"),1.25*1.22) -> 13.118896 | K10: =H10/I10/J10/V10/U10 -> 25.386547 | L10: S | M10: 49 | N10: B | O10: 90.023753 | P10: 85.748219 | Q10: =O10-P10 -> 4.275534 | R10: =IFS(L10="S",21494/2048*1.25) -> 13.118896 | S10: =IFS(N10="B",Q10/M10/100*249945/R10/V10/U10 *W10,N10="C",Q10/M10/100*249945/R10/V10/U10 ) -> 25.281233 | T10: 9.0.0.8 | U10: 1 | V10: 1.15 | W10: =383/219 -> 1.7488584 | X10: =S10/K10 -> 0.99585159 | Y10: =(S10-K10)*M10*U10*V10*J10/(249945/845) -> -0.2632015
B11: Auto rifle | C11: High-impact frame | D11: 626 | E11: 349 body | G11: S | H11: 626 | I11: 1 | J11: =IFS(G11="S",21494/2048*1.25,G11="C",1.25*2*1.22,OR(G11="R",G11="T"),1.25*1.22) -> 13.118896 | K11: =H11/I11/J11/V11/U11 -> 41.493416 | L11: S | M11: 38 | N11: B | O11: 90.023753 | P11: 84.679335 | Q11: =O11-P11 -> 5.344418 | R11: =IFS(L11="S",21494/2048*1.25) -> 13.118896 | S11: =IFS(N11="B",Q11/M11/100*249945/R11/V11/U11 *W11,N11="C",Q11/M11/100*249945/R11/V11/U11 ) -> 41.794106 | T11: 9.0.0.8 | U11: 1 | V11: 1.15 | W11: =626/349 -> 1.7936963 | X11: =S11/K11 -> 1.0072467 | Y11: =(S11-K11)*M11*U11*V11*J11/(249945/845) -> 0.58278682
B12: Auto rifle | C12: Khvostov 7G-0X | D12: 383 | E12: 219 body, 1350/770 ricochet | F12: average - with ricochetting bullets | G12: S | H12: =(219*35+770*7)*W12 -> 22831.347 | I12: 42 | J12: =IFS(G12="S",21494/2048*1.25,G12="C",1.25*2*1.22,OR(G12="R",G12="T"),1.25*1.22) -> 13.118896 | K12: =H12/I12/J12/V12/U12 -> 36.031895 | L12: / | M12: / | N12: / | O12: / | P12: / | Q12: / | R12: / | S12: / | T12: 9.0.0.8 | U12: 1 | V12: 1.15 | W12: =383/219 -> 1.7488584 | X12: =30178/30490 -> 0.98976714 | Y12: =(30178-30490)/(1500000/845) -> -0.17576
B13: Auto rifle | C13: Monte Carlo | D13: 383 | E13: 219 body | G13: S | H13: 383 | I13: 1 | J13: =IFS(G13="S",21494/2048*1.25,G13="C",1.25*2*1.22,OR(G13="R",G13="T"),1.25*1.22) -> 13.118896 | K13: =H13/I13/J13/V13/U13 -> 25.386547 | L13: S | M13: 43 | N13: B | O13: 90.023753 | P13: 86.223278 | Q13: =O13-P13 -> 3.800475 | R13: =IFS(L13="S",21494/2048*1.25) -> 13.118896 | S13: =IFS(N13="B",Q13/M13/100*249945/R13/V13/U13 *W13,N13="C",Q13/M13/100*249945/R13/V13/U13 ) -> 25.607866 | T13: 9.0.0.8 | U13: 1 | V13: 1.15 | W13: =383/219 -> 1.7488584 | X13: =S13/K13 -> 1.008718 | Y13: =(S13-K13)*M13*U13*V13*J13/(249945/845) -> 0.48539519
B14: Auto rifle | C14: Necrochasm | D14: 336 | E14: 198 body, 267 OFT | G14: S | H14: 336 | I14: 1 | J14: =IFS(G14="S",21494/2048*1.25,G14="C",1.25*2*1.22,OR(G14="R",G14="T"),1.25*1.22) -> 13.118896 | K14: =H14/I14/J14/V14/U14 -> 22.271226 | L14: S | M14: 50 | N14: B | O14: 90.023753 | P14: 86.104513 | Q14: =O14-P14 -> 3.91924 | R14: =IFS(L14="S",21494/2048*1.25) -> 13.118896 | S14: =IFS(N14="B",Q14/M14/100*249945/R14/V14/U14 *W14,N14="C",Q14/M14/100*249945/R14/V14/U14 ) -> 22.037141 | T14: 9.0.0.8 | U14: 1 | V14: 1.15 | W14: =336/198 -> 1.6969697 | X14: =S14/K14 -> 0.98948934 | Y14: =(S14-K14)*M14*U14*V14*J14/(249945/845) -> -0.59696893
B15: Auto rifle | C15: Precision frame | D15: 494 | E15: 291 body | G15: S | H15: 494 | I15: 1 | J15: =IFS(G15="S",21494/2048*1.25,G15="C",1.25*2*1.22,OR(G15="R",G15="T"),1.25*1.22) -> 13.118896 | K15: =H15/I15/J15/V15/U15 -> 32.744005 | L15: S | M15: 38 | N15: B | O15: 90.023753 | P15: 85.510689 | Q15: =O15-P15 -> 4.513064 | R15: =IFS(L15="S",21494/2048*1.25) -> 13.118896 | S15: =IFS(N15="B",Q15/M15/100*249945/R15/V15/U15 *W15,N15="C",Q15/M15/100*249945/R15/V15/U15 ) -> 33.401899 | T15: 9.0.0.8 | U15: 1 | V15: 1.15 | W15: =494/291 -> 1.6975945 | X15: =S15/K15 -> 1.020092 | Y15: =(S15-K15)*M15*U15*V15*J15/(249945/845) -> 1.2751078
B16: Auto rifle | C16: Quicksilver Storm | D16: 336 | E16: 198 body, 1164/68 rocket | F16: average - with tracking rockets | G16: S | H16: =1164+68+336*10 -> 4592 | I16: 11 | J16: =IFS(G16="S",21494/2048*1.25,G16="C",1.25*2*1.22,OR(G16="R",G16="T"),1.25*1.22) -> 13.118896 | K16: =H16/I16/J16/V16/U16 -> 27.670312 | L16: S | M16: 11 | N16: C | O16: 90.023753 | P16: 88.123515 | Q16: =O16-P16 -> 1.900238 | R16: =IFS(L16="S",21494/2048*1.25) -> 13.118896 | S16: =IFS(N16="B",Q16/M16/100*249945/R16/V16/U16 *W16,N16="C",Q16/M16/100*249945/R16/V16/U16 ) -> 28.61967 | T16: 9.0.0.8 | U16: 1 | V16: 1.15 | W16: =(494*10+1164+68)/(291*10+1164+68) -> 1.4901014 | X16: =S16/K16 -> 1.0343096 | Y16: =(S16-K16)*M16*U16*V16*J16/(249945/845) -> 0.53263574
B17: Auto rifle | C17: Quicksilver Storm | D17: 6979 | E17: 200 secondary | F17: Grenades Prepped | G17: S | H17: =6979+200 -> 7179 | I17: 1 | J17: =IFS(G17="S",21494/2048*1.25,G17="C",1.25*2*1.22,OR(G17="R",G17="T"),1.25*1.22) -> 13.118896 | K17: =H17/I17/J17/V17/U17 -> 475.84861 | L17: S | M17: 3 | N17: B | O17: 80.522565 | P17: 71.852732 | Q17: =O17-P17 -> 8.669833 | R17: =IFS(L17="S",21494/2048*1.25) -> 13.118896 | S17: =IFS(N17="B",Q17/M17/100*249945/R17/V17/U17 *W17,N17="C",Q17/M17/100*249945/R17/V17/U17 ) -> 478.78307 | T17: 9.0.0.8 | U17: 1 | V17: 1.15 | W17: 1 | X17: =S17/K17 -> 1.0061668 | Y17: =(S17-K17)*M17*U17*V17*J17/(249945/845) -> 0.44901041
B18: Auto rifle | C18: Rapid-fire frame | D18: 336 | E18: 198 body | G18: S | H18: 336 | I18: 1 | J18: =IFS(G18="S",21494/2048*1.25,G18="C",1.25*2*1.22,OR(G18="R",G18="T"),1.25*1.22) -> 13.118896 | K18: =H18/I18/J18/V18/U18 -> 22.271226 | L18: S | M18: 51 | N18: B | O18: 90.023753 | P18: 85.985748 | Q18: =O18-P18 -> 4.038005 | R18: =IFS(L18="S",21494/2048*1.25) -> 13.118896 | S18: =IFS(N18="B",Q18/M18/100*249945/R18/V18/U18 *W18,N18="C",Q18/M18/100*249945/R18/V18/U18 ) -> 22.259739 | T18: 9.0.0.8 | U18: 1 | V18: 1.15 | W18: =336/198 -> 1.6969697 | X18: =S18/K18 -> 0.99948421 | Y18: =(S18-K18)*M18*U18*V18*J18/(249945/845) -> -0.029880709
B19: Auto rifle | C19: Support frame | D19: 384 | E19: 274 body | G19: S | H19: 384 | I19: 1 | J19: =IFS(G19="S",21494/2048*1.25,G19="C",1.25*2*1.22,OR(G19="R",G19="T"),1.25*1.22) -> 13.118896 | K19: =H19/I19/J19/V19/U19 -> 25.45283 | L19: S | M19: 28 | N19: B | O19: 90.023753 | P19: 86.935867 | Q19: =O19-P19 -> 3.087886 | R19: =IFS(L19="S",21494/2048*1.25) -> 13.118896 | S19: =IFS(N19="B",Q19/M19/100*249945/R19/V19/U19 *W19,N19="C",Q19/M19/100*249945/R19/V19/U19 ) -> 25.605496 | T19: 9.0.0.8 | U19: 1 | V19: 1.15 | W19: =384/274 -> 1.4014599 | X19: =S19/K19 -> 1.005998 | Y19: =(S19-K19)*M19*U19*V19*J19/(249945/845) -> 0.21802587
B20: Auto rifle | C20: SUROS Regime | D20: 626 | E20: 384 max body, 349 min body | F20: average - Dual Speed Receiver | G20: S | H20: =(349*18+367*6+368*2+369+370*2+372+373+374+376+379+381+384)*W20 -> 23260.653 | I20: 36 | J20: =IFS(G20="S",21494/2048*1.25,G20="C",1.25*2*1.22,OR(G20="R",G20="T"),1.25*1.22) -> 13.118896 | K20: =H20/I20/J20/V20/U20 -> 42.827652 | L20: S | M20: 36 | N20: B | O20: 90.023753 | P20: 84.7981 | Q20: =O20-P20 -> 5.225653 | R20: =IFS(L20="S",21494/2048*1.25) -> 13.118896 | S20: =IFS(N20="B",Q20/M20/100*249945/R20/V20/U20 *W20,N20="C",Q20/M20/100*249945/R20/V20/U20 ) -> 43.135643 | T20: 9.0.0.8 | U20: 1 | V20: 1.15 | W20: =626/349 -> 1.7936963 | X20: =S20/K20 -> 1.0071914 | Y20: =(S20-K20)*M20*U20*V20*J20/(249945/845) -> 0.56552145
B21: Auto rifle | C21: SUROS Regime | D21: 359 | E21: 240 max body, 219 min body | F21: Spinning Up | G21: S | H21: =(219*18+230*8+231*2+232*2+233+234+235+237+238+240)*W21 -> 13319.064 | I21: 36 | J21: =IFS(G21="S",21494/2048*1.25,G21="C",1.25*2*1.22,OR(G21="R",G21="T"),1.25*1.22) -> 13.118896 | K21: =H21/I21/J21/V21/U21 -> 24.523139 | L21: S | M21: 36 | N21: B | O21: 90.023753 | P21: 86.698337 | Q21: =O21-P21 -> 3.325416 | R21: =IFS(L21="S",21494/2048*1.25) -> 13.118896 | S21: =IFS(N21="B",Q21/M21/100*249945/R21/V21/U21 *W21,N21="C",Q21/M21/100*249945/R21/V21/U21 ) -> 25.086676 | T21: 9.0.0.8 | U21: 1 | V21: 1.15 | W21: =359/219 -> 1.6392694 | X21: =S21/K21 -> 1.0229798 | Y21: =(S21-K21)*M21*U21*V21*J21/(249945/845) -> 1.0347431
B22: Auto rifle | C22: Sweet Business | D22: 423 | E22: 379 explosive, 275 body | F22: average - with explosive rounds, no ramping | G22: T | H22: =5460*1.5 -> 8190 | I22: 150 | J22: =IFS(G22="S",21494/2048*1.25,G22="C",1.25*2*1.22,OR(G22="R",G22="T"),1.25*1.22) -> 1.525 | K22: =H22/I22/J22/V22/U22 -> 31.133286 | L22: / | M22: / | N22: / | O22: / | P22: / | Q22: / | R22: / | S22: / | T22: 9.1.5.2 | U22: 1 | V22: 1.15 | W22: =423/275 -> 1.5381818 | X22: =33728/34664 -> 0.97299792 | Y22: =(33728-34664)/(1500000/845) -> -0.52728
B23: Auto rifle | C23: Tommy's Matchbook | D23: 11202 | E23: 432 ramped, 218 body 732 ramped crit, 369 crit | F23: average - with ignition | G23: T | H23: =7007*1.5 -> 10510.5 | I23: 100 | J23: =IFS(G23="S",21494/2048*1.25,G23="C",1.25*2*1.22,OR(G23="R",G23="T"),1.25*1.22) -> 1.525 | K23: =H23/I23/J23/V23/U23 -> 54.48325 | L23: T | M23: 100 | N23: C | O23: 99.64497 | P23: 94.08284 | Q23: =O23-P23 -> 5.56213 | R23: =1.25*1.22 -> 1.525 | S23: =IFS(N23="B",Q23/M23/100*182596/R23/V23/U23 *W23,N23="C",Q23/M23/100*182596/R23/V23/U23 ) -> 52.646806 | T23: 9.1.5.2 | U23: 1.1 | V23: 1.15 | W23: =369/218 -> 1.6926606 | X23: =44379/44090 -> 1.0065548 | Y23: =(44379-44090)/(1500000/845) -> 0.16280333
B24: Bow | C24: Heirloom | D24: 1399 | E24: 1166 crit, 1053 body | F24: uncharged | G24: C | H24: 38475 | I24: 15 | J24: =1.25*2*1.15 -> 2.875 | K24: =H24/I24/J24/V24/U24 -> 738.86038 | L24: C | M24: 15 | N24: C | O24: 100 | P24: 97.39645 | Q24: =O24-P24 -> 2.60355 | R24: =1.25*2*1.15 -> 2.875 | S24: =Q24/M24/100*1500000/R24/V24/U24 -> 749.96489 | T24: 9.5.0.3 | U24: 1.05 | V24: 1.15 | W24: =(1399+1166)/(1399+1053) -> 1.0460848 | X24: =S24/K24 -> 1.0150292 | Y24: =(S24-K24)*M24*U24*V24*J24/(1500000/845) -> 0.3257475
B25: Bow | C25: Heirloom | D25: 1637 | E25: 1719 scorched splash, 1590/1669 crit 2345 ignition, 1435/1507 body | F25: average - 1/3 charge, with ignition, catalyst | G25: C | H25: 19691 | I25: 5 | J25: =1.25*2*1.15 -> 2.875 | K25: =H25/I25/J25/V25/U25 -> 1134.4171 | L25: C | M25: 5 | N25: C | O25: 100 | P25: 98.698225 | Q25: =O25-P25 -> 1.301775 | R25: =1.25*2*1.15 -> 2.875 | S25: =Q25/M25/100*1500000/R25/V25/U25 -> 1124.9473 | T25: 9.5.0.3 | U25: 1.05 | V25: 1.15 | W25: =19691/18694 -> 1.0533326 | X25: =S25/K25 -> 0.99165228 | Y25: =(S25-K25)*M25*U25*V25*J25/(1500000/845) -> -0.092597917
B26: Bow | C26: Heirloom | D26: 2862 | E26: 3005 scorched splash, 1786/1875 crit 2345 ignition, 2583/2712 body | F26: average - 2/3 charge, with ignition, catalyst | G26: C | H26: 17149 | I26: 3 | J26: =1.25*2*1.15 -> 2.875 | K26: =H26/I26/J26/V26/U26 -> 1646.6169 | L26: C | M26: 3 | N26: C | O26: 100 | P26: 98.816568 | Q26: =O26-P26 -> 1.183432 | R26: =1.25*2*1.15 -> 2.875 | S26: =Q26/M26/100*1500000/R26/V26/U26 -> 1704.4659 | T26: 9.5.0.3 | U26: 1.05 | V26: 1.15 | W26: =17149/14470 -> 1.1851417 | X26: =S26/K26 -> 1.0351321 | Y26: =(S26-K26)*M26*U26*V26*J26/(1500000/845) -> 0.33939707
B27: Bow | C27: Heirloom | D27: 2862 | E27: 3005/2862 splash, 2679/2813 crit 2345 ignition, 2583/2712 body | F27: average - fully charged, with ignition, catalyst | G27: C | H27: 27908 | I27: 4 | J27: =1.25*2*1.15 -> 2.875 | K27: =H27/I27/J27/V27/U27 -> 2009.7579 | L27: C | M27: 4 | N27: C | O27: 100 | P27: 98.106509 | Q27: =O27-P27 -> 1.893491 | R27: =1.25*2*1.15 -> 2.875 | S27: =Q27/M27/100*1500000/R27/V27/U27 -> 2045.3589 | T27: 9.5.0.3 | U27: 1.05 | V27: 1.15 | W27: =27908/26794 -> 1.0415765 | X27: =S27/K27 -> 1.0177141 | Y27: =(S27-K27)*M27*U27*V27*J27/(1500000/845) -> 0.27849228
B28: Bow | C28: Hierarchy of Needs | D28: 3508 | E28: 2195 body, 2316 seeker | G28: S | H28: 3508 | I28: 1 | J28: =IFS(G28="S",21494/2048*1.25,G28="C",1.25*2*1.22,OR(G28="R",G28="T"),1.25*1.22) -> 13.118896 | K28: =H28/I28/J28/V28/U28 -> 211.38383 | L28: S | M28: 5 | N28: C | O28: 90.023753 | P28: 83.016627 | Q28: =O28-P28 -> 7.007126 | R28: =IFS(L28="S",21494/2048*1.25) -> 13.118896 | S28: =IFS(N28="B",Q28/M28/100*249945/R28/V28/U28 *W28,N28="C",Q28/M28/100*249945/R28/V28/U28 ) -> 211.07002 | T28: 9.0.0.8 | U28: 1.1 | V28: 1.15 | W28: =3508/2195 -> 1.5981777 | X28: =S28/K28 -> 0.99851546 | Y28: =(S28-K28)*M28*U28*V28*J28/(249945/845) -> -0.088030914
B29: Bow | C29: High-impact frame | D29: 5861 | E29: 4364 body, 67 tick | F29: Charged Bolts | G29: C | H29: 62027 | I29: 10 | J29: =1.25*2*1.15*1.17 -> 3.36375 | K29: =H29/I29/J29/V29/U29 -> 1596.5226 | L29: C | M29: 10 | N29: C | O29: 100 | P29: 95.502959 | Q29: =O29-P29 -> 4.497041 | R29: =1.25*2*1.15*1.17 -> 3.36375 | S29: =Q29/M29/100*1500000/R29/V29/U29 -> 1736.2506 | T29: 9.5.0.3 | U29: 1.05 | V29: 1.1 | W29: =62027/46990 -> 1.3200043 | X29: =S29/K29 -> 1.0875202 | Y29: =(S29-K29)*M29*U29*V29*J29/(1500000/845) -> 3.0581198
B30: Bow | C30: High-impact frame | D30: 2638 | E30: 3224 explosion, 1964 body | F30: Explosive Bolts | G30: C | H30: 58620 | I30: 10 | J30: =1.25*2*1.15*1.17 -> 3.36375 | K30: =H30/I30/J30/V30/U30 -> 1508.8293 | L30: C | M30: 10 | N30: C | O30: 100 | P30: 96.094675 | Q30: =O30-P30 -> 3.905325 | R30: =1.25*2*1.15*1.17 -> 3.36375 | S30: =Q30/M30/100*1500000/R30/V30/U30 -> 1507.7966 | T30: 9.5.0.3 | U30: 1.05 | V30: 1.1 | W30: =58620/51880 -> 1.1299152 | X30: =S30/K30 -> 0.99931551 | Y30: =(S30-K30)*M30*U30*V30*J30/(1500000/845) -> -0.02260375
B31: Bow | C31: High-impact frame | D31: 6447 | E31: 4800 body | F31: Heavy Bolts | G31: C | H31: 64470 | I31: 10 | J31: =1.25*2*1.15*1.17 -> 3.36375 | K31: =H31/I31/J31/V31/U31 -> 1659.4034 | L31: C | M31: 10 | N31: C | O31: 100 | P31: 95.739645 | Q31: =O31-P31 -> 4.260355 | R31: =1.25*2*1.15*1.17 -> 3.36375 | S31: =Q31/M31/100*1500000/R31/V31/U31 -> 1644.8691 | T31: 9.5.0.3 | U31: 1.05 | V31: 1.1 | W31: =64470/48000 -> 1.343125 | X31: =S31/K31 -> 0.99124128 | Y31: =(S31-K31)*M31*U31*V31*J31/(1500000/845) -> -0.31810025
B32: Bow | C32: High-impact frame | D32: 5861 | E32: 4364 body, 1111/556 retrieval | F32: Serrated Bolts, with retrieval | G32: C | H32: 64725 | I32: 10 | J32: =1.25*2*1.15*1.17 -> 3.36375 | K32: =H32/I32/J32/V32/U32 -> 1665.9669 | L32: C | M32: 10 | N32: C | O32: 100 | P32: 95.621302 | Q32: =O32-P32 -> 4.378698 | R32: =1.25*2*1.15*1.17 -> 3.36375 | S32: =Q32/M32/100*1500000/R32/V32/U32 -> 1690.5599 | T32: 9.5.0.3 | U32: 1.05 | V32: 1.1 | W32: =64725/49755 -> 1.3008743 | X32: =S32/K32 -> 1.014762 | Y32: =(S32-K32)*M32*U32*V32*J32/(1500000/845) -> 0.5382481
B33: Bow | C33: High-impact frame | D33: 5861 | E33: 4364 body, 56 explosion | F33: Spring-Auger Bolts | G33: C | H33: 59170 | I33: 10 | J33: =1.25*2*1.15*1.17 -> 3.36375 | K33: =H33/I33/J33/V33/U33 -> 1522.9859 | L33: C | M33: 10 | N33: C | O33: 100 | P33: 96.094675 | Q33: =O33-P33 -> 3.905325 | R33: =1.25*2*1.15*1.17 -> 3.36375 | S33: =Q33/M33/100*1500000/R33/V33/U33 -> 1507.7966 | T33: 9.5.0.3 | U33: 1.05 | V33: 1.1 | W33: =59170/44200 -> 1.3386878 | X33: =S33/K33 -> 0.99002662 | Y33: =(S33-K33)*M33*U33*V33*J33/(1500000/845) -> -0.33243708
B34: Bow | C34: High-impact longbow frame | D34: 3977 | E34: 3050 body, 1625 seeker | G34: S | H34: 3977 | I34: 1 | J34: =IFS(G34="S",21494/2048*1.25,G34="C",1.25*2*1.22,OR(G34="R",G34="T"),1.25*1.22) -> 13.118896 | K34: =H34/I34/J34/V34/U34 -> 255.17719 | L34: S | M34: 2 | N34: C | O34: 90.023753 | P34: 86.817102 | Q34: =O34-P34 -> 3.206651 | R34: =IFS(L34="S",21494/2048*1.25) -> 13.118896 | S34: =IFS(N34="B",Q34/M34/100*249945/R34/V34/U34 *W34,N34="C",Q34/M34/100*249945/R34/V34/U34 ) -> 257.1298 | T34: 9.0.0.8 | U34: 1.08 | V34: 1.1 | W34: =3977/3050 -> 1.3039344 | X34: =S34/K34 -> 1.007652 | Y34: =(S34-K34)*M34*U34*V34*J34/(249945/845) -> 0.20576505
B35: Bow | C35: Le Monarque | D35: 2898 | E35: 1814 body, 459 poison, 1506 seeker | F35: average - with poison | G35: C | H35: 6580 | I35: 5 | J35: =IFS(G35="S",21494/2048*1.25,G35="C",1.25*2*1.22,OR(G35="R",G35="T"),1.25*1.22) -> 3.05 | K35: =H35/I35/J35/V35/U35 -> 375.19601 | L35: S | M35: 5 | N35: C | O35: 90.023753 | P35: 78.384798 | Q35: =O35-P35 -> 11.638955 | R35: =IFS(L35="S",21494/2048*1.25) -> 13.118896 | S35: =IFS(N35="B",Q35/M35/100*249945/R35/V35/U35 *W35,N35="C",Q35/M35/100*249945/R35/V35/U35 ) -> 385.64996 | T35: 9.0.0.8 | U35: 1 | V35: 1.15 | W35: =6580/5320 -> 1.2368421 | X35: =S35/K35 -> 1.0278626 | Y35: =(S35-K35)*M35*U35*V35*J35/(249945/845) -> 0.61981272
B36: Bow | C36: Leviathan's Breath | D36: 16620 | E36: 7674 body, 12262 impact, 984 splash | G36: S | H36: =16620+12262+984 -> 29866 | I36: 1 | J36: =IFS(G36="S",21494/2048*1.25,G36="C",1.25*2*1.22,OR(G36="R",G36="T"),1.25*1.22) -> 13.118896 | K36: =H36/I36/J36/V36/U36 -> 2069.6031 | L36: S | M36: 3 | N36: C | O36: 90.023753 | P36: 54.15677 | Q36: =O36-P36 -> 35.866983 | R36: =IFS(L36="S",21494/2048*1.25) -> 13.118896 | S36: =IFS(N36="B",Q36/M36/100*249945/R36/V36/U36 *W36,N36="C",Q36/M36/100*249945/R36/V36/U36 ) -> 2070.7518 | T36: 9.1.0.2 | U36: 1 | V36: 1.1 | W36: =(16620+12262+984)/(7674+16620+984) -> 1.1815017 | X36: =S36/K36 -> 1.000555 | Y36: =(S36-K36)*M36*U36*V36*J36/(249945/845) -> 0.16812662
B37: Bow | C37: Lightweight frame | D37: 2997 | E37: 1876 body, 1506 seeker | G37: S | H37: 2997 | I37: 1 | J37: =IFS(G37="S",21494/2048*1.25,G37="C",1.25*2*1.22,OR(G37="R",G37="T"),1.25*1.22) -> 13.118896 | K37: =H37/I37/J37/V37/U37 -> 198.65139 | L37: S | M37: 5 | N37: C | O37: 90.023753 | P37: 83.966746 | Q37: =O37-P37 -> 6.057007 | R37: =IFS(L37="S",21494/2048*1.25) -> 13.118896 | S37: =IFS(N37="B",Q37/M37/100*249945/R37/V37/U37 *W37,N37="C",Q37/M37/100*249945/R37/V37/U37 ) -> 200.69538 | T37: 9.0.0.8 | U37: 1 | V37: 1.15 | W37: =2997/1876 -> 1.597548 | X37: =S37/K37 -> 1.0102894 | Y37: =(S37-K37)*M37*U37*V37*J37/(249945/845) -> 0.52126385
B38: Bow | C38: Precision frame | D38: 3071 | E38: 2356 body, 1506 seeker | G38: S | H38: 3071 | I38: 1 | J38: =IFS(G38="S",21494/2048*1.25,G38="C",1.25*2*1.22,OR(G38="R",G38="T"),1.25*1.22) -> 13.118896 | K38: =H38/I38/J38/V38/U38 -> 203.55636 | L38: S | M38: 5 | N38: C | O38: 90.023753 | P38: 83.847981 | Q38: =O38-P38 -> 6.175772 | R38: =IFS(L38="S",21494/2048*1.25) -> 13.118896 | S38: =IFS(N38="B",Q38/M38/100*249945/R38/V38/U38 *W38,N38="C",Q38/M38/100*249945/R38/V38/U38 ) -> 204.63059 | T38: 9.0.0.8 | U38: 1 | V38: 1.15 | W38: =3071/2356 -> 1.3034805 | X38: =S38/K38 -> 1.0052773 | Y38: =(S38-K38)*M38*U38*V38*J38/(249945/845) -> 0.27395291
B39: Bow | C39: Ticuu's Divination | D39: 4076 | E39: 2997 impact, 188 mark, 1506 seeker | F39: average - alternating modes, 0 stacks | G39: S | H39: =188*3+2997+4076 -> 7637 | I39: 2 | J39: =IFS(G39="S",21494/2048*1.25,G39="C",1.25*2*1.22,OR(G39="R",G39="T"),1.25*1.22) -> 13.118896 | K39: =H39/I39/J39/V39/U39 -> 253.10321 | L39: S | M39: 2 | N39: C | O39: 90.023753 | P39: 86.935867 | Q39: =O39-P39 -> 3.087886 | R39: =IFS(L39="S",21494/2048*1.25) -> 13.118896 | S39: =IFS(N39="B",Q39/M39/100*249945/R39/V39/U39 *W39,N39="C",Q39/M39/100*249945/R39/V39/U39 ) -> 255.78824 | T39: 9.0.0.8 | U39: 1 | V39: 1.15 | W39: =5616/3374 -> 1.6644932 | X39: =S39/K39 -> 1.0106084 | Y39: =(S39-K39)*M39*U39*V39*J39/(249945/845) -> 0.27389658
B40: Bow | C40: Ticuu's Divination | D40: 4076 | E40: 5616 impact, 3374 body, 341 mark | F40: average - alternating modes, 6 stacks | G40: S | H40: =341*3+5616+4076 -> 10715 | I40: 2 | J40: =IFS(G40="S",21494/2048*1.25,G40="C",1.25*2*1.22,OR(G40="R",G40="T"),1.25*1.22) -> 13.118896 | K40: =H40/I40/J40/V40/U40 -> 355.11338 | L40: S | M40: 2 | N40: C | O40: 69.35867 | P40: 64.964371 | Q40: =O40-P40 -> 4.394299 | R40: =IFS(L40="S",21494/2048*1.25) -> 13.118896 | S40: =IFS(N40="B",Q40/M40/100*249945/R40/V40/U40 *W40,N40="C",Q40/M40/100*249945/R40/V40/U40 ) -> 364.00631 | T40: 9.0.0.8 | U40: 1 | V40: 1.15 | W40: =5616/3374 -> 1.6644932 | X40: =S40/K40 -> 1.0250425 | Y40: =(S40-K40)*M40*U40*V40*J40/(249945/845) -> 0.90715712
...

Sheet Weapons
A1: INFORMATION | G1: VISUAL | L1: HEALTHBAR | T1: VERIFICATION
A2: 🖼️ | B2: Type | C2: Subtype | D2: primary Tick | E2: secondary Ticks | F2: Modifiers | G2: Boss | H2: Wipe | I2: # | J2: Full Modifiers | K2: visual Value | L2: Boss | M2: # | N2: Type | O2: HP1 | P2: HP2 | Q2: % | R2: Full Modifiers | S2: healthbar Value | T2: Patch | U2: Crit | V2: Ratio | W2: Deviation
B3: Auto rifle | C3: Adaptive frame | D3: 383 | E3: 219 body | G3: S | H3: 383 | I3: 1 | J3: =21494/2048*1.25*1.15 -> 15.086731 | K3: =H3/I3/J3 -> 25.386547 | L3: / | M3: / | N3: / | O3: / | P3: / | Q3: / | R3: / | S3: / | T3: 9.7.0 | U3: =383/219 -> 1.7488584 | V3: =S3/K3 -> #VALUE! | W3: =(S3-K3)*M3*#REF!*#REF!*J3/(249945/845) -> #VALUE!
B4: Auto rifle | C4: Balanced heat weapon - 450RPM primary | D4: 596 | E4: 352 body | G4: S | H4: 596 | I4: 1 | K4: =H4/I4/J4 -> #DIV/0! | L4: / | M4: / | N4: / | O4: / | P4: / | Q4: / | R4: / | S4: / | T4: 9.5.0.2 | U4: =596/352 -> 1.6931818 | V4: =S4/K4 -> #DIV/0! | W4: =(S4-K4)*M4*#REF!*#REF!*J4/(249945/845) -> #DIV/0!
B5: Auto rifle | C5: Centrifuse | D5: 543 | E5: 320 body | G5: S | H5: 543 | I5: 1 | K5: =H5/I5/J5 -> #DIV/0! | L5: / | M5: / | N5: / | O5: / | P5: / | Q5: / | R5: / | S5: / | T5: 9.0.0.8 | U5: =543/320 -> 1.696875 | V5: =S5/K5 -> #DIV/0! | W5: =(S5-K5)*M5*#REF!*#REF!*J5/(249945/845) -> #DIV/0!
B6: Auto rifle | C6: Cerberus+1 | D6: =1064*1.25 -> 1330 | E6: 741 body | F6: point blank | G6: S | H6: 1330 | I6: 1 | K6: =H6/I6/J6 -> #DIV/0! | L6: / | M6: / | N6: / | O6: / | P6: / | Q6: / | R6: / | S6: / | T6: 9.0.0.8 | U6: =1330/741 -> 1.7948718 | V6: =S6/K6 -> #DIV/0! | W6: =(S6-K6)*M6*#REF!*#REF!*J6/(249945/845) -> #DIV/0!
B7: Auto rifle | C7: Choir of One | D7: 4128 | E7: 2301 body | F7: hitscan | G7: S | H7: 4128 | I7: 1 | K7: =H7/I7/J7 -> #DIV/0! | L7: / | M7: / | N7: / | O7: / | P7: / | Q7: / | R7: / | S7: / | T7: 9.0.0.8 | U7: =4128/2301 -> 1.7940026 | V7: =S7/K7 -> #DIV/0! | W7: =(S7-K7)*M7*#REF!*#REF!*J7/(249945/845) -> #DIV/0!
B8: Auto rifle | C8: Choir of One | D8: 8061 | E8: 930 secondary | F8: projectile - point blank | G8: S | H8: =8061+930 -> 8991 | I8: 1 | K8: =H8/I8/J8 -> #DIV/0! | L8: / | M8: / | N8: / | O8: / | P8: / | Q8: / | R8: / | S8: / | T8: 9.0.0.8 | U8: 1 | V8: =S8/K8 -> #DIV/0! | W8: =(S8-K8)*M8*#REF!*J8/(249945/845) -> #DIV/0!
B9: Auto rifle | C9: Choir of One | D9: 1613 | E9: 155 secondary | F9: projectile - spaced | G9: S | H9: =(1613+155)*5 -> 8840 | I9: 1 | J9: =21494/2048*1.25*1.15 -> 15.086731 | K9: =H9/I9/J9 -> 585.94536 | L9: / | M9: / | N9: / | O9: / | P9: / | Q9: / | R9: / | S9: chunk | T9: 9.7.0 | U9: 1 | V9: =IF(S9="/",1,S9/K9) -> #VALUE! | W9: =IFS(S9="/","N/A",G9="S",((P9-O9)/100*249945/845)/M9-H9/249945*845) -> #VALUE!
B10: Auto rifle | C10: Hard Light | D10: 383 | E10: 219 body | G10: S | H10: 383 | I10: 1 | K10: =H10/I10/J10 -> #DIV/0! | L10: / | M10: / | N10: / | O10: / | P10: / | Q10: / | R10: / | S10: / | T10: 9.0.0.8 | U10: =383/219 -> 1.7488584 | V10: =S10/K10 -> #DIV/0! | W10: =(S10-K10)*M10*#REF!*#REF!*J10/(249945/845) -> #DIV/0!
B11: Auto rifle | C11: High-impact frame | D11: 626 | E11: 349 body | G11: S | H11: 626 | I11: 1 | K11: =H11/I11/J11 -> #DIV/0! | L11: / | M11: / | N11: / | O11: / | P11: / | Q11: / | R11: / | S11: / | T11: 9.0.0.8 | U11: =626/349 -> 1.7936963 | V11: =S11/K11 -> #DIV/0! | W11: =(S11-K11)*M11*#REF!*#REF!*J11/(249945/845) -> #DIV/0!
B12: Auto rifle | C12: Khvostov 7G-0X | D12: 383 | E12: 219 body, 1350/770 ricochet | F12: average - with ricochetting bullets | G12: S | H12: =(219*35+770*7)*U12 -> 22831.347 | I12: 42 | K12: =H12/I12/J12 -> #DIV/0! | L12: / | M12: / | N12: / | O12: / | P12: / | Q12: / | R12: / | S12: chunk | T12: 9.0.0.8 | U12: =383/219 -> 1.7488584 | V12: =IF(S12="/",1,S12/K12) -> #DIV/0! | W12: =IFS(S12="/","N/A",G12="S",((P12-O12)/100*249945/845)/M12-H12/249945*845) -> #VALUE!
B13: Auto rifle | C13: Monte Carlo | D13: 383 | E13: 219 body | G13: S | H13: 383 | I13: 1 | K13: =H13/I13/J13 -> #DIV/0! | L13: / | M13: / | N13: / | O13: / | P13: / | Q13: / | R13: / | S13: / | T13: 9.0.0.8 | U13: =383/219 -> 1.7488584 | V13: =S13/K13 -> #DIV/0! | W13: =(S13-K13)*M13*#REF!*#REF!*J13/(249945/845) -> #DIV/0!
B14: Auto rifle | C14: Necrochasm | D14: 336 | E14: 198 body, 267 OFT | G14: S | H14: 336 | I14: 1 | K14: =H14/I14/J14 -> #DIV/0! | L14: / | M14: / | N14: / | O14: / | P14: / | Q14: / | R14: / | S14: / | T14: 9.0.0.8 | U14: =336/198 -> 1.6969697 | V14: =S14/K14 -> #DIV/0! | W14: =(S14-K14)*M14*#REF!*#REF!*J14/(249945/845) -> #DIV/0!
B15: Auto rifle | C15: Precision frame | D15: 494 | E15: 291 body | G15: S | H15: 494 | I15: 1 | K15: =H15/I15/J15 -> #DIV/0! | L15: / | M15: / | N15: / | O15: / | P15: / | Q15: / | R15: / | S15: / | T15: 9.0.0.8 | U15: =494/291 -> 1.6975945 | V15: =S15/K15 -> #DIV/0! | W15: =(S15-K15)*M15*#REF!*#REF!*J15/(249945/845) -> #DIV/0!
B16: Auto rifle | C16: Quicksilver Storm | D16: 6979 | E16: 200 secondary | F16: Grenades Prepped | G16: S | H16: =6979+200 -> 7179 | I16: 1 | K16: =H16/I16/J16 -> #DIV/0! | L16: / | M16: / | N16: / | O16: / | P16: / | Q16: / | R16: / | S16: / | T16: 9.0.0.8 | U16: 1 | V16: =S16/K16 -> #DIV/0! | W16: =(S16-K16)*M16*#REF!*#REF!*J16/(249945/845) -> #DIV/0!
B17: Auto rifle | C17: Quicksilver Storm | D17: 336 | E17: 198 body, 1164/68 rocket | F17: average - with tracking rockets | G17: S | H17: =1164+68+336*10 -> 4592 | I17: 11 | K17: =H17/I17/J17 -> #DIV/0! | L17: / | M17: / | N17: / | O17: / | P17: / | Q17: / | R17: / | S17: chunk | T17: 9.0.0.8 | U17: =(494*10+1164+68)/(291*10+1164+68) -> 1.4901014 | V17: =S17/K17 -> #DIV/0! | W17: =(S17-K17)*M17*#REF!*#REF!*J17/(249945/845) -> #DIV/0!
B18: Auto rifle | C18: Rapid-fire frame | D18: 336 | E18: 198 body | G18: S | H18: 336 | I18: 1 | K18: =H18/I18/J18 -> #DIV/0! | L18: / | M18: / | N18: / | O18: / | P18: / | Q18: / | R18: / | S18: / | T18: 9.0.0.8 | U18: =336/198 -> 1.6969697 | V18: =S18/K18 -> #DIV/0! | W18: =(S18-K18)*M18*#REF!*#REF!*J18/(249945/845) -> #DIV/0!
B19: Auto rifle | C19: Support frame | D19: 384 | E19: 274 body | G19: S | H19: 384 | I19: 1 | K19: =H19/I19/J19 -> #DIV/0! | L19: / | M19: / | N19: / | O19: / | P19: / | Q19: / | R19: / | S19: / | T19: 9.0.0.8 | U19: =384/274 -> 1.4014599 | V19: =S19/K19 -> #DIV/0! | W19: =(S19-K19)*M19*#REF!*#REF!*J19/(249945/845) -> #DIV/0!
B20: Auto rifle | C20: SUROS Regime | D20: 626 | E20: 384 max body, 349 min body | F20: average - Dual Speed Receiver | G20: S | H20: =(349*18+367*6+368*2+369+370*2+372+373+374+376+379+381+384)*U20 -> 23260.653 | I20: 36 | K20: =H20/I20/J20 -> #DIV/0! | L20: / | M20: / | N20: / | O20: / | P20: / | Q20: / | R20: / | S20: / | T20: 9.0.0.8 | U20: =626/349 -> 1.7936963 | V20: =S20/K20 -> #DIV/0! | W20: =(S20-K20)*M20*#REF!*#REF!*J20/(249945/845) -> #DIV/0!
B21: Auto rifle | C21: SUROS Regime | D21: 359 | E21: 240 max body, 219 min body | F21: Spinning Up | G21: S | H21: =(219*18+230*8+231*2+232*2+233+234+235+237+238+240)*U21 -> 13319.064 | I21: 36 | K21: =H21/I21/J21 -> #DIV/0! | L21: / | M21: / | N21: / | O21: / | P21: / | Q21: / | R21: / | S21: / | T21: 9.0.0.8 | U21: =359/219 -> 1.6392694 | V21: =S21/K21 -> #DIV/0! | W21: =(S21-K21)*M21*#REF!*#REF!*J21/(249945/845) -> #DIV/0!
B22: Auto rifle | C22: Sweet Business | D22: 423 | E22: 379 explosive, 275 body | F22: average - with explosive rounds, no ramping | G22: T | H22: =5460*1.5 -> 8190 | I22: 150 | K22: =H22/I22/J22 -> #DIV/0! | L22: / | M22: / | N22: / | O22: / | P22: / | Q22: / | R22: / | S22: chunk | T22: 9.1.5.2 | U22: =423/275 -> 1.5381818 | V22: =33728/34664 -> 0.97299792 | W22: =(33728-34664)/(1500000/845) -> -0.52728
B23: Auto rifle | C23: Tommy's Matchbook | D23: 11202 | E23: 432 ramped, 218 body 732 ramped crit, 369 crit | F23: average - with ignition | G23: T | H23: =7007*1.5 -> 10510.5 | I23: 100 | K23: =H23/I23/J23 -> #DIV/0! | L23: T | M23: 100 | N23: C | O23: 99.64497 | P23: 94.08284 | Q23: =O23-P23 -> 5.56213 | R23: =1.25*1.22 -> 1.525 | S23: chunk | T23: 9.1.5.2 | U23: =369/218 -> 1.6926606 | V23: =44379/44090 -> 1.0065548 | W23: =(44379-44090)/(1500000/845) -> 0.16280333
B24: Bow | C24: Heirloom | D24: 1637 | E24: 1719 scorched splash, 1590/1669 crit 2345 ignition, 1435/1507 body | F24: average - 1/3 charge, with ignition, catalyst | G24: C | H24: 19691 | I24: 5 | K24: =H24/I24/J24 -> #DIV/0! | L24: C | M24: 5 | N24: C | O24: 100 | P24: 98.698225 | Q24: =O24-P24 -> 1.301775 | R24: =1.25*2*1.15 -> 2.875 | S24: =IFS(N24="B",Q24/M24/100*249945/R24 *U24,N24="C",Q24/M24/100*249945/R24 ) -> 226.34585 | T24: 9.5.0.3 | U24: =19691/18694 -> 1.0533326 | V24: =S24/K24 -> #DIV/0! | W24: =(S24-K24)*M24*#REF!*#REF!*J24/(1500000/845) -> #DIV/0!
B25: Bow | C25: Heirloom | D25: 1399 | E25: 1166 crit, 1053 body | F25: uncharged | G25: C | H25: 38475 | I25: 15 | K25: =H25/I25/J25 -> #DIV/0! | L25: C | M25: 15 | N25: C | O25: 100 | P25: 97.39645 | Q25: =O25-P25 -> 2.60355 | R25: =1.25*2*1.15 -> 2.875 | S25: =IFS(N25="B",Q25/M25/100*249945/R25 *U25,N25="C",Q25/M25/100*249945/R25 ) -> 150.89723 | T25: 9.5.0.3 | U25: =(1399+1166)/(1399+1053) -> 1.0460848 | V25: =S25/K25 -> #DIV/0! | W25: =(S25-K25)*M25*#REF!*#REF!*J25/(1500000/845) -> #DIV/0!
B26: Bow | C26: Heirloom | D26: 2862 | E26: 3005/2862 splash, 2679/2813 crit 2345 ignition, 2583/2712 body | F26: average - fully charged, with ignition, catalyst | G26: C | H26: 27908 | I26: 4 | K26: =H26/I26/J26 -> #DIV/0! | L26: C | M26: 4 | N26: C | O26: 100 | P26: 98.106509 | Q26: =O26-P26 -> 1.893491 | R26: =1.25*2*1.15 -> 2.875 | S26: =IFS(N26="B",Q26/M26/100*249945/R26 *U26,N26="C",Q26/M26/100*249945/R26 ) -> 411.53792 | T26: 9.5.0.3 | U26: =27908/26794 -> 1.0415765 | V26: =S26/K26 -> #DIV/0! | W26: =(S26-K26)*M26*#REF!*#REF!*J26/(1500000/845) -> #DIV/0!
B27: Bow | C27: Heirloom | D27: 2862 | E27: 3005 scorched splash, 1786/1875 crit 2345 ignition, 2583/2712 body | F27: average - 2/3 charge, with ignition, catalyst | G27: C | H27: 17149 | I27: 3 | K27: =H27/I27/J27 -> #DIV/0! | L27: C | M27: 3 | N27: C | O27: 100 | P27: 98.816568 | Q27: =O27-P27 -> 1.183432 | R27: =1.25*2*1.15 -> 2.875 | S27: =IFS(N27="B",Q27/M27/100*249945/R27 *U27,N27="C",Q27/M27/100*249945/R27 ) -> 342.9483 | T27: 9.5.0.3 | U27: =17149/14470 -> 1.1851417 | V27: =S27/K27 -> #DIV/0! | W27: =(S27-K27)*M27*#REF!*#REF!*J27/(1500000/845) -> #DIV/0!
B28: Bow | C28: Hierarchy of Needs | D28: 3508 | E28: 2195 body, 2316 seeker | G28: S | H28: 3508 | I28: 1 | K28: =H28/I28/J28 -> #DIV/0! | L28: S | M28: 5 | N28: C | O28: 90.023753 | P28: 83.016627 | Q28: =O28-P28 -> 7.007126 | R28: =IFS(L28="S",21494/2048*1.25) -> 13.118896 | S28: =IFS(N28="B",Q28/M28/100*249945/R28 *U28,N28="C",Q28/M28/100*249945/R28 ) -> 267.00357 | T28: 9.0.0.8 | U28: =3508/2195 -> 1.5981777 | V28: =S28/K28 -> #DIV/0! | W28: =(S28-K28)*M28*#REF!*#REF!*J28/(249945/845) -> #DIV/0!
B29: Bow | C29: High-impact frame | D29: 5861 | E29: 4364 body, 56 explosion | F29: Spring-Auger Bolts | G29: C | H29: 59170 | I29: 10 | K29: =H29/I29/J29 -> #DIV/0! | L29: C | M29: 10 | N29: C | O29: 100 | P29: 96.094675 | Q29: =O29-P29 -> 3.905325 | R29: =1.25*2*1.15*1.17 -> 3.36375 | S29: =IFS(N29="B",Q29/M29/100*249945/R29 *U29,N29="C",Q29/M29/100*249945/R29 ) -> 290.18698 | T29: 9.5.0.3 | U29: =59170/44200 -> 1.3386878 | V29: =S29/K29 -> #DIV/0! | W29: =(S29-K29)*M29*#REF!*#REF!*J29/(1500000/845) -> #DIV/0!
B30: Bow | C30: High-impact frame | D30: 6447 | E30: 4800 body | F30: Heavy Bolts | G30: C | H30: 64470 | I30: 10 | K30: =H30/I30/J30 -> #DIV/0! | L30: C | M30: 10 | N30: C | O30: 100 | P30: 95.739645 | Q30: =O30-P30 -> 4.260355 | R30: =1.25*2*1.15*1.17 -> 3.36375 | S30: =IFS(N30="B",Q30/M30/100*249945/R30 *U30,N30="C",Q30/M30/100*249945/R30 ) -> 316.56765 | T30: 9.5.0.3 | U30: =64470/48000 -> 1.343125 | V30: =S30/K30 -> #DIV/0! | W30: =(S30-K30)*M30*#REF!*#REF!*J30/(1500000/845) -> #DIV/0!
B31: Bow | C31: High-impact frame | D31: 2638 | E31: 3224 explosion, 1964 body | F31: Explosive Bolts | G31: C | H31: 58620 | I31: 10 | K31: =H31/I31/J31 -> #DIV/0! | L31: C | M31: 10 | N31: C | O31: 100 | P31: 96.094675 | Q31: =O31-P31 -> 3.905325 | R31: =1.25*2*1.15*1.17 -> 3.36375 | S31: =IFS(N31="B",Q31/M31/100*249945/R31 *U31,N31="C",Q31/M31/100*249945/R31 ) -> 290.18698 | T31: 9.5.0.3 | U31: =58620/51880 -> 1.1299152 | V31: =S31/K31 -> #DIV/0! | W31: =(S31-K31)*M31*#REF!*#REF!*J31/(1500000/845) -> #DIV/0!
B32: Bow | C32: High-impact frame | D32: 5861 | E32: 4364 body, 1111/556 retrieval | F32: Serrated Bolts, with retrieval | G32: C | H32: 64725 | I32: 10 | K32: =H32/I32/J32 -> #DIV/0! | L32: C | M32: 10 | N32: C | O32: 100 | P32: 95.621302 | Q32: =O32-P32 -> 4.378698 | R32: =1.25*2*1.15*1.17 -> 3.36375 | S32: =IFS(N32="B",Q32/M32/100*249945/R32 *U32,N32="C",Q32/M32/100*249945/R32 ) -> 325.36118 | T32: 9.5.0.3 | U32: =64725/49755 -> 1.3008743 | V32: =S32/K32 -> #DIV/0! | W32: =(S32-K32)*M32*#REF!*#REF!*J32/(1500000/845) -> #DIV/0!
B33: Bow | C33: High-impact frame | D33: 5861 | E33: 4364 body, 67 tick | F33: Charged Bolts | G33: C | H33: 62027 | I33: 10 | K33: =H33/I33/J33 -> #DIV/0! | L33: C | M33: 1 | N33: C | O33: 100 | P33: 95.502959 | Q33: =O33-P33 -> 4.497041 | R33: =1.25*2*1.15*1.17 -> 3.36375 | S33: chunk | T33: 9.5.0.3 | U33: =62027/46990 -> 1.3200043 | V33: =IF(S33="/",1,S33/K33) -> #DIV/0! | W33: =IFS(S33="/","N/A",G33="S",((P33-O33)/100*249945/845)/M33-H33/249945*845,G33="C",((P33-O33)/100*10000000/845)/M33-H33/10000000*845) -> -537.43548
B34: Bow | C34: High-impact longbow frame | D34: 3977 | E34: 3050 body, 1625 seeker | G34: S | H34: 3977 | I34: 1 | K34: =H34/I34/J34 -> #DIV/0! | L34: S | M34: 2 | N34: C | O34: 90.023753 | P34: 86.817102 | Q34: =O34-P34 -> 3.206651 | R34: =IFS(L34="S",21494/2048*1.25) -> 13.118896 | S34: =IFS(N34="B",Q34/M34/100*249945/R34 *U34,N34="C",Q34/M34/100*249945/R34 ) -> 305.4702 | T34: 9.0.0.8 | U34: =3977/3050 -> 1.3039344 | V34: =S34/K34 -> #DIV/0! | W34: =(S34-K34)*M34*#REF!*#REF!*J34/(249945/845) -> #DIV/0!
B35: Bow | C35: Le Monarque | D35: 2898 | E35: 1814 body, 459 poison, 1506 seeker | F35: average - with poison | G35: C | H35: 6580 | I35: 5 | K35: =H35/I35/J35 -> #DIV/0! | L35: S | M35: 5 | N35: C | O35: 90.023753 | P35: 78.384798 | Q35: =O35-P35 -> 11.638955 | R35: =IFS(L35="S",21494/2048*1.25) -> 13.118896 | S35: =IFS(N35="B",Q35/M35/100*249945/R35 *U35,N35="C",Q35/M35/100*249945/R35 ) -> 443.49746 | T35: 9.0.0.8 | U35: =6580/5320 -> 1.2368421 | V35: =S35/K35 -> #DIV/0! | W35: =(S35-K35)*M35*#REF!*#REF!*J35/(249945/845) -> #DIV/0!
B36: Bow | C36: Leviathan's Breath | D36: 16620 | E36: 7674 body, 12262 impact, 984 splash | G36: S | H36: =16620+12262+984 -> 29866 | I36: 1 | K36: =H36/I36/J36 -> #DIV/0! | L36: S | M36: 3 | N36: C | O36: 90.023753 | P36: 54.15677 | Q36: =O36-P36 -> 35.866983 | R36: =IFS(L36="S",21494/2048*1.25) -> 13.118896 | S36: =IFS(N36="B",Q36/M36/100*249945/R36 *U36,N36="C",Q36/M36/100*249945/R36 ) -> 2277.827 | T36: 9.1.0.2 | U36: =(16620+12262+984)/(7674+16620+984) -> 1.1815017 | V36: =S36/K36 -> #DIV/0! | W36: =(S36-K36)*M36*#REF!*#REF!*J36/(249945/845) -> #DIV/0!
B37: Bow | C37: Lightweight frame | D37: 2997 | E37: 1876 body, 1506 seeker | G37: S | H37: 2997 | I37: 1 | K37: =H37/I37/J37 -> #DIV/0! | L37: S | M37: 5 | N37: C | O37: 90.023753 | P37: 83.966746 | Q37: =O37-P37 -> 6.057007 | R37: =IFS(L37="S",21494/2048*1.25) -> 13.118896 | S37: =IFS(N37="B",Q37/M37/100*249945/R37 *U37,N37="C",Q37/M37/100*249945/R37 ) -> 230.79969 | T37: 9.0.0.8 | U37: =2997/1876 -> 1.597548 | V37: =S37/K37 -> #DIV/0! | W37: =(S37-K37)*M37*#REF!*#REF!*J37/(249945/845) -> #DIV/0!
B38: Bow | C38: Precision frame | D38: 3071 | E38: 2356 body, 1506 seeker | G38: S | H38: 3071 | I38: 1 | K38: =H38/I38/J38 -> #DIV/0! | L38: S | M38: 5 | N38: C | O38: 90.023753 | P38: 83.847981 | Q38: =O38-P38 -> 6.175772 | R38: =IFS(L38="S",21494/2048*1.25) -> 13.118896 | S38: =IFS(N38="B",Q38/M38/100*249945/R38 *U38,N38="C",Q38/M38/100*249945/R38 ) -> 235.32518 | T38: 9.0.0.8 | U38: =3071/2356 -> 1.3034805 | V38: =S38/K38 -> #DIV/0! | W38: =(S38-K38)*M38*#REF!*#REF!*J38/(249945/845) -> #DIV/0!
B39: Bow | C39: Ticuu's Divination | D39: 4076 | E39: 2997 impact, 188 mark, 1506 seeker | F39: average - alternating modes, 0 stacks | G39: S | H39: =188*3+2997+4076 -> 7637 | I39: 2 | K39: =H39/I39/J39 -> #DIV/0! | L39: S | M39: 2 | N39: C | O39: 90.023753 | P39: 86.935867 | Q39: =O39-P39 -> 3.087886 | R39: =IFS(L39="S",21494/2048*1.25) -> 13.118896 | S39: =IFS(N39="B",Q39/M39/100*249945/R39 *U39,N39="C",Q39/M39/100*249945/R39 ) -> 294.15647 | T39: 9.0.0.8 | U39: =5616/3374 -> 1.6644932 | V39: =S39/K39 -> #DIV/0! | W39: =(S39-K39)*M39*#REF!*#REF!*J39/(249945/845) -> #DIV/0!
B40: Bow | C40: Ticuu's Divination | D40: 4076 | E40: 5616 impact, 3374 body, 341 mark | F40: average - alternating modes, 6 stacks | G40: S | H40: =341*3+5616+4076 -> 10715 | I40: 2 | K40: =H40/I40/J40 -> #DIV/0! | L40: S | M40: 2 | N40: C | O40: 69.35867 | P40: 64.964371 | Q40: =O40-P40 -> 4.394299 | R40: =IFS(L40="S",21494/2048*1.25) -> 13.118896 | S40: =IFS(N40="B",Q40/M40/100*249945/R40 *U40,N40="C",Q40/M40/100*249945/R40 ) -> 418.60726 | T40: 9.0.0.8 | U40: =5616/3374 -> 1.6644932 | V40: =S40/K40 -> #DIV/0! | W40: =(S40-K40)*M40*#REF!*#REF!*J40/(249945/845) -> #DIV/0!
...

Sheet Abilities
A1: INFORMATION | G1: VISUAL | L1: HEALTHBAR | S1: VERIFICATION
A2: 🖼️ | B2: Type | C2: Subtype | D2: primary Tick | E2: secondary Ticks | F2: Modifiers | G2: Boss | H2: Wipe | I2: # | J2: Full Modifiers | K2: visual Value | L2: Boss | M2: # | N2: HP1 | O2: HP2 | P2: % | Q2: Full Modifiers | R2: healthbar Value | S2: Patch | T2: Ratio | U2: Deviation
B3: Grenade | C3: Arcbolt | D3: 6640 | G3: S | H3: 6640 | I3: 1 | J3: =IFS(G3="S",21494/2048,G3="C",(21494/2048)/(87875/9999)*2*1.3,OR(G3="R",G3="T"),1) -> 10.495117 | K3: =H3/I3/J3 -> 632.67517 | L3: S | M3: 5 | N3: 90.023753 | O3: 76.72209 | P3: =N3-O3 -> 13.301663 | Q3: =IFS(L3="S",21494/2048,L3="R",1) -> 10.495117 | R3: =IFS(L3="S",P3/M3/100*249945/Q3,L3="R",P3/M3/100*170255/Q3) -> 633.5678 | S3: 9.1.5.2 | T3: =R3/K3 -> 1.0014109 | U3: =IFS(L3="S",(R3-K3)*M3*J3/(249945/845),L3="R",(R3-K3)*M3*J3/(170255/845)) -> 0.1583594
B4: Grenade | C4: Axion Bolt | D4: 8245 | E4: 66 direct, 67 seeker impact | F4: Chaos Accelerant | G4: S | H4: =66*2+67*2+8245*2 -> 16756 | I4: 1 | J4: =IFS(G4="S",21494/2048,G4="C",(21494/2048)/(87875/9999)*2*1.3,OR(G4="R",G4="T"),1) -> 10.495117 | K4: =H4/I4/J4 -> 1596.552 | L4: S | M4: 2 | N4: 90.023753 | O4: 76.603325 | P4: =N4-O4 -> 13.420428 | Q4: =IFS(L4="S",21494/2048,L4="R",1) -> 10.495117 | R4: =IFS(L4="S",P4/M4/100*249945/Q4,L4="R",P4/M4/100*170255/Q4) -> 1598.0617 | S4: 9.1.5.2 | T4: =R4/K4 -> 1.0009456 | U4: =IFS(L4="S",(R4-K4)*M4*J4/(249945/845),L4="R",(R4-K4)*M4*J4/(170255/845)) -> 0.10713159
B5: Grenade | C5: Axion Bolt | D5: 6596 | E5: 66 direct, 67 seeker impact | G5: S | H5: =66+67+6596 -> 6729 | I5: 1 | J5: =IFS(G5="S",21494/2048,G5="C",(21494/2048)/(87875/9999)*2*1.3,OR(G5="R",G5="T"),1) -> 10.495117 | K5: =H5/I5/J5 -> 641.1553 | L5: S | M5: 4 | N5: 90.023753 | O5: 79.097387 | P5: =N5-O5 -> 10.926366 | Q5: =IFS(L5="S",21494/2048,L5="R",1) -> 10.495117 | R5: =IFS(L5="S",P5/M5/100*249945/Q5,L5="R",P5/M5/100*170255/Q5) -> 650.53836 | S5: 9.1.5.2 | T5: =R5/K5 -> 1.0146346 | U5: =IFS(L5="S",(R5-K5)*M5*J5/(249945/845),L5="R",(R5-K5)*M5*J5/(170255/845)) -> 1.3316936
B6: Grenade | C6: Electrified Snare | D6: ? | E6: ? | F6: Facet of Courage | G6: R | H6: 2494 | I6: 2 | J6: =IFS(G6="S",21494/2048,G6="C",(21494/2048)/(87875/9999)*2*1.3,OR(G6="R",G6="T"),1) -> 1 | K6: =H6/I6/J6 -> 1247 | L6: R | M6: 2 | N6: 100 | O6: 98.456057 | P6: =N6-O6 -> 1.543943 | Q6: =IFS(L6="S",21494/2048,L6="R",1) -> 1 | R6: =IFS(L6="S",P6/M6/100*249945/Q6,L6="R",P6/M6/100*170255/Q6) -> 1314.3201 | S6: 9.1.5.4 | T6: =R6/K6 -> 1.0539856 | U6: =IFS(L6="S",(R6-K6)*M6*J6/(249945/845),L6="R",(R6-K6)*M6*J6/(170255/845)) -> 0.66823841
B7: Grenade | C7: Firebolt | D7: 4283 | E7: 7441 ignition, 88 scorch start | F7: average - Ember of Ashes, with ignition | G7: S | H7: =4283*4+88*3+146*2+150*2+210*2+209*3+7441 -> 26476 | I7: 4 | J7: =IFS(G7="S",21494/2048,G7="C",(21494/2048)/(87875/9999)*2*1.3,OR(G7="R",G7="T"),1) -> 10.495117 | K7: =H7/I7/J7 -> 630.67423 | L7: S | M7: 4 | N7: 90.023753 | O7: 79.334917 | P7: =N7-O7 -> 10.688836 | Q7: =IFS(L7="S",21494/2048,L7="R",1) -> 10.495117 | R7: =IFS(L7="S",P7/M7/100*249945/Q7,L7="R",P7/M7/100*170255/Q7) -> 636.39621 | S7: 9.1.5.2 | T7: =R7/K7 -> 1.0090728 | U7: =IFS(L7="S",(R7-K7)*M7*J7/(249945/845),L7="R",(R7-K7)*M7*J7/(170255/845)) -> 0.81209231
B8: Grenade | C8: Flashbang | D8: 830 | E8: 7 impact | G8: R | H8: 5022 | I8: 6 | J8: =IFS(G8="S",21494/2048,G8="C",(21494/2048)/(87875/9999)*2*1.3,OR(G8="R",G8="T"),1) -> 1 | K8: =H8/I8/J8 -> 837 | L8: R | M8: 6 | N8: 100 | O8: 97.030879 | P8: =N8-O8 -> 2.969121 | Q8: =IFS(L8="S",21494/2048,L8="R",1) -> 1 | R8: =IFS(L8="S",P8/M8/100*249945/Q8,L8="R",P8/M8/100*170255/Q8) -> 842.51283 | S8: 9.5.0 | T8: =R8/K8 -> 1.0065864 | U8: =IFS(L8="S",(R8-K8)*M8*J8/(249945/845),L8="R",(R8-K8)*M8*J8/(170255/845)) -> 0.16416569
B9: Grenade | C9: Flux | D9: 19109 | E9: 67 impact | G9: S | H9: =67+19109 -> 19176 | I9: 1 | J9: =IFS(G9="S",21494/2048,G9="C",(21494/2048)/(87875/9999)*2*1.3,OR(G9="R",G9="T"),1) -> 10.495117 | K9: =H9/I9/J9 -> 1827.1354 | L9: S | M9: 3 | N9: 90.023753 | O9: 66.983373 | P9: =N9-O9 -> 23.04038 | Q9: =IFS(L9="S",21494/2048,L9="R",1) -> 10.495117 | R9: =IFS(L9="S",P9/M9/100*249945/Q9,L9="R",P9/M9/100*170255/Q9) -> 1829.0499 | S9: 9.1.5.2 | T9: =R9/K9 -> 1.0010478 | U9: =IFS(L9="S",(R9-K9)*M9*J9/(249945/845),L9="R",(R9-K9)*M9*J9/(170255/845)) -> 0.20378377
B10: Grenade | C10: Freezing Singularity | D10: 685 | E10: 172 tick, 237/3781 shatter, 5647 suppress | F10: Facet of Courage, Facet of Ruin | G10: S | H10: =685+35+172*16+122+3781+237+5647 -> 13259 | I10: 1 | J10: =IFS(G10="S",21494/2048,G10="C",(21494/2048)/(87875/9999)*2*1.3,OR(G10="R",G10="T"),1) -> 10.495117 | K10: =H10/I10/J10 -> 1263.3494 | L10: S | M10: 1 | N10: 90.023753 | O10: 84.679335 | P10: =N10-O10 -> 5.344418 | Q10: =IFS(L10="S",21494/2048,L10="R",1) -> 10.495117 | R10: =IFS(L10="S",P10/M10/100*249945/Q10,L10="R",P10/M10/100*170255/Q10) -> 1272.7924 | S10: 9.1.5.2 | T10: =R10/K10 -> 1.0074746 | U10: =IFS(L10="S",(R10-K10)*M10*J10/(249945/845),L10="R",(R10-K10)*M10*J10/(170255/845)) -> 0.33505054
B11: Grenade | C11: Fusion | D11: 8124 | E11: 63 impact, 7624 2nd explosion, 150 scorch start, 7441 ignition | F11: average - Ember of Ashes, Touch of Flame, with ignition | G11: S | H11: =63*2+7624*2+8124*2+7441+150*4 -> 39663 | I11: 2 | J11: =IFS(G11="S",21494/2048,G11="C",(21494/2048)/(87875/9999)*2*1.3,OR(G11="R",G11="T"),1) -> 10.495117 | K11: =H11/I11/J11 -> 1889.593 | L11: S | M11: 2 | N11: 90.023753 | O11: 73.990499 | P11: =N11-O11 -> 16.033254 | Q11: =IFS(L11="S",21494/2048,L11="R",1) -> 10.495117 | R11: =IFS(L11="S",P11/M11/100*249945/Q11,L11="R",P11/M11/100*170255/Q11) -> 1909.1886 | S11: 9.1.5.2 | T11: =R11/K11 -> 1.0103703 | U11: =IFS(L11="S",(R11-K11)*M11*J11/(249945/845),L11="R",(R11-K11)*M11*J11/(170255/845)) -> 1.3905564
B12: Grenade | C12: Fusion | D12: 8124 | E12: 63 impact, 150 scorch start, 7441 ignition | F12: average - Ember of Ashes, with ignition | G12: S | H12: =63*2+8124*2+7441+150*4 -> 24415 | I12: 2 | J12: =IFS(G12="S",21494/2048,G12="C",(21494/2048)/(87875/9999)*2*1.3,OR(G12="R",G12="T"),1) -> 10.495117 | K12: =H12/I12/J12 -> 1163.16 | L12: S | M12: 2 | N12: 90.023753 | O12: 80.166271 | P12: =N12-O12 -> 9.857482 | Q12: =IFS(L12="S",21494/2048,L12="R",1) -> 10.495117 | R12: =IFS(L12="S",P12/M12/100*249945/Q12,L12="R",P12/M12/100*170255/Q12) -> 1173.7974 | S12: 9.1.5.2 | T12: =R12/K12 -> 1.0091453 | U12: =IFS(L12="S",(R12-K12)*M12*J12/(249945/845),L12="R",(R12-K12)*M12*J12/(170255/845)) -> 0.75486391
B13: Grenade | C13: Glacier | D13: 166 | E13: 23 Fissures | F13: average - Whisper of Fissures | G13: R | H13: 5368 | I13: 4 | J13: =IFS(G13="S",21494/2048,G13="C",(21494/2048)/(87875/9999)*2*1.3,OR(G13="R",G13="T"),1) -> 1 | K13: =H13/I13/J13 -> 1342 | L13: R | M13: 4 | N13: 100 | O13: 97.030879 | P13: =N13-O13 -> 2.969121 | Q13: =IFS(L13="S",21494/2048,L13="R",1) -> 1 | R13: =IFS(L13="S",P13/M13/100*249945/Q13,L13="R",P13/M13/100*170255/Q13) -> 1263.7692 | S13: 9.1.5.2 | T13: =R13/K13 -> 0.94170584 | U13: =IFS(L13="S",(R13-K13)*M13*J13/(249945/845),L13="R",(R13-K13)*M13*J13/(170255/845)) -> -1.553082
B14: Grenade | C14: Glacier | D14: 166 | E14: 24 Fissures | F14: average - Whisper of Fissures, Touch of Winter | G14: R | H14: 3990 | I14: 3 | J14: =IFS(G14="S",21494/2048,G14="C",(21494/2048)/(87875/9999)*2*1.3,OR(G14="R",G14="T"),1) -> 1 | K14: =H14/I14/J14 -> 1330 | L14: R | M14: 3 | N14: 100 | O14: 97.743468 | P14: =N14-O14 -> 2.256532 | Q14: =IFS(L14="S",21494/2048,L14="R",1) -> 1 | R14: =IFS(L14="S",P14/M14/100*249945/Q14,L14="R",P14/M14/100*170255/Q14) -> 1280.6195 | S14: 9.1.5.2 | T14: =R14/K14 -> 0.96287182 | U14: =IFS(L14="S",(R14-K14)*M14*J14/(249945/845),L14="R",(R14-K14)*M14*J14/(170255/845)) -> -0.73524724
