Workbook

Sheet Home
C1: Welcome to Destiny 2: Quantum Damage-ics
B2: =image("https://www.bungie.net/common/destiny2_content/icons/f385fda03b8ab139f6c2179844685fcf.jpg", 4, 65, 65) | D2: Game version: 8.2.6 >>> 9.5.6.3 | F2: =image("https://www.bungie.net/common/destiny2_content/icons/a93e3f872c8e0af699f09d59e09603c6.jpg", 4, 65, 65)
D3: Want to invest in the spreadsheet? Ko-fi
C4: Purpose
C5: The purpose of this spreadsheet is to showcase the absolute maximization of raw weapon DPS on boss-tier combatants; It serves as a reference of where weapons stand in comparison to other weapons in the context of boss DPS phases. The spreadsheet provides raw values that the user can process to compare DPS or manipulate on their own means to compare damage multipliers.
C6: Assumptions Made
C7: To make data comparison between weapons more fair: > All weapons are normalized, i.e. the new weapon bonus is removed > The only exception to this rule is exotics, as they all have an innate +5% > All weapons assume the effects of Rally barricade/Lunafactions reload speed boosting to minimize reload speeds to a consistent amount. > All weapons assume Extended Mag (or similar) and Backup Mag (whenever applicable), unless otherwise stated, to keep magazine sizes at a consistent amount. > Changing the magazine capacity may affect the total reserves of a weapon; see the Inventory and Mag Database below for further information. > Note: some weapons may be able to maximize the magazine stat through means other than Backup Mag, see Inventory and Mag Database below. > All legendary weapons exclude perks unless otherwise stated. > All weapons assume depleting the entire magazine before reloading unless otherwise stated. > All weapons assume reloading the instant the final round of the magazine is fired (hitting the reload context button at the same time the final round is fired). > All weapon DPS calculations assume precision hits whenever applicable or unless otherwise stated. > All pellet shotguns DPS calculations assume body shots, unless otherwise stated, to make comparison more realistic.
C8: Methods and Calculations
B9: =image("https://www.bungie.net/common/destiny2_content/icons/f87eddefbcbc59f22ba3cb8c4af7c824.jpg", 4, 65, 65) | C9: Method of DPS calculation: (damage sum of individual attacks) / (time sum of individual attacks) note that this is not (measured total damage) / (measured total time) The total damage over total time is the Average DPS, and will likely be higher if not equal to the Sustained DPS because the time span measured is relatively small. As you increase time (and assume infinite ammo) you will approach the actual Sustained DPS figure. To get a better visual, visit the Equations page and see the graph for DPS as a function of time. All timings are done at 60 fps. | F9: =image("https://www.bungie.net/common/destiny2_content/icons/73819c52be4d6d983470c16141d4ea59.jpg", 4, 65, 65)
C10: Other Notes
C11: As you navigate this spreadsheet, take note: > If a cell has a hyperlink, you can double-click on the cell to be able to directly click on the hyperlink. > If you wish to inspect how DPS values were calculated, you can double-click on a cell to see the exact formula. > Some cells make use of custom-defined formulas which are scripted and aren't viewable in read-only mode. > Some of these formulas are defined in the Equations page. > Other formulas may require you to download a copy of this spreasheet and open Extensions -> Apps Script to view them as they are programmed functions. > Color-gradient columns are meant to compare values to other members within the same column. > More green is bettter, within the same respective column (e.g.: more damage or better sustained DPS). > Certain fields may contain a note on them for more information. Expand these notes by dragging the bottom-right corner for better readability. > If you wish to sort everything, see "All Weapons" and its associated page header. > The Weapon Change Log page is to keep track of when weapons were last tested and their respective data points were modified. > Any cells highlighted in red are considered to be outdated/bad/to-be-determined and subject to change. Remember: this spreadsheet is meant to represent frame-perfect DPS scenarios. The data is intended to explore the best potential of weapons on their own and serve as a comparison tool when it comes to choosing your next DPS option. Do not expect to hit the DPS values provided. These values are for ultra-tier (boss) enemies only. They may or may not apply to other-tiered enemies, such as minibosses, champions, majors, and minors. For more context, see this.
C12: Contact
B13: =image("https://www.bungie.net/common/destiny2_content/icons/ef22dad66075d196eb70d63b553bbc37.jpg", 4, 65, 65) | C13: If you have any questions, comments, concerns, or would simply like to make contributions, you have a few methods of contact: > Google Form: use this Google form if you prefer to stay anonymous or do not want to use Reddit > Private Message: send a private message u/XboxUser123 > Reddit comment (fallback): make a comment on this Reddit post Please let me know of any potential issues, I am a one-man army (with some helpers) and keeping this spreadsheet as accurate as possible is the priority! | F13: =image("https://www.bungie.net/common/destiny2_content/icons/d0757ce420245c12bd9e57d2e7a1f3bc.jpg", 4, 65, 65)
C14: Definitions
B15: =image("https://www.bungie.net/common/destiny2_content/icons/0f4ca23c2d932ed784c7710a5b1c37d7.jpg", 4, 65, 65) | C15: Some definitions on words, phrases, and acronyms used: 1-Mag DPS or "True DPS" > The amount of DPS while not considering reloading, or equivalently (if applicable) of a single magazine. > The DPS of a single magazine and the DPS of omitting reloads entirely and focusing solely on damage and fire rate are identical. > Note that some weapons have a unique 1-mag DPS compared to their theoretical "True DPS" counterpart due to how they work (such as Merciless). Sustained DPS > The amount of DPS while also considering reloading. > This is the DPS you would expect to have for DPS phases, assuming you had infinite reserves and infinite time. > Note that this also assumes you hit the reload context as soon as you fire your final round. > If the data entry is for a single magazine, the Sustained DPS and True DPS will be equivalent. > A way to guage the difference between Sustained DPS and True DPS is to look it as minimums and maximums. > Sustained DPS is the minimum DPS expected, while 1-mag or "True DPS" is the maximum DPS expected. Average DPS > The amount of total damage divided by the total time. Although it is not considered in this spreadsheet, it can be easily calculated using existing values. > For more context, dividing the total damage over the time to empty should yield a result between the sustained and true DPS figures. > Average DPS should be closer to the sustained DPS than the true DPS. > If this average figure appears off, let me know as there may be a problem with how the time to empty is set up. For a more visual representation between the three DPS types, see the Equations page and the associated Desmos graph. The sloping lines in that graph represent the average DPS at an instant of time. cata > Stands for "catalyst," meaning the data row assumes an exotic weapon catalyst is used. DOT > Stands for "Damage Over Time," refers to passive damage sources, such as Witherhoard blights, that passively deal damage without your interaction over time. "w/" or "w/o" > Stands for "with" or "without," respectively. DDC > Stands for "Destiny Data Compendium," implies that the data was sourced from the Destiny Data Compendium Weapon damage is "normalized" > Weapons do not assume "new gear" bonus > Exotic weapons do not assume "featured gear" bonus | F15: =image("https://www.bungie.net/common/destiny2_content/icons/e55041686045a487bc46bc3f4cf0fe0f.jpg", 4, 65, 65)
B16: =image("https://www.bungie.net/common/destiny2_content/icons/2e3161404a48ca6f7326d4010f79bc13.jpg", 4, 65, 65) | F16: =image("https://www.bungie.net/common/destiny2_content/icons/940fbc426dcd7048d31160c92d5d5708.jpg", 4, 65, 65)
C17: Testing is done on the Dummy of Practice in the new shooting range, Normal difficulty (no modifiers)
C18: All damage testing is done on Barry in "The Investigation" mission of the Witch Queen campaign on legendary difficulty.
C20: References & Links
B21: =image("https://www.bungie.net/common/destiny2_content/icons/96fa99298a501e77a4f51337d3c12867.jpg", 4, 65, 65) | C21: External data used: D2Foundry/D2Gunsmith for some reload timings Destiny Data Compendium for certain multipliers and miscellaneous data Destiny 2 Inventory and Mag Database for reserves and magazine stats See Also: destiny2.science for other scientific research into Destiny 2 Inspired by: Damage Chart Madness | F21: =image("https://www.bungie.net/common/destiny2_content/icons/41b410dbf888f3256867c011a4e955e5.jpg", 4, 65, 65)

Sheet Bounty Board (1)
A1: Bounty Board
A2: Date Issued | B2: What is Needed | C2: Description | D2: Reward
A3: No bounties are present at this time
A4: 46004 | B4: Data! Data! Data! | C4: Need to retest entire suites of weapons. Simplest being the legendaries. See the TODO page for more specifics on what needs to be retested. Note: make sure to turn off the special surge that is going on this week if you decide to test the special weapons Note: don't forget, weapon stat will affect your damage output, make sure to minimize it to 0 or 1 | D4: The high ground

Sheet Primaries
A1: Note: all weapons assume Backup Mag whenever applicable; All weapon damage (except exotics) is normalized. Want to contribute? Have questions, comments, or concerns? See Home page contact information.
B2: Frame/Weapon | C2: 1-Mag Burst or "True" DPS | D2: Sustained DPS | F2: Theoretical Total Damage | G2: 1-Mag Damage | H2: Magazine Capacity | I2: Reserves + Magazine | J2: Fire rate (rpm) | K2: Reload Speed (s) | L2: Time to Empty (s) | M2: Body Damage | N2: Precision Damage
A3: Auto Rifles | B3: Rapid-Fire | C3: =(G3)/(H3 * 1/J3 * 60/1) -> 276 | D3: =(G3)/((H3-1) * 1/J3 * 60/1 + K3) -> 242.25098 | F3: inf | G3: =N3 * H3 -> 1610 | H3: 70 | I3: inf | J3: 720 | K3: =1.12*0.8 -> 0.896 | L3: inf | M3: 14 | N3: 23
B4: Adaptive | C4: =(G4)/(H4 * 1/J4 * 60/1) -> 260 | D4: =(G4)/((H4-1) * 1/J4 * 60/1 + K4) -> 220.53571 | F4: inf | G4: =N4 * H4 -> 1482 | H4: 57 | I4: inf | J4: 600 | K4: 1.12 | L4: inf | M4: 15 | N4: 26
B5: Support | C5: =(G5)/(H5 * 1/J5 * 60/1) -> 260 | D5: =(G5)/((H5-1) * 1/J5 * 60/1 + K5) -> 222.22222 | F5: inf | G5: =N5 * H5 -> 1560 | H5: 60 | I5: inf | J5: 600 | K5: 1.12 | L5: inf | M5: 19 | N5: =N4 -> 26
B6: Precision | C6: =(G6)/(H6 * 1/J6 * 60/1) -> 247.5 | D6: =(G6)/((H6-1) * 1/J6 * 60/1 + K6) -> 212.54771 | F6: inf | G6: =N6 * H6 -> 1485 | H6: 45 | I6: inf | J6: 450 | K6: 1.12 | L6: inf | M6: 20 | N6: 33
B7: High-Impact | C7: =(G7)/(H7 * 1/J7 * 60/1) -> 252 | D7: =(G7)/((H7-1) * 1/J7 * 60/1 + K7) -> 223.58044 | F7: inf | G7: =N7 * H7 -> 1890 | H7: 45 | I7: inf | J7: 360 | K7: 1.12 | L7: inf | M7: 24 | N7: 42
A8: average per mag | B8: Sweet Business | C8: =(G8)/(H8 * 1/J8 * 60/1) -> 471.68675 | D8: =(G8)/((H8-1) * 1/J8 * 60/1 + K8) -> 398.5295 | F8: inf | G8: =N8 * H8 + ('Weapon Specifics'!D64*4 + floor(108/8,1)*'Weapon Specifics'!D64) -> 4959 | H8: 150 | I8: inf | J8: =150/(1.38 * 1/60 + (150-13) * 1/900) -> 856.0558 | K8: 2 | L8: inf | M8: 20 | N8: 30
A9: Spinning Up | B9: Suros Regime | C9: =(G9)/(H9 * 1/J9 * 60/1) -> 332.24128 | D9: =(G9)/((H9-1) * 1/J9 * 60/1 + K9) -> 244.06429 | F9: inf | G9: =H9/2 * N9 + H9/2 * N9 * (1.05+1.1)/2 -> 952.425 | H9: 34 | I9: inf | J9: =H9/(12 * 1/600 + 12 * 1/720 + (H9-24) * 1/900) -> 711.62791 | K9: =K10 -> 1.12 | L9: inf | M9: 16 | N9: 27
A10: Dual Speed Receiver | B10: Suros Regime | C10: =(G10)/(H10 * 1/J10 * 60/1) -> 273.9 | D10: =(G10)/((H10-1) * 1/J10 * 60/1 + K10) -> 234.45619 | F10: inf | G10: =H10/2 * N10 + H10/2 * N10 * (1.05+1.1)/2 -> 1552.1 | H10: 34 | I10: inf | J10: 360 | K10: 1.12 | L10: inf | M10: 25 | N10: 44 | O10: Aiming-down-sights only
B11: Tommy's Matchbook | C11: =(G11)/(H11 * 1/J11 * 60/1) + 'Elemental Effects'!E13 -> 711.84143 | D11: =(G11)/((H11-1) * 1/J11 * 60/1 + K11) + 'Elemental Effects'!E13 -> 648.24735 | F11: inf | G11: =(20 * 'Weapon Specifics'!D76) + N11*(H11-20) + ('Elemental Effects'!$E$4)*(2) -> 5746 | H11: 100 | I11: inf | J11: 720 | K11: 0.93 | L11: inf | M11: 28 | N11: 47 | O11: Assumes normal 20 bullets + 80 buffed while burning; considers ignitions and approx. scorch
A12: Ember of Ashes | B12: Tommy's Matchbook | C12: =(G12)/(H12 * 1/J12 * 60/1) + 'Elemental Effects'!E13 -> 801.00143 | D12: =(G12)/((H12-1) * 1/J12 * 60/1 + K12) + 'Elemental Effects'!E13 -> 729.18417 | F12: inf | G12: =(20 * 'Weapon Specifics'!D76) + N12*(H12-20) + ('Elemental Effects'!$E$4)*(3) -> 6489 | H12: 100 | I12: inf | J12: 720 | K12: 0.93 | L12: inf | M12: =M11 -> 28 | N12: =N11 -> 47 | O12: Assumes normal 20 bullets + 80 buffed while burning; considers ignitions and approx. scorch
B13: Quicksilver Storm | C13: =(G13)/(H13 * 1/J13 * 60/1) -> 367.05882 | D13: =(G13)/((H13-1) * 1/J13 * 60/1 + K13) -> 296.20253 | F13: inf | G13: =H13*N13 + FLOOR(H13/'Weapon Specifics'!D48,1) * ('Weapon Specifics'!D49) -> 1560 | H13: 51 | I13: inf | J13: 720 | K13: 1.1 | L13: inf | M13: 14 | N13: 24 | O13: DPS assumes bullets + rockets.
A14: mixed modes | B14: Quicksilver Storm | C14: =D14 -> 445.46763 | D14: =(N14*22 + ('Weapon Specifics'!D49)*2 + ('Weapon Specifics'!D50)*2)/(('Weapon Specifics'!D48*2) * 1/J14 * 60/1 + 1.1 + 1.1 + 0.6) -> 445.46763 | F14: inf | G14: N/A | H14: 51 | I14: inf | J14: 720 | K14: 1.1 | L14: inf | M14: =M13 -> 14 | N14: =N13 -> 24 | O14: DPS assumes 22 rounds + 2 rockets > grenade > grenade > repeat; an extra grenade is held
B15: Necrochasm | C15: =(G15)/(H15 * 1/J15 * 60/1) -> 288 | D15: =(G15)/((H15-1) * 1/J15 * 60/1 + K15) -> 228.86205 | F15: inf | G15: =N15 * H15 -> 1200 | H15: 50 | I15: inf | J15: 720 | K15: 1.16 | L15: inf | M15: =M13 -> 14 | N15: =N13 -> 24
B16: Vex Mythoclast | C16: =(G16)/(H16 * 1/J16 * 60/1) -> 612 | D16: =(G16)/((H16-1) * 1/J16 * 60/1 + K16) -> 498.04688 | F16: inf | G16: =N16 * H16 -> 2550 | H16: 25 | I16: inf | J16: 360 | K16: 1.12 | L16: inf | M16: 57 | N16: 102 | O16: Excludes linear shots
B17: Hard Light | C17: =(G17)/(H17 * 1/J17 * 60/1) -> 270 | D17: =(G17)/((H17-1) * 1/J17 * 60/1 + K17) -> 223.47973 | F17: inf | G17: =N17 * H17 -> 1323 | H17: 49 | I17: inf | J17: 600 | K17: 1.12 | L17: inf | M17: 16 | N17: 27
B18: Khvostov 7G-0X | C18: =(N18*6 + 'Weapon Specifics'!D33)/(7 * 1/J18 * 60/1) -> 304.28571 | D18: =((H18-7)*N18 + 7*'Weapon Specifics'!D33)/((H18-1) * 1/J18 * 60/1 + K18) -> 249.81203 | F18: inf | G18: =N18 * (H18 - floor(H18/7,1)) + FLOOR(H18/7,1) * N18*(1+2.52) -> 1569.24 | H18: 43 | I18: inf | J18: 600 | K18: 1.12 | L18: inf | M18: =M17 -> 16 | N18: =N17 -> 27 | O18: with ricochet rounds
B19: Monte Carlo | C19: =(G19)/(H19 * 1/J19 * 60/1) -> 270 | D19: =(G19)/((H19-1) * 1/J19 * 60/1 + K19) -> 219.18819 | F19: inf | G19: =N19 * H19 -> 1188 | H19: 44 | I19: inf | J19: 600 | K19: 1.12 | L19: inf | M19: =M17 -> 16 | N19: =N17 -> 27 | O19: =CONCAT("Bayonet does ", 'Weapon Specifics'!$D$40) -> Bayonet does 2913
B20: Centrifuse | C20: =(G20)/(H20 * 1/J20 * 60/1) -> 262.5 | D20: =(G20)/((H20-1) * 1/J20 * 60/1 + K20) -> 247.3822 | F20: inf | G20: =N20 * H20 -> 1575 | H20: 45 | I20: inf | J20: 450 | K20: 0.5 | L20: inf | M20: 21 | N20: 35
A21: normal, close range | B21: Cerberus+1 | C21: =(G21)/(H21 * 1/J21 * 60/1) -> 312 | D21: =(G21)/((H21-1) * 1/J21 * 60/1 + K21) -> 263.39869 | F21: inf | G21: =M21 * H21 -> 1612 | H21: 31 | I21: inf | J21: 360 | K21: 1.12 | L21: inf | M21: =13*4 -> 52 | N21: 93 | O21: Body damage DPS
A22: normal, close range | B22: Cerberus+1 | C22: =(G22)/(H22 * 1/J22 * 60/1) -> 558 | D22: =(G22)/((H22-1) * 1/J22 * 60/1 + K22) -> 471.07843 | F22: inf | G22: =N22 * H22 -> 2883 | H22: 31 | I22: inf | J22: =J21 -> 360 | K22: 1.12 | L22: inf | M22: =M21 -> 52 | N22: =N21 -> 93 | O22: Precision damage DPS
A23: normal, far range | B23: Cerberus+1 | C23: =(G23)/(H23 * 1/J23 * 60/1) -> 384 | D23: =(G23)/((H23-1) * 1/J23 * 60/1 + K23) -> 324.18301 | F23: inf | G23: =M23 * H23 -> 1984 | H23: 31 | I23: inf | J23: =J21 -> 360 | K23: 1.12 | L23: inf | M23: =16*4 -> 64 | N23: =28*4 -> 112 | O23: Reverse damage fall-off; body damage DPS
A24: normal, far range | B24: Cerberus+1 | C24: =(G24)/(H24 * 1/J24 * 60/1) -> 672 | D24: =(G24)/((H24-1) * 1/J24 * 60/1 + K24) -> 567.32026 | F24: inf | G24: =N24 * H24 -> 3472 | H24: 31 | I24: inf | J24: =J21 -> 360 | K24: 1.12 | L24: inf | M24: =M23 -> 64 | N24: =N23 -> 112 | O24: Reverse damage fall-off; all precision shots land for precision damage DPS (if it's even possible)
A25: cata, close range | B25: Cerberus+1 | C25: =(G25)/(H25 * 1/J25 * 60/1) -> 468 | D25: N/A | F25: inf | G25: =M25 * H25 -> 2418 | H25: 31 | I25: inf | J25: =J21 -> 360 | K25: 1.12 | L25: inf | M25: =M21*1.5 -> 78 | N25: =N21*1.5 -> 139.5 | O25: Body damage DPS; requires a kill before reload, buff lasts for ~8 seconds
A26: cata, close range | B26: Cerberus+1 | C26: =(G26)/(H26 * 1/J26 * 60/1) -> 837 | D26: N/A | F26: inf | G26: =N26 * H26 -> 4324.5 | H26: 31 | I26: inf | J26: =J21 -> 360 | K26: 1.12 | L26: inf | M26: =M25 -> 78 | N26: =N25 -> 139.5 | O26: Precision damage DPS; requires a kill before reload, buff lasts for ~8 seconds
A27: cata, far range | B27: Cerberus+1 | C27: =(G27)/(H27 * 1/J27 * 60/1) -> 576 | D27: N/A | F27: inf | G27: =M27 * H27 -> 2976 | H27: 31 | I27: inf | J27: =J21 -> 360 | K27: 1.12 | L27: inf | M27: =M23*1.5 -> 96 | N27: =N23*1.5 -> 168 | O27: Body damage DPS; requires a kill before reload, buff lasts for ~8 seconds
A28: cata, far range | B28: Cerberus+1 | C28: =(G28)/(H28 * 1/J28 * 60/1) -> 1008 | D28: N/A | F28: inf | G28: =N28 * H28 -> 5208 | H28: 31 | I28: inf | J28: =J21 -> 360 | K28: 1.12 | L28: inf | M28: =M27 -> 96 | N28: =N27 -> 168 | O28: Precision damage DPS; requires a kill before reload, buff lasts for ~8 seconds
A29: SMGs | B29: Precision | C29: =(G29)/(H29 * 1/J29 * 60/1) -> 370 | D29: =(G29)/((H29-1) * 1/J29 * 60/1 + K29) -> 271.39364 | F29: inf | G29: =N29 * H29 -> 1110 | H29: 30 | I29: inf | J29: 600 | K29: 1.19 | L29: inf | M29: 23 | N29: 37
B30: Aggressive | C30: =(G30)/(H30 * 1/J30 * 60/1) -> 396 | D30: =(G30)/((H30-1) * 1/J30 * 60/1 + K30) -> 274.49168 | F30: inf | G30: =N30 * H30 -> 990 | H30: 30 | I30: inf | J30: 720 | K30: 1.19 | L30: inf | M30: 19 | N30: 33
B31: Adaptive | C31: =(G31)/(H31 * 1/J31 * 60/1) -> 390 | D31: =(G31)/((H31-1) * 1/J31 * 60/1 + K31) -> 276.40449 | F31: inf | G31: =N31 * H31 -> 1066 | H31: 41 | I31: inf | J31: 900 | K31: 1.19 | L31: inf | M31: 16 | N31: 26
B32: Lightweight | C32: =(G32)/(H32 * 1/J32 * 60/1) -> 420 | D32: =(G32)/((H32-1) * 1/J32 * 60/1 + K32) -> 295.51451 | F32: inf | G32: =N32 * H32 -> 1120 | H32: 40 | I32: inf | J32: 900 | K32: 1.19 | L32: inf | M32: 15 | N32: 28
B33: Riskrunner | C33: =(G33)/(H33 * 1/J33 * 60/1) -> 420 | D33: =(G33)/((H33-1) * 1/J33 * 60/1 + K33) -> 309.1621 | F33: inf | G33: =N33 * H33 -> 1316 | H33: 47 | I33: inf | J33: 900 | K33: 1.19 | L33: inf | M33: 17 | N33: 28
A34: Arc Conductor | B34: Riskrunner | C34: =(G34)/(H34 * 1/J34 * 60/1) -> 462 | D34: =(G34)/((H34-1) * 1/J34 * 60/1 + K34) -> 340.07831 | F34: inf | G34: =N34 * H34 -> 1447.6 | H34: =H33 -> 47 | I34: inf | J34: 900 | K34: 1.19 | L34: inf | M34: =M33*1.1 -> 18.7 | N34: =N33*1.1 -> 30.8
A35: Grounded | B35: The Manticore | C35: =(G35)/(H35 * 1/J35 * 60/1) -> 435 | D35: =(G35)/((H35-1) * 1/J35 * 60/1 + K35) -> 310.4503 | F35: inf | G35: =N35 * H35 -> 1218 | H35: 42 | I35: inf | J35: 900 | K35: 1.19 | L35: inf | M35: 16 | N35: 29
A36: Airborne | B36: The Manticore | C36: =(67*N36 * (1 + 2))/(67*2 * 1/J36 * 60/1 + 0.5) -> 617.91519 | D36: =(67*N36 * (1 + 2))/((67-1)*1/J36*60/1 + E36*2 + 0.5 + (67-1)*1/J36*60/1 + K36) -> 555.67207 | F36: inf | G36: =N36 * H36 -> 1218 | H36: =H35 -> 42 | I36: inf | J36: 900 | K36: =K35 -> 1.19 | L36: inf | M36: =M35 -> 16 | N36: =N35 -> 29 | O36: 67 shots to fill (37 + reload + 30 + reload) > jump > 67 airborne shots
A37: Ride the Bull average | B37: Huckleberry | C37: =(G37)/(H37 * 1/J37 * 60/1) + ('Weapon Specifics'!$D$66*3)/(3+0.285+2) -> 567.3536 | D37: =(G37 + 'Weapon Specifics'!$D$66*3)/((H37-1) * 1/J37 * 60/1 + K37) -> 464.63688 | F37: inf | G37: =N37 * H37 -> 1428 | H37: 42 | I37: inf | J37: =H37/(10 * 1/750 + 10 * 1/810 + (H37-20) * 1/900) -> 837.93103 | K37: 1.19 | L37: inf | M37: 20 | N37: 34
A38: Ride the Bullx2 + Rmpgx3 | B38: Huckleberry | C38: =(G38 + 'Weapon Specifics'!$D$66*3)/(H38 * 1/J38 * 60/1) -> 1021.2429 | D38: N/A | F38: inf | G38: =N38 * H38 -> 2370.48 | H38: =H37 -> 42 | I38: inf | J38: 900 | K38: N/A | L38: inf | M38: =M37*1.66 -> 33.2 | N38: =N37*1.66 -> 56.44 | O38: This assumes 3 kills have been made
B39: Tarrabah | C39: =(G39)/(H39 * 1/J39 * 60/1) -> 408 | D39: =(G39)/((H39-1) * 1/J39 * 60/1 + K39) -> 295.77465 | F39: inf | G39: =N39 * H39 -> 1190 | H39: 35 | I39: inf | J39: 720 | K39: 1.19 | L39: inf | M39: =M37 -> 20 | N39: =N37 -> 34
A40: Ravenous Beast | B40: Tarrabah | C40: =(G40)/(H40 * 1/J40 * 60/1) -> 855 | D40: =(G40)/((H40-1) * 1/J40 * 60/1 + K40) -> 619.82187 | F40: inf | G40: =N40 * H40 -> 1995 | H40: =H39 -> 35 | I40: inf | J40: 900 | K40: =K39*0.8 -> 0.952 | L40: inf | M40: 56 | N40: 57
...

Sheet Specials
A1: Note: all weapons assume Backup Mag whenever applicable; All weapon damage (except exotics) is normalized. Want to contribute? Have questions, comments, or concerns? See Home page contact information.
B2: Frame/Weapon | C2: 1-Mag Burst or "True" DPS | D2: Sustained DPS | F2: Theoretical Total Damage | G2: 1-Mag Damage | H2: Magazine Capacity | I2: Reserves + Magazine | J2: Fire rate (rpm) | K2: Reload Speed (s) | L2: Time to Empty (s) | M2: Body Damage | N2: Precision Damage
A3: Sniper Rifles | B3: Rapid-Fire | C3: =(G3)/(H3 * 1/J3 * 60/1) -> 1050 | D3: =(G3)/((H3-1) * 1/J3 * 60/1 + K3) -> 758.04455 | F3: =I3*N3 -> 13950 | G3: =N3 * H3 -> 3150 | H3: 7 | I3: ='Reserves Data (Reference)'!$D$3 -> 31 | J3: 140 | K3: =1.98*0.8 -> 1.584 | L3: =timeToEmpty(H3,I3,J3,K3) -> 17.478857 | M3: 131 | N3: 450
A4: Triple Tap | B4: Rapid-Fire | C4: =(G4)/(H4 * 1/J4 * 60/1) -> 1050 | D4: =(G4)/((H4-1) * 1/J4 * 60/1 + K4) -> 827.03214 | F4: =I4*N4 -> 19800 | G4: =N4 * H4 -> 4500 | H4: =tripleTap($H$3) -> 10 | I4: =floor(I3/H3,1)*H4+tripleTap(mod(I3, H3)) -> 44 | J4: 140 | K4: =1.98*0.8 -> 1.584 | L4: =timeToEmpty(H4,I4,J4,K4) -> 23.050286 | M4: =M3 -> 131 | N4: =N3 -> 450 | O4: Assumes precision hit counter is reset on every reload
A5: Fourth Time's the Charm | B5: Rapid-Fire | C5: =(G5)/(H5 * 1/J5 * 60/1) -> 1050 | D5: =(G5)/((H5-1) * 1/J5 * 60/1 + K5) -> 843.31192 | F5: =I5*N5 -> 21150 | G5: =N5 * H5 -> 4950 | H5: =fourthTimesTheCharm(H3) -> 11 | I5: =floor(I3/H3,1)*H5+fourthtimesthecharm(mod(I3, H3)) -> 47 | J5: 140 | K5: =1.98*0.8 -> 1.584 | L5: =timeToEmpty(H5,I5,J5,K5) -> 24.336 | M5: =M3 -> 131 | N5: =N3 -> 450 | O5: Assumes precision hit counter is reset on every reload
A6: FTTC + Rewind Round | B6: Rapid-Fire | C6: =(N6)/(1/J6 * 60/1) -> 1050 | D6: =C6 -> 1050 | F6: =I6*N6 -> 26550 | G6: N/A | H6: =I6 -> 59 | I6: =fourthTimesTheCharm(I3) -> 59 | J6: 140 | K6: =1.98*0.8 -> 1.584 | L6: =timeToEmpty(H6,I6,J6,K6) -> 24.857143 | M6: =M4 -> 131 | N6: =N4 -> 450 | O6: Assumes being able to fire all rounds without reloading due to perk interactions
B7: Adaptive | C7: =(G7)/(H7 * 1/J7 * 60/1) -> 891 | D7: =(G7)/((H7-1) * 1/J7 * 60/1 + K7) -> 695.31773 | F7: =I7*N7 -> 14256 | G7: =N7 * H7 -> 4158 | H7: 7 | I7: ='Reserves Data (Reference)'!$D$4 -> 24 | J7: 90 | K7: 1.98 | L7: =timeToEmpty(H7,I7,J7,K7) -> 19.273333 | M7: 183 | N7: 594
A8: Triple Tap | B8: Adaptive | C8: =(G8)/(H8 * 1/J8 * 60/1) -> 891 | D8: =(G8)/((H8-1) * 1/J8 * 60/1 + K8) -> 744.3609 | F8: =I8*N8 -> 20196 | G8: =N8 * H8 -> 5940 | H8: =tripleTap(H7) -> 10 | I8: =floor(I7/H7,1)*H8+tripletap(mod(I7, H7)) -> 34 | J8: 90 | K8: 1.98 | L8: =timeToEmpty(H8,I8,J8,K8) -> 25.94 | M8: =M7 -> 183 | N8: =N7 -> 594 | O8: Assumes precision hit counter is reset on every reload
A9: Fourth Time's the Charm | B9: Adaptive | C9: =(G9)/(H9 * 1/J9 * 60/1) -> 891 | D9: =(G9)/((H9-1) * 1/J9 * 60/1 + K9) -> 755.66692 | F9: =I9*N9 -> 21384 | G9: =N9 * H9 -> 6534 | H9: =fourthTimesTheCharm($H$7) -> 11 | I9: =floor(I7/H7,1)*H9+fourthtimesthecharm(mod(I7, H7)) -> 36 | J9: 90 | K9: 1.98 | L9: =timeToEmpty(H9,I9,J9,K9) -> 27.273333 | M9: =M7 -> 183 | N9: =N7 -> 594 | O9: Assumes precision hit counter is reset on every reload
B10: Aggressive | C10: =(G10)/(H10 * 1/J10 * 60/1) -> 871.2 | D10: =(G10)/((H10-1) * 1/J10 * 60/1 + K10) -> 683.18695 | F10: =I10*N10 -> 14520 | G10: =N10 * H10 -> 3630 | H10: 5 | I10: ='Reserves Data (Reference)'!$D$5 -> 20 | J10: 72 | K10: 1.98 | L10: =timeToEmpty(H10,I10,J10,K10) -> 19.273333 | M10: 208 | N10: 726
A11: Triple Tap | B11: Aggressive | C11: =(G11)/(H11 * 1/J11 * 60/1) -> 871.2 | D11: =(G11)/((H11-1) * 1/J11 * 60/1 + K11) -> 728.08023 | F11: =I11*N11 -> 20328 | G11: =N11 * H11 -> 5082 | H11: =tripleTap(H10) -> 7 | I11: =floor(I10/H10,1)*H11+tripletap(mod(I10, H10)) -> 28 | J11: 72 | K11: 1.98 | L11: =timeToEmpty(H11,I11,J11,K11) -> 25.94 | M11: =M10 -> 208 | N11: =N10 -> 726 | O11: Assumes precision hit counter is reset on every reload
A12: Fourth Time's the Charm | B12: Aggressive | C12: =(G12)/(H12 * 1/J12 * 60/1) -> 871.2 | D12: =(G12)/((H12-1) * 1/J12 * 60/1 + K12) -> 728.08023 | F12: =I12*N12 -> 20328 | G12: =N12 * H12 -> 5082 | H12: =fourthTimesTheCharm(H10) -> 7 | I12: =floor(I10/H10,1)*H12+fourthtimesthecharm(mod(I10, H10)) -> 28 | J12: 72 | K12: 1.98 | L12: =timeToEmpty(H12,I12,J12,K12) -> 25.94 | M12: =M10 -> 208 | N12: =N10 -> 726 | O12: Assumes precision hit counter is reset on every reload
B13: Cloudstrike | C13: =N13*J13/60 + ('Weapon Specifics'!$D$10)/(3*1/J13*60/1) -> 1552.4444 | D13: =(G13)/((H13-1) * 1/J13 * 60/1 + K13) -> 1195.9303 | F13: =I13*N13 + floor(I13/3,1)*('Weapon Specifics'!$D$10) -> 20410 | G13: =N13 * H13 + CEILING(H13/3,1)*('Weapon Specifics'!$D$10) -> 5088 | H13: 7 | I13: ='Reserves Data (Reference)'!$D$6 -> 31 | J13: 140 | K13: =1.98*0.85 -> 1.683 | L13: =timeToEmpty(H13,I13,J13,K13) -> 17.874857 | M13: =M3 -> 131 | N13: =N3 -> 450 | O13: Assumes precision hit counter is reset on every reload; Strikes occur every three precision hits
A14: cata | B14: Cloudstrike | C14: =N14*J14/60 + ('Weapon Specifics'!$D$10)/(3*1/J14*60/1) -> 1552.4444 | D14: =(G14)/((H14-1) * 1/J14 * 60/1 + K14) -> 1278.6674 | F14: =I14*N14 + floor(I14/3,1)*('Weapon Specifics'!$D$10) -> 28844 | G14: =N14 * H14 + CEILING(H14/3,1)*('Weapon Specifics'!$D$10) -> 7084 | H14: =tripleTap(H13) -> 10 | I14: =FLOOR(I13/H13,1)*H14+tripleTap(MOD(I13,H13)) -> 44 | J14: 140 | K14: =K13 -> 1.683 | L14: =timeToEmpty(H14,I14,J14,K14) -> 23.446286 | M14: =M13 -> 131 | N14: =N13 -> 450 | O14: Assumes precision hit counter is reset on every reload; Strikes occur every three precision hits
B15: Izanagi's Burden | C15: =(G15)/(H15 * 1/J15 * 60/1) -> 891 | D15: =(G15)/((H15-1) * 1/J15 * 60/1 + K15) -> 596.98492 | F15: =I15*N15 -> 11880 | G15: =N15 * H15 -> 2376 | H15: 4 | I15: ='Reserves Data (Reference)'!$D$7 -> 20 | J15: 90 | K15: 1.98 | L15: =timeToEmpty(H15,I15,J15,K15) -> 17.92 | M15: =M7 -> 183 | N15: =N7 -> 594
A16: cata, 4x Honed Edge | B16: Izanagi's Burden | C16: =D16 -> 515 | D16: =(G16)/((H16-1) * 1/J16 * 60/1 + K16) -> 515 | F16: =N16*floor(I16/4,1) +if(mod(I16, 4)=3, N15*2.31, if(mod(I16, 4)=2, N15*1.79, if(mod(I16, 4)=1, N15, 0))) -> 13390 | G16: =N16*floor(H16/4,1) -> 2678 | H16: =H15 -> 4 | I16: =I15 -> 20 | J16: 90 | K16: 3.2 | L16: =timeToEmpty(H16,I16,J16,K16) -> 22.8 | M16: 466 | N16: 2678
B17: Still Hunt | C17: =(G17)/((H17+3) * 1/J17 * 60/1 + 'Weapon Specifics'!$D$59) -> 1140.8031 | D17: =(G17)/((H17+3-1) * 1/J17 * 60/1 + K17 + 'Weapon Specifics'!$D$59) -> 974.94465 | F17: =I17*N17 + floor(I17/6+1,1)*('Weapon Specifics'!$D$61) -> 32852 | G17: =N17 * H17 + ('Weapon Specifics'!$D$61) -> 8807 | H17: 6 | I17: ='Reserves Data (Reference)'!D8 -> 20 | J17: 90 | K17: 1.98 | L17: =3*1/J17*60 + floor(I17/H17,1)*(6*1/J17*60 + 'Weapon Specifics'!$D$59 + 3*1/J17*60 + K17) + (mod(I17, H17)-1)*1/J17*60 -> 31.766667 | M17: =M7 -> 183 | N17: =N7 -> 594 | O17: Magazine is reloaded on cast, but golden gun shots are from the magazine
A18: Celestial | B18: Still Hunt | C18: =(G18)/((H18+1) * 1/J18 * 60/1 + 'Weapon Specifics'!$D$59) -> 1358.2985 | D18: =(G18)/((H18+1-1) * 1/J18 * 60/1 + K18 + 'Weapon Specifics'!$D$59) -> 1126.6234 | F18: =I18*N18 + floor(I18/6+1,1)*'Weapon Specifics'!$D$63 -> 32324 | G18: =N18 * H18 + 'Weapon Specifics'!$D$63 -> 8675 | H18: 6 | I18: =I17 -> 20 | J18: 90 | K18: 1.98 | L18: =1*1/J18*60 + floor(I18/H18,1)*(6*1/J18*60 + 'Weapon Specifics'!$D$59 + 1*1/J18*60 + K18) + (mod(I18, H18)-1)*1/J18*60 -> 26.433333 | M18: =M17 -> 183 | N18: =N17 -> 594 | O18: Magazine is reloaded on cast, but golden gun shots are from the magazine
B19: Borealis | C19: =(G19)/(H19 * 1/J19 * 60/1) -> 871.2 | D19: =(G19)/((H19-1) * 1/J19 * 60/1 + K19) -> 683.18695 | F19: =I19*N19 -> 14520 | G19: =N19 * H19 -> 3630 | H19: 5 | I19: ='Reserves Data (Reference)'!$D$9 -> 20 | J19: 72 | K19: 1.98 | L19: =timeToEmpty(H19,I19,J19,K19) -> 19.273333 | M19: =M10 -> 208 | N19: =N10 -> 726
A20: Ionic Return | B20: Borealis | C20: =(G20)/((H20-1) * 1/J20 * 60/1) -> 1524.6 | D20: N/A | F20: =I20*N20 -> 20328 | G20: =N20 * H20 -> 5082 | H20: 5 | I20: ='Reserves Data (Reference)'!$D$9 -> 20 | J20: 72 | K20: 1.98 | L20: =timeToEmpty(H20,I20,J20,K20) -> 19.273333 | M20: =M19*1.4 -> 291.2 | N20: =N19*1.4 -> 1016.4
A21: The Master 0x | B21: New Land Beyond | C21: =(G21)/(H21 * 1/J21 * 60/1) -> 556.21622 | D21: =(G21)/((H21-1) * 1/J21 * 60/1 + K21) -> 551.37307 | F21: =I21*N21 -> 41160 | G21: =N21 * H21 -> 8232 | H21: 8 | I21: ='Reserves Data (Reference)'!D10 -> 40 | J21: =1/(1.85 * 1/60) -> 32.432432 | K21: 1.98 | L21: =timeToEmpty(H21,I21,J21,K21) -> 72.67 | M21: 374 | N21: 1029 | O21: Base damage, The Master 0x, without any stat buffs
A22: The Master 0x | B22: New Land Beyond | C22: =(G22)/(H22 * 1/J22 * 60/1) -> 751.09489 | D22: =(G22)/((H22-1) * 1/J22 * 60/1 + K22) -> 711.49525 | F22: =I22*N22 -> 41160 | G22: =N22 * H22 -> 8232 | H22: =H21 -> 8 | I22: =I21 -> 40 | J22: =1/(1.37 * 1/60) -> 43.79562 | K22: =K21 -> 1.98 | L22: =timeToEmpty(H22,I22,J22,K22) -> 55.87 | M22: =M21 -> 374 | N22: =N21 -> 1029 | O22: Base damage, The Master 0x, with a Rally Barricade
A23: The Master 10x | B23: New Land Beyond | C23: =(G23)/(H23 * 1/J23 * 60/1) -> 1123.3577 | D23: =(G23)/((H23-1) * 1/J23 * 60/1 + K23) -> 1064.1314 | F23: =I23*N23 -> 61560 | G23: =N23 * H23 -> 12312 | H23: =H21 -> 8 | I23: =I21 -> 40 | J23: =J22 -> 43.79562 | K23: =K21 -> 1.98 | L23: =L22 -> 55.87 | M23: =M21 -> 374 | N23: 1539 | O23: The Master 10x, with a Rally Barricade
A24: The Master 20x | B24: New Land Beyond | C24: =(G24)/(H24 * 1/J24 * 60/1) -> 1276.6423 | D24: =(G24)/((H24-1) * 1/J24 * 60/1 + K24) -> 1209.3345 | F24: =I24*N24 -> 69960 | G24: =N24 * H24 -> 13992 | H24: =H21 -> 8 | I24: =I21 -> 40 | J24: =J23 -> 43.79562 | K24: =K21 -> 1.98 | L24: =L22 -> 55.87 | M24: =M21 -> 374 | N24: 1749 | O24: The Master 20x, with a Rally Barricade
B25: Ice Breaker | C25: =G25/L25 -> 871.38333 | D25: =C25 -> 871.38333 | F25: =G25 -> 10670 | G25: =H25*N25 -> 10670 | H25: 10 | I25: N/A | J25: 49 | K25: N/A | L25: =H25*1/J25*60 -> 12.244898 | M25: 305 | N25: 1067
A26: Trace Rifles | B26: Adaptive | C26: =(G26)/(H26 * 1/J26 * 60/1) -> 420 | D26: =(G26)/((H26-1) * 1/J26 * 60/1 + K26) -> 350.5618 | F26: =I26*N26 -> 14560 | G26: =N26 * H26 -> 2912 | H26: 104 | I26: ='Reserves Data (Reference)'!$D$11 -> 520 | J26: 900 | K26: 1.44 | L26: =timeToEmpty(H26,I26,J26,K26) -> 40.093333 | M26: 21 | N26: 28
B27: Ruinous Effigy | C27: =(G27)/(H27 * 1/J27 * 60/1) -> 615 | D27: =(G27)/((H27-1) * 1/J27 * 60/1 + K27) -> 504.45026 | F27: =I27*N27 -> 19270 | G27: =N27 * H27 -> 3854 | H27: 94 | I27: ='Reserves Data (Reference)'!$D$12 -> 470 | J27: 900 | K27: 1.44 | L27: =timeToEmpty(H27,I27,J27,K27) -> 36.76 | M27: 30 | N27: 41
A28: cata | B28: Ruinous Effigy | C28: =(G28)/(H28 * 1/J28 * 60/1) -> 799.5 | D28: =(G28)/((H28-1) * 1/J28 * 60/1 + K28) -> 655.78534 | F28: =I28*N28 -> 25051 | G28: =N28 * H28 -> 5010.2 | H28: =H27 -> 94 | I28: =I27 -> 470 | J28: =J27 -> 900 | K28: 1.44 | L28: =timeToEmpty(H28,I28,J28,K28) -> 36.76 | M28: =M27*1.3 -> 39 | N28: =N27*1.3 -> 53.3 | O28: Assumes 100% uptime on enemy debuffed from being hit by the orb
A29: Transmutation Sphere | B29: Ruinous Effigy | C29: =(G29)/((H29-1) * 1/J29 * 60/1 + 48/60) -> 601.89542 | D29: N/A | F29: =G29 -> 9209 | G29: =M29 * (H29-1) + 'Weapon Specifics'!$D$54 -> 9209 | H29: 30 | I29: 30 | J29: =1/(30/60*1/60) -> 120 | K29: N/A | L29: =I29*1/J29*60/1 -> 15 | M29: 271 | N29: 203 | O29: One swing is barely faster than the other, assumes melee spam and slam on final ammo
A30: T-Sphere blocking field | B30: Ruinous Effigy | C30: =(G30)/(L30+0.8) -> 238.59649 | D30: N/A | F30: =G30 -> 2040 | G30: =M30 * H30 + 'Weapon Specifics'!$D$54 -> 2040 | H30: 30 | I30: 30 | J30: =1/(0.25*1/60) -> 240 | K30: N/A | L30: =(I30-3)*1/J30*60/1 + (3-1)*0.5 -> 7.75 | M30: 23 | N30: =M30 -> 23 | O30: Assumes you slam on 1 ammo, uses the full 30 ammo before slamming
A31: base damage, no buffs | B31: Divinity | C31: =(H31*N31)/(H31 * 1/J31 * 60/1) + 'Weapon Specifics'!$D$16/1.3/((17+60)*1/J31*60) -> 335.58941 | D31: =(G31)/((H31-1) * 1/J31 * 60/1 + K31) -> 282.76221 | F31: =I31*N31 -> 7050 | G31: =N31 * H31 + FLOOR((H32-17)/60,1)*('Weapon Specifics'!$D$16*1/1.3) -> 4045.3846 | H31: 194 | I31: ='Reserves Data (Reference)'!$D$13 -> 470 | J31: 900 | K31: 1.44 | L31: =timeToEmpty(H31,I31,J31,K31) -> 34.013333 | M31: 11 | N31: 15 | O31: Still assumes Penance; Penance will benefit from any buffs or debuffs applied
A32: with Judgement | B32: Divinity | C32: =(H32*N32)/(H32 * 1/J32 * 60/1) + 'Weapon Specifics'!$D$16/((17+60)*1/J32*60) -> 436.26623 | D32: =(G32)/((H32-1) * 1/J32 * 60/1 + K32) -> 413.82805 | F32: =I32*N32 -> 9165 | G32: =17*N31 + N32 * (H32-17) + FLOOR((H32-10)/60,1)*'Weapon Specifics'!$D$16 -> 5920.5 | H32: =H31 -> 194 | I32: =I31 -> 470 | J32: =J31 -> 900 | K32: =K31 -> 1.44 | L32: =L31 -> 34.013333 | M32: =N32 -> 19.5 | N32: =N31*1.3 -> 19.5 | O32: Judgement activates after ~17 rounds, Penance every 60 on Judgement and deals 24794
B33: Coldheart | C33: =(G33)/(H33 * 1/J33 * 60/1) -> 709.97525 | D33: =(G33)/((H33-1) * 1/J33 * 60/1 + K33) -> 589.69984 | F33: =I33*N33 -> 14645 | G33: =((N33+'Weapon Specifics'!$D$11)/2 * 41) + 'Weapon Specifics'!$D$11*(H33-41) -> 4780.5 | H33: 101 | I33: ='Reserves Data (Reference)'!$D$14 -> 505 | J33: 900 | K33: 1.44 | L33: =timeToEmpty(H33,I33,J33,K33) -> 39.093333 | M33: 22 | N33: 29
A34: after Ionic Trace pickup | B34: Coldheart | C34: =(G34)/(H34 * 1/J34 * 60/1) -> 723.63861 | D34: =(G34)/((H34-1) * 1/J34 * 60/1 + K34) -> 601.04852 | F34: =I34*N34 -> 14645 | G34: =((N34+'Weapon Specifics'!$D$11)/2 * 33) + 'Weapon Specifics'!$D$11*(H34-33) -> 4872.5 | H34: =H33 -> 101 | I34: =I33 -> 505 | J34: =J33 -> 900 | K34: 1.44 | L34: =timeToEmpty(H34,I34,J34,K34) -> 39.093333 | M34: =M33 -> 22 | N34: =N33 -> 29 | O34: Picking up an Ionic Trace reduces number of hits requires to cap damage to 33 rounds
B35: Prometheous Lens | C35: =(G35)/(H35 * 1/J35 * 60/1) + 'Elemental Effects'!$E$13 -> 412.32143 | D35: =(G35)/((H35-1) * 1/J35 * 60/1 + K35) + 'Elemental Effects'!$E$13 -> 345.70451 | F35: =I35*N35 -> 13000 | G35: =N35 * H35 -> 2600 | H35: 100 | I35: ='Reserves Data (Reference)'!$D$15 -> 500 | J35: 900 | K35: 1.44 | L35: =timeToEmpty(H35,I35,J35,K35) -> 38.76 | M35: 19 | N35: 26 | O35: Without ignitions
B36: Prometheous Lens | C36: =(G36)/(H36 * 1/J36 * 60/1) + 'Elemental Effects'!$E$13 + 'Elemental Effects'!$E$4 / (150*1/J37*60) -> 486.62143 | D36: =(G36)/((H36-1) * 1/J36 * 60/1 + K36) + 'Elemental Effects'!$E$13 -> 345.70451 | F36: =I36*N36 + 3*'Elemental Effects'!$E$4 -> 15229 | G36: =N36 * H36 -> 2600 | H36: 100 | I36: ='Reserves Data (Reference)'!$D$15 -> 500 | J36: 900 | K36: 1.44 | L36: =timeToEmpty(H36,I36,J36,K36) -> 38.76 | M36: =M35 -> 19 | N36: =N35 -> 26 | O36: With ignitions
A37: Ember of Ashes | B37: Prometheous Lens | C37: =(G37)/(H37 * 1/J37 * 60/1) + 'Elemental Effects'!$E$13 + 'Elemental Effects'!$E$4 / (100*1/J37*60) -> 523.77143 | D37: =(G37)/((H37-1) * 1/J37 * 60/1 + K37) + 'Elemental Effects'!$E$13 -> 345.70451 | F37: =I37*N37 + floor(I37/H37,1) * 'Elemental Effects'!$E$4 -> 16715 | G37: =N37 * H37 -> 2600 | H37: 100 | I37: ='Reserves Data (Reference)'!$D$15 -> 500 | J37: 900 | K37: 1.44 | L37: =timeToEmpty(H37,I37,J37,K37) -> 38.76 | M37: =M35 -> 19 | N37: =N35 -> 26 | O37: With ignitions, Ember of Ashes
B38: The Navigator | C38: =(G38)/(H38 * 1/J38 * 60/1) -> 435 | D38: =(G38)/((H38-1) * 1/J38 * 60/1 + K38) -> 358.80102 | F38: =I38*N38 -> 14065 | G38: =N38 * H38 -> 2813 | H38: 97 | I38: ='Reserves Data (Reference)'!$D$16 -> 485 | J38: 900 | K38: 1.44 | L38: =timeToEmpty(H38,I38,J38,K38) -> 37.76 | M38: =M33 -> 22 | N38: =N33 -> 29
A39: average | B39: Wavesplitter | C39: =(G39)/(H39 * 1/J39 * 60/1) -> 580 | D39: =(G39)/((H39-1) * 1/J39 * 60/1 + K39) -> 480.92869 | F39: =I39*N39 -> 19333.333 | G39: =N39 * H39 -> 3866.6667 | H39: 100 | I39: ='Reserves Data (Reference)'!$D$17 -> 500 | J39: 900 | K39: 1.44 | L39: =timeToEmpty(H39,I39,J39,K39) -> 38.76 | M39: =AVERAGE('Weapon Specifics'!$D$82,'Weapon Specifics'!$D$83,'Weapon Specifics'!$D$84) -> 29 | N39: =AVERAGE('Weapon Specifics'!$D$85,'Weapon Specifics'!$D$86,'Weapon Specifics'!$D$87) -> 38.666667
A40: power level III | B40: Wavesplitter | C40: =(G40)/(H40 * 1/J40 * 60/1) -> 735 | D40: =(G40)/((H40-1) * 1/J40 * 60/1 + K40) -> 609.45274 | F40: =I40*N40 -> 24500 | G40: =N40 * H40 -> 4900 | H40: =H39 -> 100 | I40: =I39 -> 500 | J40: =J39 -> 900 | K40: =K39 -> 1.44 | L40: =L39 -> 38.76 | M40: ='Weapon Specifics'!D84 -> 36 | N40: ='Weapon Specifics'!D87 -> 49 | O40: Orbs crank the power level up to III for a duration
...

Sheet Heavies
A1: Note: all weapons assume Backup Mag whenever applicable, rocket launchers assume Impact Casing wherever applicable; All weapon damage (except exotics) is normalized. Want to contribute? Have questions, comments, or concerns? See Home page for contact information.
B2: Frame/Weapon | C2: 1-Mag Burst or "True" DPS | D2: Sustained DPS | F2: Theoretical Total Damage | G2: 1-Mag Damage | H2: Magazine Capacity | I2: Reserves + Magazine | J2: Fire rate (rpm) | K2: Reload Speed (s) | L2: Time to Empty (s) | M2: Body Damage | N2: Precision Damage
A3: Machine Guns | B3: Rapid-Fire | C3: =(G3)/(H3 * 1/J3 * 60/1) -> 825 | D3: =(G3)/((H3-1) * 1/J3 * 60/1 + K3) -> 604.91584 | F3: =I3*N3 -> 31625 | G3: =N3 * H3 -> 6325 | H3: 115 | I3: ='Reserves Data (Reference)'!D67 -> 575 | J3: 900 | K3: =3.57*0.8 -> 2.856 | L3: =timeToEmpty(H3,I3,J3,K3) -> 49.424 | M3: 42 | N3: 55
A4: Triple Tap | B4: Rapid-Fire | C4: =(G4)/(H4 * 1/J4 * 60/1) -> 825 | D4: =(G4)/((H4-1) * 1/J4 * 60/1 + K4) -> 663.58025 | F4: =I4*N4 -> 47300 | G4: =N4 * H4 -> 9460 | H4: =tripleTap(H3) -> 172 | I4: =floor(I3/H3,1)*H4+tripleTap(mod(I3, H3)) -> 860 | J4: =J3 -> 900 | K4: =3.57*0.8 -> 2.856 | L4: =timeToEmpty(H4,I4,J4,K4) -> 68.424 | M4: =M3 -> 42 | N4: =N3 -> 55
A5: Fourth Time's the Charm | B5: Rapid-Fire | C5: =(G5)/(H5 * 1/J5 * 60/1) -> 825 | D5: =(G5)/((H5-1) * 1/J5 * 60/1 + K5) -> 696.60393 | F5: =I5*N5 -> 62425 | G5: =N5 * H5 -> 12485 | H5: =fourthTimesTheCharm(H3) -> 227 | I5: =floor(I3/H3,1)*H5+fourthTimesTheCharm(mod(I3, H3)) -> 1135 | J5: =J3 -> 900 | K5: =3.57*0.8 -> 2.856 | L5: =timeToEmpty(H5,I5,J5,K5) -> 86.757333 | M5: =M3 -> 42 | N5: =N3 -> 55
B6: Aggressive | C6: =(G6)/(H6 * 1/J6 * 60/1) -> 770 | D6: =(G6)/((H6-1) * 1/J6 * 60/1 + K6) -> 557.43835 | F6: =I6*N6 -> 35035 | G6: =N6 * H6 -> 7007 | H6: 91 | I6: ='Reserves Data (Reference)'!D68 -> 455 | J6: 600 | K6: 3.57 | L6: =timeToEmpty(H6,I6,J6,K6) -> 59.28 | M6: 60 | N6: 77
B7: Adaptive | C7: =(G7)/(H7 * 1/J7 * 60/1) -> 720 | D7: =(G7)/((H7-1) * 1/J7 * 60/1 + K7) -> 535.84718 | F7: =I7*N7 -> 36000 | G7: =N7 * H7 -> 7200 | H7: 75 | I7: ='Reserves Data (Reference)'!D69 -> 375 | J7: 450 | K7: 3.57 | L7: =timeToEmpty(H7,I7,J7,K7) -> 63.613333 | M7: 68 | N7: 96
B8: High-Impact | C8: =(G8)/(H8 * 1/J8 * 60/1) -> 678 | D8: =(G8)/((H8-1) * 1/J8 * 60/1 + K8) -> 532.90715 | F8: =I8*N8 -> 42149 | G8: =N8 * H8 -> 8475 | H8: 75 | I8: ='Reserves Data (Reference)'!D70 -> 373 | J8: 360 | K8: 3.57 | L8: =timeToEmpty(H8,I8,J8,K8) -> 75.613333 | M8: 78 | N8: 113
B9: Heir Apparent | C9: =(G9)/(H9 * 1/J9 * 60/1) -> 810 | D9: =(G9)/((H9-1) * 1/J9 * 60/1 + K9) -> 641.45714 | F9: =I9*N9 -> 23760 | G9: =N9 * H9 -> 10800 | H9: 200 | I9: ='Reserves Data (Reference)'!D71 -> 440 | J9: 900 | K9: 3.57 | L9: =timeToEmpty(H9,I9,J9,K9) -> 36.273333 | M9: 45 | N9: 54
B10: Thunderlord | C10: =(N10*720*1/60) + 'Weapon Specifics'!$D$88/(10*1/720 * 60) -> 1189.62 | D10: =(G10)/((H10-1) * 1/J10 * 60/1 + K10) -> 645.91691 | F10: =G10*floor(I10/H10,1) + mod(I10, H10) * N10 + floor(mod(I10, H10)/10,1) * 'Weapon Specifics'!$D$88 -> 37512.6 | G10: =H10*N10 + floor(H10/10,1) * 'Weapon Specifics'!$D$88 -> 6140.1 | H10: 62 | I10: ='Reserves Data (Reference)'!D72 -> 379 | J10: =H10/(13*1/450 + 13*1/600 + (H10-13*2)*1/720) -> 616.57459 | K10: 3.57 | L10: =timeToEmpty(H10,I10,J10,K10) -> 57.62 | M10: 68 | N10: 96
A11: cata | B11: Thunderlord | C11: =(N11*720*1/60) + 'Weapon Specifics'!$D$88/(10*1/720 * 60) -> 1189.62 | D11: =C11 -> 1189.62 | F11: =I11*N11 + FLOOR(I11/10,1)*'Weapon Specifics'!$D$88 -> 37543.95 | G11: inf | H11: inf | I11: =I10 -> 379 | J11: =J10 -> 616.57459 | K11: 3.57 | L11: =13*1/450*60 + 13*1/600*60 + (I11-13*2)*1/720*60 -> 32.45 | M11: =M10 -> 68 | N11: =N10 -> 96
A12: w/o weaken | B12: Deterministic Chaos | C12: =(G12)/(H12 * 1/J12 * 60/1) -> 1566.1141 | D12: =(G12)/((H12-1) * 1/J12 * 60/1 + K12) -> 1098.7062 | F12: =I12*N12 -> 42488 | G12: =N12 * H12 + floor(H12/16,1) * (2681*1/1.15 + 37) -> 12528.913 | H12: 48 | I12: ='Reserves Data (Reference)'!D73 -> 376 | J12: 360 | K12: 3.57 | L12: =timeToEmpty(H12,I12,J12,K12) -> 86.323333 | M12: =M8 -> 78 | N12: =N8 -> 113 | O12: This assumes 0% weaken uptime
A13: w/ weaken | B13: Deterministic Chaos | C13: =(G13)/(H13 * 1/J13 * 60/1) -> 1798.95 | D13: =(G13)/((H13-1) * 1/J13 * 60/1 + K13) -> 1262.052 | F13: =I13*N13 -> 48861.2 | G13: =N13 * H13 + floor(H13/16,1) * (2681 + 37) -> 14391.6 | H13: 48 | I13: =I12 -> 376 | J13: 360 | K13: 3.57 | L13: =timeToEmpty(H13,I13,J13,K13) -> 86.323333 | M13: =M12*1.15 -> 89.7 | N13: =N12*1.15 -> 129.95 | O13: This assumes 100% weaken uptime
B14: Xenophage | C14: =(G14)/(H14 * 1/J14 * 60/1) -> 1362 | D14: =(G14)/((H14-1) * 1/J14 * 60/1 + K14) -> 925.07837 | F14: =I14*M14 -> 19749 | G14: =M14 * H14 -> 8853 | H14: 13 | I14: ='Reserves Data (Reference)'!D74 -> 29 | J14: 120 | K14: 3.57 | L14: =timeToEmpty(H14,I14,J14,K14) -> 20.14 | M14: =138+543 -> 681 | N14: N/A | O14: Does not deal precision damage
A15: w/o rockets | B15: Grand Overture | C15: =(G15)/(H15 * 1/J15 * 60/1) -> 898.33333 | D15: =(G15)/(0.8 + (H15-1) * 1/J15 * 60/1 + K15) -> 683.57641 | F15: =I15*M15 -> 31262 | G15: =M15 * H15 -> 10780 | H15: 20 | I15: ='Reserves Data (Reference)'!D75 -> 58 | J15: 100 | K15: 3.57 | L15: =timeToEmpty(H15,I15,J15,K15) -> 40.14 | M15: 539 | N15: N/A | O15: Does not deal precision damage
A16: w/ rockets | B16: Grand Overture | C16: =(('Weapon Specifics'!$D$89)*20)/(1.4) -> 855 | D16: =(G16)/(0.8 + (H15-1) * 1/J16 * 60/1 + 0.8 + 1.4 + K16) -> 666.49972 | F16: =I15*M16 + I15*('Weapon Specifics'!$D$89) -> 34733.3 | G16: =M16 * H15 + H15 * ('Weapon Specifics'!$D$89) -> 11977 | H16: =H15 -> 20 | I16: =I15 -> 58 | J16: =J15 -> 100 | K16: =K15 -> 3.57 | L16: =timeToEmpty(H15,I15,J16,K16) + ceiling(I15/20,1)*0.8 + ceiling(I15/20,1)*0.8 + I15*(1.4/20) -> 49 | M16: =M15 -> 539 | N16: N/A | O16: Does not deal precision damage; shoot 20 rounds > swap mode > shoot 20 rockets > reload
A17: Grenade Launchers | B17: Rapid-Fire | C17: =(G17)/(H17 * 1/J17 * 60/1) -> 1535 | D17: =(G17)/((H17-1) * 1/J17 * 60/1 + K17) -> 1040.678 | F17: =I17*M17 -> 18420 | G17: =M17 * H17 -> 4912 | H17: 8 | I17: ='Reserves Data (Reference)'!D76 -> 30 | J17: 150 | K17: 1.92 | L17: =timeToEmpty(H17,I17,J17,K17) -> 16.16 | M17: =450+164 -> 614 | N17: N/A
A18: Cascade Point | B18: Rapid-Fire | C18: =(G18)/(H18 * 1/J18 * 60/1) -> 2558.3333 | D18: =(G18)/((H18-1) * 1/J18 * 60/1 + K18) -> 1364.4444 | F18: =I18*M18 -> 18420 | G18: =M18 * H18 -> 4912 | H18: 8 | I18: =I17 -> 30 | J18: =J17/0.6 -> 250 | K18: 1.92 | L18: =timeToEmpty(H18,I18,J18,K18) -> 12 | M18: =M17 -> 614 | N18: N/A
B19: Adaptive | C19: =(G19)/(H19 * 1/J19 * 60/1) -> 1444 | D19: =(G19)/((H19-1) * 1/J19 * 60/1 + K19) -> 1035.1254 | F19: =I19*M19 -> 18772 | G19: =M19 * H19 -> 5776 | H19: 8 | I19: ='Reserves Data (Reference)'!D77 -> 26 | J19: 120 | K19: 2.08 | L19: =timeToEmpty(H19,I19,J19,K19) -> 17.24 | M19: =535+187 -> 722 | N19: N/A
A20: Cascade Point | B20: Adaptive | C20: =(G20)/(H20 * 1/J20 * 60/1) -> 2406.6667 | D20: =(G20)/((H20-1) * 1/J20 * 60/1 + K20) -> 1381.8182 | F20: =I20*M20 -> 18772 | G20: =M20 * H20 -> 5776 | H20: 8 | I20: =I19 -> 26 | J20: =J19/0.6 -> 200 | K20: 2.08 | L20: =timeToEmpty(H20,I20,J20,K20) -> 12.84 | M20: =M19 -> 722 | N20: N/A
B21: Compressed Wave | C21: =(G21)/(H21 * 1/J21 * 60/1) -> 1460 | D21: =(G21)/(H21 * 1/J21 * 60/1 + K21) -> 902.82686 | F21: =I21*M21 -> 18980 | G21: =M21 * H21 -> 5110 | H21: 7 | I21: ='Reserves Data (Reference)'!D78 -> 26 | J21: 120 | K21: 2.16 | L21: =I21*1/J21*60/1 + Floor(I21/H21,1) * K21 -> 19.48 | M21: 730 | N21: N/A
A22: Cascade Point | B22: Compressed Wave | C22: =(G22)/(H22 * 1/J22 * 60/1) -> 2433.3333 | D22: =(G22)/(H22 * 1/J22 * 60/1 + K22) -> 1199.5305 | F22: =I22*M22 -> 18980 | G22: =M22 * H22 -> 5110 | H22: =H21 -> 7 | I22: =I21 -> 26 | J22: =J21/0.6 -> 200 | K22: =K21 -> 2.16 | L22: =I22*1/J22*60/1 + Floor(I22/H22,1) * K22 -> 14.28 | M22: =M21 -> 730 | N22: N/A
A23: cata | B23: The Prospector | C23: =(G23)/(H23 * 1/J23 * 60/1) -> 1694 | D23: =(G23)/((H23-1) * 1/J23 * 60/1 + K23) -> 948.13433 | F23: =I23*M23 -> 18480 | G23: =M23*H23 -> 3696 | H23: =H24 -> 6 | I23: =I24 -> 30 | J23: =J24 -> 165 | K23: =K24 -> 2.08 | L23: =L24 -> 17.410909 | M23: =187+429 -> 616 | N23: N/A | O23: Assumes no bomblets contact the boss (DPS minimum)
A24: cata | B24: The Prospector | C24: =(G24)/(H24 * 1/J24 * 60/1) -> 2915 | D24: =(G24)/((H24-1) * 1/J24 * 60/1 + K24) -> 1631.5299 | F24: =I24*(M24+'Weapon Specifics'!$D$4*3) -> 31800 | G24: =(M24+'Weapon Specifics'!$D$4*3)*H24 -> 6360 | H24: 6 | I24: ='Reserves Data (Reference)'!D79 -> 30 | J24: 165 | K24: 2.08 | L24: =timeToEmpty(H24,I24,J24,K24) -> 17.410909 | M24: =M23 + 'Weapon Specifics'!D4*3 -> 838 | N24: N/A | O24: Assumes all bomblets contact the boss (DPS maximum)
A25: single-stick | B25: Anarchy | C25: =(M26+'Weapon Specifics'!D5*10/0.5)/10 -> 145.9 | D25: =C25 -> 145.9 | F25: =I25*M25 + I25 * 10/0.5 * 'Weapon Specifics'!D5 -> 42311 | G25: =M25 * H25 + H25 * 10/0.5 * 'Weapon Specifics'!D5 -> 8754 | H25: 6 | I25: ='Reserves Data (Reference)'!D80 -> 29 | J25: 150 | K25: 2.08 | L25: =I25*10 -> 290 | M25: 19 | N25: N/A | O25: Assumes a single grenade > wait out damage, reloading while waiting
A26: double-stick | B26: Anarchy | C26: =(M26+'Weapon Specifics'!D6*10/0.5)/10 -> 963.9 | D26: =C26 -> 963.9 | F26: =I26*M26 + floor(I26/2,1) * 10/0.5 * 'Weapon Specifics'!D6 + mod(I26, 2) * 10/0.5 * 'Weapon Specifics'!D5 -> 136671 | G26: =M26 * H26 + H26/2 * 10/0.5 * 'Weapon Specifics'!D6 -> 28974 | H26: 6 | I26: =I25 -> 29 | J26: 150 | K26: 2.08 | L26: =FLOOR(I26/2,1) * 10 + mod(I26, 2) * 10 -> 150 | M26: 19 | N26: N/A | O26: Assumes two grenades > wait out damage, reloading while waiting
A27: cata | B27: The Colony | C27: =(G27)/(H27 * 1/J27 * 60/1) -> 1766.3333 | D27: =(G27)/((H27-1) * 1/J27 * 60/1 + K27) -> 1192.126 | F27: =I27*M27 -> 18925 | G27: =M27 * H27 -> 6056 | H27: 8 | I27: ='Reserves Data (Reference)'!D81 -> 25 | J27: 140 | K27: 2.08 | L27: =timeToEmpty(H27,I27,J27,K27) -> 15.24 | M27: =715+42 -> 757 | N27: N/A
B28: Parasite | C28: =(G28)/(H28 * 1/J28 * 60/1) -> 4064 | D28: =(G28)/(K28) -> 976.92308 | F28: =I28*M28 -> 36576 | G28: =M28 * H28 -> 2032 | H28: 1 | I28: ='Reserves Data (Reference)'!D82 -> 18 | J28: 120 | K28: 2.08 | L28: =timeToEmpty(H28,I28,J28,K28) -> 35.36 | M28: =543+1489 -> 2032 | N28: N/A
A29: x20 WH on first, avg | B29: Parasite | C29: =C28 -> 4064 | D29: =(M29*(I29-1) + G29)/(K29 * (I29-1)) -> 1149.3213 | F29: =(I29-1)*M29 + G29 -> 40640 | G29: =M29*(1+0.1*20) -> 6096 | H29: 1 | I29: =I28 -> 18 | J29: 120 | K29: 2.08 | L29: =timeToEmpty(H29,I29,J29,K29) -> 35.36 | M29: =M28 -> 2032 | N29: N/A | O29: Assumes first shot is x20 Worm's Hunger, rest are 0x Worm's Hunger; Average DPS
A30: no charge, spamming | B30: Salvation's Grip | C30: =(G30)/(H30 * 1/J30 * 60/1) -> 1522 | D30: =(G30)/((H30-1) * 1/J30 * 60/1 + K30) -> 1068.0702 | F30: =I30*M30 -> 19025 | G30: =M30 * H30 -> 6088 | H30: 8 | I30: ='Reserves Data (Reference)'!D83 -> 25 | J30: 120 | K30: 2.2 | L30: =timeToEmpty(H30,I30,J30,K30) -> 17.1 | M30: =581+180 -> 761 | N30: N/A
A31: full charge, spamming | B31: Salvation's Grip | C31: =('Weapon Specifics'!$D$8*5 + 'Weapon Specifics'!$D$8*5 + 'Weapon Specifics'!$D$7)/(2 + 2 * 1/$J$30 * 60/1) -> 672 | D31: =C31 -> 672 | F31: =('Weapon Specifics'!D8*5 + 'Weapon Specifics'!D8*5 + 'Weapon Specifics'!D7) * (floor(I31/2,1)) + ('Elemental Effects'!$E$9 + 'Weapon Specifics'!D8*5 + 'Weapon Specifics'!D7) * mod(I31, 2) -> 25609 | G31: N/A | H31: 8 | I31: =I30 -> 25 | J31: =1/(1000/1000*1/60) -> 60 | K31: 2.2 | L31: =timeToEmpty(H31,I31,J31,K31) -> 27.6 | M31: ='Elemental Effects'!$E$7 -> 158 | N31: N/A | O31: Assumes boss naturally shatters on its own (no additional damage done from any other source)
A32: full charge, spamming | B32: Salvation's Grip | C32: =('Weapon Specifics'!$D$9*5+'Elemental Effects'!$E$9)/(1+1/$J$30*60) -> 390.66667 | D32: =C32 -> 390.66667 | F32: =('Weapon Specifics'!$D$9*5+'Elemental Effects'!$E$9)*I32 -> 14650 | G32: N/A | H32: 8 | I32: =I31 -> 25 | J32: =1/(1000/1000*1/60) -> 60 | K32: 2.2 | L32: =timeToEmpty(H32,I32,J32,K32) -> 27.6 | M32: ='Elemental Effects'!$E$7 -> 158 | N32: N/A | O32: Assumes boss is big enough that all crystals shatter as they spawn
A33: mix | B33: Salvation's Grip | C33: =(M33 + 'Elemental Effects'!$E$9 + 'Weapon Specifics'!$D$8*5) / (1 + 0.5 + 1/J30*60) -> 1156 | D33: =C33 -> 1156 | F33: =('Weapon Specifics'!D8*5 + 'Elemental Effects'!$E$9 + M33) * Floor(I33/2,1) + ('Weapon Specifics'!D8*5 + 'Elemental Effects'!$E$9) * mod(I33, 2) -> 29065 | G33: N/A | H33: 8 | I33: =I30 -> 25 | J33: =J31 -> 60 | K33: =K31 -> 2.2 | L33: =I33/2 * 2/(1 + 1*1/J30*60) -> 16.666667 | M33: =247+744 -> 991 | N33: N/A | O33: Full charge > normal shot > repeat
A34: full charge, spamming, WoF | B34: Salvation's Grip | C34: =('Elemental Effects'!$E$9 + ('Weapon Specifics'!$D$8+'Elemental Effects'!$E$8)*5+('Weapon Specifics'!$D$8+'Elemental Effects'!$E$8)*5 + 'Weapon Specifics'!$D$7)/(2 + 1/J34 * 60/1) -> 869 | D34: =C34 -> 869 | F34: =('Elemental Effects'!$E$9 + ('Weapon Specifics'!D8+'Elemental Effects'!$E$8)*5 + ('Weapon Specifics'!D8+'Elemental Effects'!$E$8)*5 + 'Weapon Specifics'!D7) * (floor(I34/2,1)) + ('Elemental Effects'!$E$9+('Weapon Specifics'!D8+'Elemental Effects'!$E$8)*5 + 'Weapon Specifics'!D7) * mod(I34, 2) -> 32816 | G34: N/A | H34: 8 | I34: =I33 -> 25 | J34: =1/(1000/1000*1/60) -> 60 | K34: 2.2 | L34: =timeToEmpty(H34,I34,J34,K34) -> 27.6 | M34: =M31 -> 158 | N34: N/A | O34: Whisper of Fissures; Assumes boss naturally shatters on its own
A35: full charge, spamming, WoF | B35: Salvation's Grip | C35: =(('Weapon Specifics'!$D$9 + 'Elemental Effects'!$E$8)*5+'Elemental Effects'!$E$9)/(1+1/$J$30*60) -> 467.33333 | D35: =C35 -> 467.33333 | F35: =(('Weapon Specifics'!$D$9 + 'Elemental Effects'!$E$8)*5+'Elemental Effects'!$E$9)*I35 -> 17525 | G35: N/A | H35: 8 | I35: =I34 -> 25 | J35: =1/(1000/1000*1/60) -> 60 | K35: 2.2 | L35: =timeToEmpty(H35,I35,J35,K35) -> 27.6 | M35: =M32 -> 158 | N35: N/A | O35: Whisper of Fissures; Assumes boss is bit enough that all crystals shatter as they spawn
A36: mix, WoF | B36: Salvation's Grip | C36: =(M36 + 'Elemental Effects'!$E$9 + ('Weapon Specifics'!D8+'Elemental Effects'!$E$8)*5) / (1 + 1/J33*60 + 0.5) -> 970.8 | D36: =C36 -> 970.8 | F36: =(M36 + ('Weapon Specifics'!D8+'Elemental Effects'!$E$8)*5+'Elemental Effects'!$E$9) * Floor(I36/2,1) + mod(I36, 2) * (('Weapon Specifics'!D8+'Elemental Effects'!$E$8)*5+'Elemental Effects'!$E$9) -> 30560 | G36: N/A | H36: 8 | I36: =I33 -> 25 | J36: =J34 -> 60 | K36: =K34 -> 2.2 | L36: =I36/2 * 2/(1 + 1*1/J33*60) -> 12.5 | M36: =M33 -> 991 | N36: N/A | O36: Whisper of Fissures; Full charge > normal shot > repeat
A37: Rocket Launchers | B37: Aggressive | C37: =(G37)/(H37 * 1/J37 * 60/1) -> 2294.875 | D37: =(M37)/(K37) -> 781.23404 | F37: =I37*M37 -> 16523.1 | G37: =M37 * H37 -> 1835.9 | H37: 1 | I37: ='Reserves Data (Reference)'!D84 -> 9 | J37: =1/0.8*60 -> 75 | K37: 2.35 | L37: =timeToEmpty(H37,I37,J37,K37) -> 18.8 | M37: =(1397+399*1.1) -> 1835.9 | N37: N/A | O37: Adaptive and Aggressive rocket launchers share the same damage
A38: Wolfpack Rounds | B38: Aggressive | C38: =(G38)/(H38 * 1/J38 * 60/1) -> 2894.875 | D38: =(M38)/(K38) -> 985.48936 | F38: =I38*M38 -> 20843.1 | G38: =M38 * H38 -> 2315.9 | H38: 1 | I38: =I37 -> 9 | J38: =J37 -> 75 | K38: 2.35 | L38: =L37 -> 18.8 | M38: =M37 + ('Weapon Specifics'!$D$92)*8 -> 2315.9 | N38: N/A
A39: Bipod | B39: Aggressive | C39: =(G39)/(H39 * 1/J39 * 60/1) -> 1721.1562 | D39: =(G39)/((H39-1) * 1/J39 * 60/1 + K39) -> 874.2381 | F39: =I39*M39 -> 19276.95 | G39: =M39 * H39 -> 2753.85 | H39: 2 | I39: ='Reserves Data (Reference)'!D85 -> 14 | J39: =J37 -> 75 | K39: 2.35 | L39: =timeToEmpty(H39,I39,J39,K39) -> 19.7 | M39: =M37*(1-0.25) -> 1376.925 | N39: N/A
A40: Bipod + Wolfpack Rounds | B40: Aggressive | C40: =(G40)/(H40 * 1/J40 * 60/1) -> 2321.1562 | D40: =(G40)/((H40-1) * 1/J40 * 60/1 + K40) -> 1179 | F40: =I40*M40 -> 25996.95 | G40: =M40 * H40 -> 3713.85 | H40: 2 | I40: =I39 -> 14 | J40: =J37 -> 75 | K40: 2.35 | L40: =L39 -> 19.7 | M40: =M39 + ('Weapon Specifics'!$D$92)*8 -> 1856.925 | N40: N/A
...

Sheet Swords
A1: !!! IMPORTANT: ALL SWORDS ASSUME SWORDMASTER'S GUARD + JAGGED EDGE + MASTERWORK + BACKUP MAG UNLESS OTHERWISE STATED !!! All weapon damage (except exotic) is normalized. Want to contribute? Have questions, comments, or concerns? See Home page for contact information.
A2: Sword | B2: Lucent Blades Count | C2: DPS: Waiting for Heavy to Recharge | D2: DPS: Not Waiting for Heavy to Recharge | F2: Theoretical Total Damage if Waiting for Heavy | G2: Theoretical Total Damage if Not Waiting for Heavy | H2: Reserves | I2: Average Swing Speed (spm) | J2: Heavy Swing Time (s) | K2: Recharge Delay (s) | L2: Time to Empty if Waiting for Heavy (s) | M2: Time to Empty if Not Waiting for Heavy (s) | N2: Time if Waiting for Heavy (s) | O2: Light Count until Waiting for Heavy | P2: Light Count until Heavy is Ready | Q2: Heavy Ammo Cost | R2: Light Attack Damage | S2: Heavy Attack Damage
A3: Adaptive | B3: 0 | C3: =(O3*R3 + S3) / (K3 + J3) -> 962.28571 | D3: =(P3*R3 + S3) / (P3*1/I3*60 + J3) -> 966.15385 | F3: =floor(H3/(O3+Q3),1)*(O3*R3+S3) + if(mod(H3, O3+Q3) > O3, (O3*R3+S3), mod(H3, O3+Q3)*R3) -> 26944 | G3: =floor(H3/(P3+Q3),1)*(P3*R3+S3) + if(mod(H3, P3+Q3) > P3, (P3*R3+S3), mod(H3, P3+Q3)*R3) -> 26376 | H3: ='Reserves Data (Reference)'!$D$113 -> 70 | I3: =(3)/((0.46+0.46+0.49)*1/60) -> 127.65957 | J3: 1.08 | K3: 2.42 | L3: =floor(H3/(O3+Q3),1)*(O3*1/I3*60+J3) + if(mod(H3, O3+Q3) > O3, (O3*1/I3*60+J3), mod(H3, O3+Q3)*1/I3*60) -> 27.44 | M3: =floor(H3/(P3+Q3),1)*(P3*1/I3*60+J3) + if(mod(H3, P3+Q3) > P3, (P3*1/I3*60+J3), mod(H3, P3+Q3)*1/I3*60) -> 27.3 | N3: =K3-(O3*1/I3*60) -> 0.07 | O3: =CEILING(K3*I3*1/60,1)-1 -> 5 | P3: =O3+1 -> 6 | Q3: 4 | R3: 400 | S3: =R3+242*4 -> 1368
B4: 1 | C4: =(O4*R4 + S4) / (K4 + J4) -> 982.78146 | D4: =(P4*R4 + S4) / (P4*1/I4*60 + J4) -> 981.9242 | F4: =floor(H4/(O4+Q4),1)*(O4*R4+S4) + if(mod(H4, O4+Q4) > O4, (O4*R4+S4), mod(H4, O4+Q4)*R4) -> 26712 | G4: =floor(H4/(P4+Q4),1)*(P4*R4+S4) + if(mod(H4, P4+Q4) > P4, (P4*R4+S4), mod(H4, P4+Q4)*R4) -> 26944 | H4: =$H$3 -> 70 | I4: =$I$3 -> 127.65957 | J4: =$J$3 -> 1.08 | K4: 1.94 | L4: =floor(H4/(O4+Q4),1)*(O4*1/I4*60+J4) + if(mod(H4, O4+Q4) > O4, (O4*1/I4*60+J4), mod(H4, O4+Q4)*1/I4*60) -> 26.64 | M4: =floor(H4/(P4+Q4),1)*(P4*1/I4*60+J4) + if(mod(H4, P4+Q4) > P4, (P4*1/I4*60+J4), mod(H4, P4+Q4)*1/I4*60) -> 27.44 | N4: =K4-(O4*1/I4*60) -> 0.06 | O4: =CEILING(K4*I4*1/60,1)-1 -> 4 | P4: =O4+1 -> 5 | Q4: =$Q$3 -> 4 | R4: =$R$3 -> 400 | S4: =S3 -> 1368
B5: 2 | C5: =(O5*R5 + S5) / (K5 + J5) -> 987.69231 | D5: =(P5*R5 + S5) / (P5*1/I5*60 + J5) -> 1002.7027 | F5: =floor(H5/(O5+Q5),1)*(O5*R5+S5) + if(mod(H5, O5+Q5) > O5, (O5*R5+S5), mod(H5, O5+Q5)*R5) -> 25680 | G5: =floor(H5/(P5+Q5),1)*(P5*R5+S5) + if(mod(H5, P5+Q5) > P5, (P5*R5+S5), mod(H5, P5+Q5)*R5) -> 26712 | H5: =$H$3 -> 70 | I5: =$I$3 -> 127.65957 | J5: =$J$3 -> 1.08 | K5: 1.52 | L5: =floor(H5/(O5+Q5),1)*(O5*1/I5*60+J5) + if(mod(H5, O5+Q5) > O5, (O5*1/I5*60+J5), mod(H5, O5+Q5)*1/I5*60) -> 24.9 | M5: =floor(H5/(P5+Q5),1)*(P5*1/I5*60+J5) + if(mod(H5, P5+Q5) > P5, (P5*1/I5*60+J5), mod(H5, P5+Q5)*1/I5*60) -> 26.64 | N5: =K5-(O5*1/I5*60) -> 0.11 | O5: =CEILING(K5*I5*1/60,1)-1 -> 3 | P5: =O5+1 -> 4 | Q5: =$Q$3 -> 4 | R5: =$R$3 -> 400 | S5: =S3 -> 1368
B6: 3 | C6: =(O6*R6 + S6) / (K6 + J6) -> 934.48276 | D6: =(P6*R6 + S6) / (P6*1/I6*60 + J6) -> 1031.3253 | F6: =floor(H6/(O6+Q6),1)*(O6*R6+S6) + if(mod(H6, O6+Q6) > O6, (O6*R6+S6), mod(H6, O6+Q6)*R6) -> 26016 | G6: =floor(H6/(P6+Q6),1)*(P6*R6+S6) + if(mod(H6, P6+Q6) > P6, (P6*R6+S6), mod(H6, P6+Q6)*R6) -> 25680 | H6: =$H$3 -> 70 | I6: =$I$3 -> 127.65957 | J6: =$J$3 -> 1.08 | K6: 1.24 | L6: =floor(H6/(O6+Q6),1)*(O6*1/I6*60+J6) + if(mod(H6, O6+Q6) > O6, (O6*1/I6*60+J6), mod(H6, O6+Q6)*1/I6*60) -> 24.24 | M6: =floor(H6/(P6+Q6),1)*(P6*1/I6*60+J6) + if(mod(H6, P6+Q6) > P6, (P6*1/I6*60+J6), mod(H6, P6+Q6)*1/I6*60) -> 24.9 | N6: =K6-(O6*1/I6*60) -> 0.3 | O6: =CEILING(K6*I6*1/60,1)-1 -> 2 | P6: =O6+1 -> 3 | Q6: =$Q$3 -> 4 | R6: =$R$3 -> 400 | S6: =S3 -> 1368
A7: Jump-Heavy | B7: 0 | C7: =(R7+S7)/(0.5+0.33+0.48) -> 540.45802 | D7: =(R7+S7)/(0.5+0.33+0.48) -> 540.45802 | F7: =floor(H7/(1+Q7),1)*(R7+S7)+mod(H7, (1+Q7))*R7 -> 24780 | G7: =floor(H7/(1+Q7),1)*(R7+S7)+mod(H7, (1+Q7))*R7 -> 24780 | H7: =$H$3 -> 70 | I7: =(2/(0.05+0.33+0.48))*60 -> 139.53488 | J7: 0.48 | K7: N/A | L7: =H7*1/I7*60 -> 30.1 | M7: =H7*1/I7*60 -> 30.1 | N7: N/A | O7: N/A | P7: N/A | Q7: 1 | R7: 333 | S7: 375
A8: Light Spam | B8: N/A | C8: =R8*I8*1/60 -> 851.06383 | D8: =R8*I8*1/60 -> 851.06383 | F8: =H8*R8 -> 28000 | G8: =H8*R8 -> 28000 | H8: =$H$3 -> 70 | I8: =$I$3 -> 127.65957 | J8: N/A | K8: N/A | L8: N/A | M8: N/A | N8: N/A | O8: N/A | P8: N/A | Q8: N/A | R8: =$R$3 -> 400 | S8: N/A
A9: Adaptive (Bequest) | B9: 0 | C9: =(O9*R9 + S9) / (K9 + J9) -> 1056.6038 | D9: =(P9*R9 + S9) / (P9*1/I9*60 + J9) -> 1093.2432 | F9: =floor(H9/(O9+Q9),1)*(O9*R9+S9) + if(mod(H9, O9+Q9) > O9, (O9*R9+S9), mod(H9, O9+Q9)*R9) -> 28000 | G9: =floor(H9/(P9+Q9),1)*(P9*R9+S9) + if(mod(H9, P9+Q9) > P9, (P9*R9+S9), mod(H9, P9+Q9)*R9) -> 29124 | H9: ='Reserves Data (Reference)'!$D$114 -> 69 | I9: =(3)/((0.46+0.46+0.49)*1/60) -> 127.65957 | J9: 1.08 | K9: 1.57 | L9: =floor(H9/(O9+Q9),1)*(O9*1/I9*60+J9) + if(mod(H9, O9+Q9) > O9, (O9*1/I9*60+J9), mod(H9, O9+Q9)*1/I9*60) -> 24.9 | M9: =floor(H9/(P9+Q9),1)*(P9*1/I9*60+J9) + if(mod(H9, P9+Q9) > P9, (P9*1/I9*60+J9), mod(H9, P9+Q9)*1/I9*60) -> 26.64 | N9: =K9-(O9*1/I9*60) -> 0.16 | O9: =CEILING(K9*I9*1/60,1)-1 -> 3 | P9: =O9+1 -> 4 | Q9: 4 | R9: 436 | S9: =R9 + 264*4 -> 1492
